2019-03-29 11:25:04,185 - util.py[DEBUG]: Cloud-init v. 18.3-9-g2e62cb8a-0ubuntu1~16.04.2 running 'init-local' at Fri, 29 Mar 2019 11:25:04 +0000. Up 7.75 seconds.
2019-03-29 11:25:04,185 - main.py[DEBUG]: No kernel command line url found.
2019-03-29 11:25:04,186 - main.py[DEBUG]: Closing stdin.
2019-03-29 11:25:04,189 - util.py[DEBUG]: Writing to /var/log/cloud-init.log - ab: [644] 0 bytes
2019-03-29 11:25:04,189 - util.py[DEBUG]: Changing the ownership of /var/log/cloud-init.log to 104:4
2019-03-29 11:25:04,189 - util.py[DEBUG]: Attempting to remove /var/lib/cloud/instance/boot-finished
2019-03-29 11:25:04,189 - util.py[DEBUG]: Attempting to remove /var/lib/cloud/data/no-net
2019-03-29 11:25:04,190 - handlers.py[DEBUG]: start: init-local/check-cache: attempting to read from cache [check]
2019-03-29 11:25:04,190 - util.py[DEBUG]: Reading from /var/lib/cloud/instance/obj.pkl (quiet=False)
2019-03-29 11:25:04,190 - stages.py[DEBUG]: no cache found
2019-03-29 11:25:04,190 - handlers.py[DEBUG]: finish: init-local/check-cache: SUCCESS: no cache found
2019-03-29 11:25:04,190 - util.py[DEBUG]: Attempting to remove /var/lib/cloud/instance
2019-03-29 11:25:04,192 - stages.py[DEBUG]: Using distro class <class 'cloudinit.distros.ubuntu.Distro'>
2019-03-29 11:25:04,192 - __init__.py[DEBUG]: Looking for data source in: ['NoCloud', 'ConfigDrive', 'OpenNebula', 'DigitalOcean', 'Azure', 'AltCloud', 'OVF', 'MAAS', 'GCE', 'OpenStack', 'CloudSigma', 'SmartOS', 'Bigstep', 'Scaleway', 'AliYun', 'Ec2', 'CloudStack', 'None'], via packages ['', 'cloudinit.sources'] that matches dependencies ['FILESYSTEM']
2019-03-29 11:25:04,230 - util.py[DEBUG]: Reading from /etc/os-release (quiet=False)
2019-03-29 11:25:04,230 - util.py[DEBUG]: Read 298 bytes from /etc/os-release
2019-03-29 11:25:04,267 - __init__.py[DEBUG]: Searching for local data source in: ['DataSourceNoCloud', 'DataSourceConfigDrive', 'DataSourceOpenNebula', 'DataSourceDigitalOcean', 'DataSourceAzure', 'DataSourceOVF', 'DataSourceOpenStackLocal', 'DataSourceCloudSigma', 'DataSourceSmartOS', 'DataSourceEc2Local']
2019-03-29 11:25:04,267 - handlers.py[DEBUG]: start: init-local/search-NoCloud: searching for local data from DataSourceNoCloud
2019-03-29 11:25:04,267 - __init__.py[DEBUG]: Seeing if we can get any data from <class 'cloudinit.sources.DataSourceNoCloud.DataSourceNoCloud'>
2019-03-29 11:25:04,267 - __init__.py[DEBUG]: Update datasource metadata and network config due to events: New instance first boot
2019-03-29 11:25:04,267 - util.py[DEBUG]: Running command ['systemd-detect-virt', '--quiet', '--container'] with allowed return codes [0] (shell=False, capture=True)
2019-03-29 11:25:04,269 - util.py[DEBUG]: Running command ['running-in-container'] with allowed return codes [0] (shell=False, capture=True)
2019-03-29 11:25:04,271 - util.py[DEBUG]: Running command ['lxc-is-container'] with allowed return codes [0] (shell=False, capture=True)
2019-03-29 11:25:04,273 - util.py[DEBUG]: Reading from /proc/1/environ (quiet=False)
2019-03-29 11:25:04,273 - util.py[DEBUG]: Read 150 bytes from /proc/1/environ
2019-03-29 11:25:04,273 - util.py[DEBUG]: Reading from /proc/self/status (quiet=False)
2019-03-29 11:25:04,273 - util.py[DEBUG]: Read 966 bytes from /proc/self/status
2019-03-29 11:25:04,273 - util.py[DEBUG]: querying dmi data /sys/class/dmi/id/product_serial
2019-03-29 11:25:04,273 - util.py[DEBUG]: Reading from /sys/class/dmi/id/product_serial (quiet=False)
2019-03-29 11:25:04,273 - util.py[DEBUG]: Read 37 bytes from /sys/class/dmi/id/product_serial
2019-03-29 11:25:04,274 - util.py[DEBUG]: dmi data /sys/class/dmi/id/product_serial returned ec266cc0-73c7-15bc-182d-74c083574a38
2019-03-29 11:25:04,274 - util.py[DEBUG]: Reading from /var/lib/cloud/seed/nocloud/user-data (quiet=False)
2019-03-29 11:25:04,274 - util.py[DEBUG]: Reading from /var/lib/cloud/seed/nocloud/meta-data (quiet=False)
2019-03-29 11:25:04,274 - util.py[DEBUG]: Reading from /var/lib/cloud/seed/nocloud/vendor-data (quiet=False)
2019-03-29 11:25:04,274 - util.py[DEBUG]: Reading from /var/lib/cloud/seed/nocloud/network-config (quiet=False)
2019-03-29 11:25:04,274 - util.py[DEBUG]: Reading from /var/lib/cloud/seed/nocloud-net/user-data (quiet=False)
2019-03-29 11:25:04,274 - util.py[DEBUG]: Reading from /var/lib/cloud/seed/nocloud-net/meta-data (quiet=False)
2019-03-29 11:25:04,274 - util.py[DEBUG]: Reading from /var/lib/cloud/seed/nocloud-net/vendor-data (quiet=False)
2019-03-29 11:25:04,274 - util.py[DEBUG]: Reading from /var/lib/cloud/seed/nocloud-net/network-config (quiet=False)
2019-03-29 11:25:04,274 - util.py[DEBUG]: Running command ['blkid', '-odevice', '/dev/sr0'] with allowed return codes [0, 2] (shell=False, capture=True)
2019-03-29 11:25:04,276 - util.py[DEBUG]: Running command ['blkid', '-odevice', '/dev/sr1'] with allowed return codes [0, 2] (shell=False, capture=True)
2019-03-29 11:25:04,277 - util.py[DEBUG]: Running command ['blkid', '-tTYPE=vfat', '-odevice'] with allowed return codes [0, 2] (shell=False, capture=True)
2019-03-29 11:25:04,290 - util.py[DEBUG]: Running command ['blkid', '-tTYPE=iso9660', '-odevice'] with allowed return codes [0, 2] (shell=False, capture=True)
2019-03-29 11:25:04,302 - util.py[DEBUG]: Running command ['blkid', '-tLABEL=cidata', '-odevice'] with allowed return codes [0, 2] (shell=False, capture=True)
2019-03-29 11:25:04,314 - handlers.py[DEBUG]: finish: init-local/search-NoCloud: SUCCESS: no local data found from DataSourceNoCloud
2019-03-29 11:25:04,314 - handlers.py[DEBUG]: start: init-local/search-ConfigDrive: searching for local data from DataSourceConfigDrive
2019-03-29 11:25:04,314 - __init__.py[DEBUG]: Seeing if we can get any data from <class 'cloudinit.sources.DataSourceConfigDrive.DataSourceConfigDrive'>
2019-03-29 11:25:04,315 - __init__.py[DEBUG]: Update datasource metadata and network config due to events: New instance first boot
2019-03-29 11:25:04,315 - util.py[DEBUG]: Running command ['blkid', '-odevice', '/dev/sr0'] with allowed return codes [0, 2] (shell=False, capture=True)
2019-03-29 11:25:04,316 - util.py[DEBUG]: Running command ['blkid', '-odevice', '/dev/sr1'] with allowed return codes [0, 2] (shell=False, capture=True)
2019-03-29 11:25:04,318 - util.py[DEBUG]: Running command ['blkid', '-odevice', '/dev/cd0'] with allowed return codes [0, 2] (shell=False, capture=True)
2019-03-29 11:25:04,319 - util.py[DEBUG]: Running command ['blkid', '-odevice', '/dev/cd1'] with allowed return codes [0, 2] (shell=False, capture=True)
2019-03-29 11:25:04,321 - util.py[DEBUG]: Running command ['blkid', '-tTYPE=vfat', '-odevice'] with allowed return codes [0, 2] (shell=False, capture=True)
2019-03-29 11:25:04,333 - util.py[DEBUG]: Running command ['blkid', '-tTYPE=iso9660', '-odevice'] with allowed return codes [0, 2] (shell=False, capture=True)
2019-03-29 11:25:04,345 - util.py[DEBUG]: Running command ['blkid', '-tLABEL=config-2', '-odevice'] with allowed return codes [0, 2] (shell=False, capture=True)
2019-03-29 11:25:04,357 - util.py[DEBUG]: Running command ['blkid', '-tLABEL=CONFIG-2', '-odevice'] with allowed return codes [0, 2] (shell=False, capture=True)
2019-03-29 11:25:04,368 - DataSourceConfigDrive.py[DEBUG]: devices=[] dslist=['NoCloud', 'ConfigDrive', 'OpenNebula', 'DigitalOcean', 'Azure', 'AltCloud', 'OVF', 'MAAS', 'GCE', 'OpenStack', 'CloudSigma', 'SmartOS', 'Bigstep', 'Scaleway', 'AliYun', 'Ec2', 'CloudStack', 'None']
2019-03-29 11:25:04,369 - handlers.py[DEBUG]: finish: init-local/search-ConfigDrive: SUCCESS: no local data found from DataSourceConfigDrive
2019-03-29 11:25:04,369 - handlers.py[DEBUG]: start: init-local/search-OpenNebula: searching for local data from DataSourceOpenNebula
2019-03-29 11:25:04,369 - __init__.py[DEBUG]: Seeing if we can get any data from <class 'cloudinit.sources.DataSourceOpenNebula.DataSourceOpenNebula'>
2019-03-29 11:25:04,369 - __init__.py[DEBUG]: Update datasource metadata and network config due to events: New instance first boot
2019-03-29 11:25:04,369 - util.py[DEBUG]: Running command ['blkid', '-tLABEL=CONTEXT', '-odevice'] with allowed return codes [0, 2] (shell=False, capture=True)
2019-03-29 11:25:04,381 - util.py[DEBUG]: Running command ['blkid', '-tLABEL=CDROM', '-odevice'] with allowed return codes [0, 2] (shell=False, capture=True)
2019-03-29 11:25:04,393 - util.py[DEBUG]: Running command ['blkid', '-tTYPE=iso9660', '-odevice'] with allowed return codes [0, 2] (shell=False, capture=True)
2019-03-29 11:25:04,405 - handlers.py[DEBUG]: finish: init-local/search-OpenNebula: SUCCESS: no local data found from DataSourceOpenNebula
2019-03-29 11:25:04,405 - handlers.py[DEBUG]: start: init-local/search-DigitalOcean: searching for local data from DataSourceDigitalOcean
2019-03-29 11:25:04,405 - __init__.py[DEBUG]: Seeing if we can get any data from <class 'cloudinit.sources.DataSourceDigitalOcean.DataSourceDigitalOcean'>
2019-03-29 11:25:04,405 - __init__.py[DEBUG]: Update datasource metadata and network config due to events: New instance first boot
2019-03-29 11:25:04,405 - util.py[DEBUG]: Running command ['systemd-detect-virt', '--quiet', '--container'] with allowed return codes [0] (shell=False, capture=True)
2019-03-29 11:25:04,407 - util.py[DEBUG]: Running command ['running-in-container'] with allowed return codes [0] (shell=False, capture=True)
2019-03-29 11:25:04,408 - util.py[DEBUG]: Running command ['lxc-is-container'] with allowed return codes [0] (shell=False, capture=True)
2019-03-29 11:25:04,410 - util.py[DEBUG]: Reading from /proc/1/environ (quiet=False)
2019-03-29 11:25:04,410 - util.py[DEBUG]: Read 150 bytes from /proc/1/environ
2019-03-29 11:25:04,410 - util.py[DEBUG]: Reading from /proc/self/status (quiet=False)
2019-03-29 11:25:04,410 - util.py[DEBUG]: Read 966 bytes from /proc/self/status
2019-03-29 11:25:04,411 - util.py[DEBUG]: querying dmi data /sys/class/dmi/id/sys_vendor
2019-03-29 11:25:04,411 - util.py[DEBUG]: Reading from /sys/class/dmi/id/sys_vendor (quiet=False)
2019-03-29 11:25:04,411 - util.py[DEBUG]: Read 4 bytes from /sys/class/dmi/id/sys_vendor
2019-03-29 11:25:04,411 - util.py[DEBUG]: dmi data /sys/class/dmi/id/sys_vendor returned Xen
2019-03-29 11:25:04,411 - handlers.py[DEBUG]: finish: init-local/search-DigitalOcean: SUCCESS: no local data found from DataSourceDigitalOcean
2019-03-29 11:25:04,411 - handlers.py[DEBUG]: start: init-local/search-Azure: searching for local data from DataSourceAzure
2019-03-29 11:25:04,411 - __init__.py[DEBUG]: Seeing if we can get any data from <class 'cloudinit.sources.DataSourceAzure.DataSourceAzure'>
2019-03-29 11:25:04,411 - __init__.py[DEBUG]: Update datasource metadata and network config due to events: New instance first boot
2019-03-29 11:25:04,411 - util.py[DEBUG]: Running command ['systemd-detect-virt', '--quiet', '--container'] with allowed return codes [0] (shell=False, capture=True)
2019-03-29 11:25:04,413 - util.py[DEBUG]: Running command ['running-in-container'] with allowed return codes [0] (shell=False, capture=True)
2019-03-29 11:25:04,415 - util.py[DEBUG]: Running command ['lxc-is-container'] with allowed return codes [0] (shell=False, capture=True)
2019-03-29 11:25:04,416 - util.py[DEBUG]: Reading from /proc/1/environ (quiet=False)
2019-03-29 11:25:04,416 - util.py[DEBUG]: Read 150 bytes from /proc/1/environ
2019-03-29 11:25:04,417 - util.py[DEBUG]: Reading from /proc/self/status (quiet=False)
2019-03-29 11:25:04,417 - util.py[DEBUG]: Read 966 bytes from /proc/self/status
2019-03-29 11:25:04,417 - util.py[DEBUG]: querying dmi data /sys/class/dmi/id/chassis_asset_tag
2019-03-29 11:25:04,417 - util.py[DEBUG]: Reading from /sys/class/dmi/id/chassis_asset_tag (quiet=False)
2019-03-29 11:25:04,417 - util.py[DEBUG]: Read 1 bytes from /sys/class/dmi/id/chassis_asset_tag
2019-03-29 11:25:04,417 - util.py[DEBUG]: dmi data /sys/class/dmi/id/chassis_asset_tag returned 
2019-03-29 11:25:04,417 - DataSourceAzure.py[DEBUG]: Non-Azure DMI asset tag '' discovered.
2019-03-29 11:25:04,417 - handlers.py[DEBUG]: finish: init-local/search-Azure: SUCCESS: no local data found from DataSourceAzure
2019-03-29 11:25:04,417 - handlers.py[DEBUG]: start: init-local/search-OVF: searching for local data from DataSourceOVF
2019-03-29 11:25:04,417 - __init__.py[DEBUG]: Seeing if we can get any data from <class 'cloudinit.sources.DataSourceOVF.DataSourceOVF'>
2019-03-29 11:25:04,417 - __init__.py[DEBUG]: Update datasource metadata and network config due to events: New instance first boot
2019-03-29 11:25:04,417 - util.py[DEBUG]: Running command ['systemd-detect-virt', '--quiet', '--container'] with allowed return codes [0] (shell=False, capture=True)
2019-03-29 11:25:04,419 - util.py[DEBUG]: Running command ['running-in-container'] with allowed return codes [0] (shell=False, capture=True)
2019-03-29 11:25:04,421 - util.py[DEBUG]: Running command ['lxc-is-container'] with allowed return codes [0] (shell=False, capture=True)
2019-03-29 11:25:04,422 - util.py[DEBUG]: Reading from /proc/1/environ (quiet=False)
2019-03-29 11:25:04,422 - util.py[DEBUG]: Read 150 bytes from /proc/1/environ
2019-03-29 11:25:04,422 - util.py[DEBUG]: Reading from /proc/self/status (quiet=False)
2019-03-29 11:25:04,422 - util.py[DEBUG]: Read 966 bytes from /proc/self/status
2019-03-29 11:25:04,423 - util.py[DEBUG]: querying dmi data /sys/class/dmi/id/product_name
2019-03-29 11:25:04,423 - util.py[DEBUG]: Reading from /sys/class/dmi/id/product_name (quiet=False)
2019-03-29 11:25:04,423 - util.py[DEBUG]: Read 9 bytes from /sys/class/dmi/id/product_name
2019-03-29 11:25:04,423 - util.py[DEBUG]: dmi data /sys/class/dmi/id/product_name returned HVM domU
2019-03-29 11:25:04,423 - util.py[DEBUG]: Reading from /proc/mounts (quiet=False)
2019-03-29 11:25:04,423 - util.py[DEBUG]: Read 1991 bytes from /proc/mounts
2019-03-29 11:25:04,423 - util.py[DEBUG]: Fetched {'udev': {'fstype': 'devtmpfs', 'mountpoint': '/dev', 'opts': 'rw,nosuid,relatime,size=30907648k,nr_inodes=7726912,mode=755'}, 'securityfs': {'fstype': 'securityfs', 'mountpoint': '/sys/kernel/security', 'opts': 'rw,nosuid,nodev,noexec,relatime'}, '/dev/xvda1': {'fstype': 'ext4', 'mountpoint': '/', 'opts': 'rw,relatime,discard,data=ordered'}, 'sysfs': {'fstype': 'sysfs', 'mountpoint': '/sys', 'opts': 'rw,nosuid,nodev,noexec,relatime'}, 'debugfs': {'fstype': 'debugfs', 'mountpoint': '/sys/kernel/debug', 'opts': 'rw,relatime'}, 'pstore': {'fstype': 'pstore', 'mountpoint': '/sys/fs/pstore', 'opts': 'rw,nosuid,nodev,noexec,relatime'}, 'hugetlbfs': {'fstype': 'hugetlbfs', 'mountpoint': '/dev/hugepages', 'opts': 'rw,relatime'}, 'devpts': {'fstype': 'devpts', 'mountpoint': '/dev/pts', 'opts': 'rw,nosuid,noexec,relatime,gid=5,mode=620,ptmxmode=000'}, 'proc': {'fstype': 'proc', 'mountpoint': '/proc', 'opts': 'rw,nosuid,nodev,noexec,relatime'}, 'mqueue': {'fstype': 'mqueue', 'mountpoint': '/dev/mqueue', 'opts': 'rw,relatime'}, 'systemd-1': {'fstype': 'autofs', 'mountpoint': '/proc/sys/fs/binfmt_misc', 'opts': 'rw,relatime,fd=33,pgrp=1,timeout=0,minproto=5,maxproto=5,direct'}, 'tmpfs': {'fstype': 'tmpfs', 'mountpoint': '/sys/fs/cgroup', 'opts': 'ro,nosuid,nodev,noexec,mode=755'}, 'fusectl': {'fstype': 'fusectl', 'mountpoint': '/sys/fs/fuse/connections', 'opts': 'rw,relatime'}, 'cgroup': {'fstype': 'cgroup', 'mountpoint': '/sys/fs/cgroup/pids', 'opts': 'rw,nosuid,nodev,noexec,relatime,pids'}} mounts from proc
2019-03-29 11:25:04,423 - util.py[DEBUG]: Running command ['blkid', '-tTYPE=iso9660', '-odevice'] with allowed return codes [0, 2] (shell=False, capture=True)
2019-03-29 11:25:04,435 - handlers.py[DEBUG]: finish: init-local/search-OVF: SUCCESS: no local data found from DataSourceOVF
2019-03-29 11:25:04,435 - handlers.py[DEBUG]: start: init-local/search-OpenStackLocal: searching for local data from DataSourceOpenStackLocal
2019-03-29 11:25:04,435 - __init__.py[DEBUG]: Seeing if we can get any data from <class 'cloudinit.sources.DataSourceOpenStack.DataSourceOpenStackLocal'>
2019-03-29 11:25:04,436 - __init__.py[DEBUG]: Update datasource metadata and network config due to events: New instance first boot
2019-03-29 11:25:04,436 - util.py[DEBUG]: Running command ['systemd-detect-virt', '--quiet', '--container'] with allowed return codes [0] (shell=False, capture=True)
2019-03-29 11:25:04,437 - util.py[DEBUG]: Running command ['running-in-container'] with allowed return codes [0] (shell=False, capture=True)
2019-03-29 11:25:04,439 - util.py[DEBUG]: Running command ['lxc-is-container'] with allowed return codes [0] (shell=False, capture=True)
2019-03-29 11:25:04,440 - util.py[DEBUG]: Reading from /proc/1/environ (quiet=False)
2019-03-29 11:25:04,441 - util.py[DEBUG]: Read 150 bytes from /proc/1/environ
2019-03-29 11:25:04,441 - util.py[DEBUG]: Reading from /proc/self/status (quiet=False)
2019-03-29 11:25:04,441 - util.py[DEBUG]: Read 966 bytes from /proc/self/status
2019-03-29 11:25:04,441 - util.py[DEBUG]: querying dmi data /sys/class/dmi/id/product_name
2019-03-29 11:25:04,441 - util.py[DEBUG]: Reading from /sys/class/dmi/id/product_name (quiet=False)
2019-03-29 11:25:04,441 - util.py[DEBUG]: Read 9 bytes from /sys/class/dmi/id/product_name
2019-03-29 11:25:04,441 - util.py[DEBUG]: dmi data /sys/class/dmi/id/product_name returned HVM domU
2019-03-29 11:25:04,441 - util.py[DEBUG]: Running command ['systemd-detect-virt', '--quiet', '--container'] with allowed return codes [0] (shell=False, capture=True)
2019-03-29 11:25:04,443 - util.py[DEBUG]: Running command ['running-in-container'] with allowed return codes [0] (shell=False, capture=True)
2019-03-29 11:25:04,444 - util.py[DEBUG]: Running command ['lxc-is-container'] with allowed return codes [0] (shell=False, capture=True)
2019-03-29 11:25:04,446 - util.py[DEBUG]: Reading from /proc/1/environ (quiet=False)
2019-03-29 11:25:04,446 - util.py[DEBUG]: Read 150 bytes from /proc/1/environ
2019-03-29 11:25:04,446 - util.py[DEBUG]: Reading from /proc/self/status (quiet=False)
2019-03-29 11:25:04,446 - util.py[DEBUG]: Read 966 bytes from /proc/self/status
2019-03-29 11:25:04,446 - util.py[DEBUG]: querying dmi data /sys/class/dmi/id/chassis_asset_tag
2019-03-29 11:25:04,446 - util.py[DEBUG]: Reading from /sys/class/dmi/id/chassis_asset_tag (quiet=False)
2019-03-29 11:25:04,447 - util.py[DEBUG]: Read 1 bytes from /sys/class/dmi/id/chassis_asset_tag
2019-03-29 11:25:04,447 - util.py[DEBUG]: dmi data /sys/class/dmi/id/chassis_asset_tag returned 
2019-03-29 11:25:04,447 - util.py[DEBUG]: Reading from /proc/1/environ (quiet=False)
2019-03-29 11:25:04,447 - util.py[DEBUG]: Read 150 bytes from /proc/1/environ
2019-03-29 11:25:04,447 - handlers.py[DEBUG]: finish: init-local/search-OpenStackLocal: SUCCESS: no local data found from DataSourceOpenStackLocal
2019-03-29 11:25:04,447 - handlers.py[DEBUG]: start: init-local/search-CloudSigma: searching for local data from DataSourceCloudSigma
2019-03-29 11:25:04,447 - __init__.py[DEBUG]: Seeing if we can get any data from <class 'cloudinit.sources.DataSourceCloudSigma.DataSourceCloudSigma'>
2019-03-29 11:25:04,447 - __init__.py[DEBUG]: Update datasource metadata and network config due to events: New instance first boot
2019-03-29 11:25:04,447 - DataSourceCloudSigma.py[DEBUG]: determining hypervisor product name via dmi data
2019-03-29 11:25:04,447 - util.py[DEBUG]: Running command ['systemd-detect-virt', '--quiet', '--container'] with allowed return codes [0] (shell=False, capture=True)
2019-03-29 11:25:04,449 - util.py[DEBUG]: Running command ['running-in-container'] with allowed return codes [0] (shell=False, capture=True)
2019-03-29 11:25:04,451 - util.py[DEBUG]: Running command ['lxc-is-container'] with allowed return codes [0] (shell=False, capture=True)
2019-03-29 11:25:04,452 - util.py[DEBUG]: Reading from /proc/1/environ (quiet=False)
2019-03-29 11:25:04,453 - util.py[DEBUG]: Read 150 bytes from /proc/1/environ
2019-03-29 11:25:04,453 - util.py[DEBUG]: Reading from /proc/self/status (quiet=False)
2019-03-29 11:25:04,453 - util.py[DEBUG]: Read 966 bytes from /proc/self/status
2019-03-29 11:25:04,453 - util.py[DEBUG]: querying dmi data /sys/class/dmi/id/product_name
2019-03-29 11:25:04,453 - util.py[DEBUG]: Reading from /sys/class/dmi/id/product_name (quiet=False)
2019-03-29 11:25:04,453 - util.py[DEBUG]: Read 9 bytes from /sys/class/dmi/id/product_name
2019-03-29 11:25:04,453 - util.py[DEBUG]: dmi data /sys/class/dmi/id/product_name returned HVM domU
2019-03-29 11:25:04,453 - DataSourceCloudSigma.py[DEBUG]: detected hypervisor as HVM domU
2019-03-29 11:25:04,453 - handlers.py[DEBUG]: finish: init-local/search-CloudSigma: SUCCESS: no local data found from DataSourceCloudSigma
2019-03-29 11:25:04,453 - handlers.py[DEBUG]: start: init-local/search-SmartOS: searching for local data from DataSourceSmartOS
2019-03-29 11:25:04,453 - __init__.py[DEBUG]: Seeing if we can get any data from <class 'cloudinit.sources.DataSourceSmartOS.DataSourceSmartOS'>
2019-03-29 11:25:04,454 - util.py[DEBUG]: Running command ['systemd-detect-virt', '--quiet', '--container'] with allowed return codes [0] (shell=False, capture=True)
2019-03-29 11:25:04,455 - util.py[DEBUG]: Running command ['running-in-container'] with allowed return codes [0] (shell=False, capture=True)
2019-03-29 11:25:04,457 - util.py[DEBUG]: Running command ['lxc-is-container'] with allowed return codes [0] (shell=False, capture=True)
2019-03-29 11:25:04,459 - util.py[DEBUG]: Reading from /proc/1/environ (quiet=False)
2019-03-29 11:25:04,459 - util.py[DEBUG]: Read 150 bytes from /proc/1/environ
2019-03-29 11:25:04,459 - util.py[DEBUG]: Reading from /proc/self/status (quiet=False)
2019-03-29 11:25:04,459 - util.py[DEBUG]: Read 966 bytes from /proc/self/status
2019-03-29 11:25:04,459 - util.py[DEBUG]: querying dmi data /sys/class/dmi/id/product_name
2019-03-29 11:25:04,459 - util.py[DEBUG]: Reading from /sys/class/dmi/id/product_name (quiet=False)
2019-03-29 11:25:04,459 - util.py[DEBUG]: Read 9 bytes from /sys/class/dmi/id/product_name
2019-03-29 11:25:04,459 - util.py[DEBUG]: dmi data /sys/class/dmi/id/product_name returned HVM domU
2019-03-29 11:25:04,459 - __init__.py[DEBUG]: Update datasource metadata and network config due to events: New instance first boot
2019-03-29 11:25:04,459 - DataSourceSmartOS.py[DEBUG]: Not running on smartos
2019-03-29 11:25:04,460 - handlers.py[DEBUG]: finish: init-local/search-SmartOS: SUCCESS: no local data found from DataSourceSmartOS
2019-03-29 11:25:04,460 - handlers.py[DEBUG]: start: init-local/search-Ec2Local: searching for local data from DataSourceEc2Local
2019-03-29 11:25:04,460 - __init__.py[DEBUG]: Seeing if we can get any data from <class 'cloudinit.sources.DataSourceEc2.DataSourceEc2Local'>
2019-03-29 11:25:04,460 - __init__.py[DEBUG]: Update datasource metadata and network config due to events: New instance first boot
2019-03-29 11:25:04,460 - util.py[DEBUG]: Reading from /sys/hypervisor/uuid (quiet=False)
2019-03-29 11:25:04,460 - util.py[DEBUG]: Read 37 bytes from /sys/hypervisor/uuid
2019-03-29 11:25:04,460 - util.py[DEBUG]: Running command ['systemd-detect-virt', '--quiet', '--container'] with allowed return codes [0] (shell=False, capture=True)
2019-03-29 11:25:04,462 - util.py[DEBUG]: Running command ['running-in-container'] with allowed return codes [0] (shell=False, capture=True)
2019-03-29 11:25:04,464 - util.py[DEBUG]: Running command ['lxc-is-container'] with allowed return codes [0] (shell=False, capture=True)
2019-03-29 11:25:04,465 - util.py[DEBUG]: Reading from /proc/1/environ (quiet=False)
2019-03-29 11:25:04,465 - util.py[DEBUG]: Read 150 bytes from /proc/1/environ
2019-03-29 11:25:04,465 - util.py[DEBUG]: Reading from /proc/self/status (quiet=False)
2019-03-29 11:25:04,465 - util.py[DEBUG]: Read 966 bytes from /proc/self/status
2019-03-29 11:25:04,465 - util.py[DEBUG]: querying dmi data /sys/class/dmi/id/product_serial
2019-03-29 11:25:04,466 - util.py[DEBUG]: Reading from /sys/class/dmi/id/product_serial (quiet=False)
2019-03-29 11:25:04,466 - util.py[DEBUG]: Read 37 bytes from /sys/class/dmi/id/product_serial
2019-03-29 11:25:04,466 - util.py[DEBUG]: dmi data /sys/class/dmi/id/product_serial returned ec266cc0-73c7-15bc-182d-74c083574a38
2019-03-29 11:25:04,466 - DataSourceEc2.py[DEBUG]: strict_mode: warn, cloud_platform=AWS
2019-03-29 11:25:04,466 - util.py[DEBUG]: Reading from /etc/os-release (quiet=False)
2019-03-29 11:25:04,466 - util.py[DEBUG]: Read 298 bytes from /etc/os-release
2019-03-29 11:25:04,466 - util.py[DEBUG]: Reading from /sys/class/net/ens3/name_assign_type (quiet=False)
2019-03-29 11:25:04,466 - util.py[DEBUG]: Read 2 bytes from /sys/class/net/ens3/name_assign_type
2019-03-29 11:25:04,467 - util.py[DEBUG]: Reading from /sys/class/net/ens3/carrier (quiet=False)
2019-03-29 11:25:04,467 - util.py[DEBUG]: Reading from /sys/class/net/ens3/dormant (quiet=False)
2019-03-29 11:25:04,467 - util.py[DEBUG]: Reading from /sys/class/net/ens3/operstate (quiet=False)
2019-03-29 11:25:04,467 - util.py[DEBUG]: Read 5 bytes from /sys/class/net/ens3/operstate
2019-03-29 11:25:04,467 - util.py[DEBUG]: Reading from /sys/class/net/ens3/address (quiet=False)
2019-03-29 11:25:04,467 - util.py[DEBUG]: Read 18 bytes from /sys/class/net/ens3/address
2019-03-29 11:25:04,467 - dhcp.py[DEBUG]: Performing a dhcp discovery on ens3
2019-03-29 11:25:04,467 - util.py[DEBUG]: Copying /sbin/dhclient to /var/tmp/cloud-init/cloud-init-dhcp-eodhorzn/dhclient
2019-03-29 11:25:04,482 - util.py[DEBUG]: Running command ['ip', 'link', 'set', 'dev', 'ens3', 'up'] with allowed return codes [0] (shell=False, capture=True)
2019-03-29 11:25:04,501 - util.py[DEBUG]: Running command ['/var/tmp/cloud-init/cloud-init-dhcp-eodhorzn/dhclient', '-1', '-v', '-lf', '/var/tmp/cloud-init/cloud-init-dhcp-eodhorzn/dhcp.leases', '-pf', '/var/tmp/cloud-init/cloud-init-dhcp-eodhorzn/dhclient.pid', 'ens3', '-sf', '/bin/true'] with allowed return codes [0] (shell=False, capture=True)
2019-03-29 11:25:04,583 - util.py[DEBUG]: All files appeared after 0 seconds: ['/var/tmp/cloud-init/cloud-init-dhcp-eodhorzn/dhclient.pid', '/var/tmp/cloud-init/cloud-init-dhcp-eodhorzn/dhcp.leases']
2019-03-29 11:25:04,583 - util.py[DEBUG]: Reading from /var/tmp/cloud-init/cloud-init-dhcp-eodhorzn/dhclient.pid (quiet=False)
2019-03-29 11:25:04,583 - util.py[DEBUG]: Read 5 bytes from /var/tmp/cloud-init/cloud-init-dhcp-eodhorzn/dhclient.pid
2019-03-29 11:25:04,583 - util.py[DEBUG]: Reading from /var/tmp/cloud-init/cloud-init-dhcp-eodhorzn/dhcp.leases (quiet=False)
2019-03-29 11:25:04,583 - util.py[DEBUG]: Read 513 bytes from /var/tmp/cloud-init/cloud-init-dhcp-eodhorzn/dhcp.leases
2019-03-29 11:25:04,584 - dhcp.py[DEBUG]: Received dhcp lease on ens3 for 10.0.0.206/255.255.255.0
2019-03-29 11:25:04,584 - __init__.py[DEBUG]: Attempting setup of ephemeral network on ens3 with 10.0.0.206/24 brd 10.0.0.255
2019-03-29 11:25:04,584 - util.py[DEBUG]: Running command ['ip', '-family', 'inet', 'addr', 'add', '10.0.0.206/24', 'broadcast', '10.0.0.255', 'dev', 'ens3'] with allowed return codes [0] (shell=False, capture=True)
2019-03-29 11:25:04,586 - util.py[DEBUG]: Running command ['ip', '-family', 'inet', 'link', 'set', 'dev', 'ens3', 'up'] with allowed return codes [0] (shell=False, capture=True)
2019-03-29 11:25:04,589 - util.py[DEBUG]: Running command ['ip', 'route', 'show', '0.0.0.0/0'] with allowed return codes [0] (shell=False, capture=True)
2019-03-29 11:25:04,590 - util.py[DEBUG]: Running command ['ip', '-4', 'route', 'add', 'default', 'via', '10.0.0.1', 'dev', 'ens3'] with allowed return codes [0] (shell=False, capture=True)
2019-03-29 11:25:04,595 - util.py[DEBUG]: Resolving URL: http://169.254.169.254 took 0.003 seconds
2019-03-29 11:25:04,595 - util.py[DEBUG]: Resolving URL: http://instance-data.:8773 took 0.000 seconds
2019-03-29 11:25:04,595 - DataSourceEc2.py[DEBUG]: Removed the following from metadata urls: ['http://instance-data.:8773']
2019-03-29 11:25:04,595 - url_helper.py[DEBUG]: [0/1] open 'http://169.254.169.254/2009-04-04/meta-data/instance-id' with {'headers': {'User-Agent': 'Cloud-Init/18.3-9-g2e62cb8a-0ubuntu1~16.04.2'}, 'method': 'GET', 'timeout': 50.0, 'url': 'http://169.254.169.254/2009-04-04/meta-data/instance-id', 'allow_redirects': True} configuration
2019-03-29 11:25:04,600 - url_helper.py[DEBUG]: Read from http://169.254.169.254/2009-04-04/meta-data/instance-id (200, 19b) after 1 attempts
2019-03-29 11:25:04,600 - DataSourceEc2.py[DEBUG]: Using metadata source: 'http://169.254.169.254'
2019-03-29 11:25:04,600 - url_helper.py[DEBUG]: [0/1] open 'http://169.254.169.254/2016-09-02/meta-data/instance-id' with {'headers': {'User-Agent': 'Cloud-Init/18.3-9-g2e62cb8a-0ubuntu1~16.04.2'}, 'method': 'GET', 'url': 'http://169.254.169.254/2016-09-02/meta-data/instance-id', 'allow_redirects': True} configuration
2019-03-29 11:25:04,602 - url_helper.py[DEBUG]: Read from http://169.254.169.254/2016-09-02/meta-data/instance-id (200, 19b) after 1 attempts
2019-03-29 11:25:04,602 - DataSourceEc2.py[DEBUG]: Found preferred metadata version 2016-09-02
2019-03-29 11:25:04,602 - url_helper.py[DEBUG]: [0/6] open 'http://169.254.169.254/2016-09-02/user-data' with {'headers': {'User-Agent': 'Cloud-Init/18.3-9-g2e62cb8a-0ubuntu1~16.04.2'}, 'method': 'GET', 'timeout': 5.0, 'url': 'http://169.254.169.254/2016-09-02/user-data', 'allow_redirects': True} configuration
2019-03-29 11:25:04,604 - url_helper.py[DEBUG]: [0/6] open 'http://169.254.169.254/2016-09-02/meta-data/' with {'headers': {'User-Agent': 'Cloud-Init/18.3-9-g2e62cb8a-0ubuntu1~16.04.2'}, 'method': 'GET', 'timeout': 5.0, 'url': 'http://169.254.169.254/2016-09-02/meta-data/', 'allow_redirects': True} configuration
2019-03-29 11:25:04,605 - url_helper.py[DEBUG]: Read from http://169.254.169.254/2016-09-02/meta-data/ (200, 268b) after 1 attempts
2019-03-29 11:25:04,605 - url_helper.py[DEBUG]: [0/6] open 'http://169.254.169.254/2016-09-02/meta-data/block-device-mapping/' with {'headers': {'User-Agent': 'Cloud-Init/18.3-9-g2e62cb8a-0ubuntu1~16.04.2'}, 'method': 'GET', 'timeout': 5.0, 'url': 'http://169.254.169.254/2016-09-02/meta-data/block-device-mapping/', 'allow_redirects': True} configuration
2019-03-29 11:25:04,607 - url_helper.py[DEBUG]: Read from http://169.254.169.254/2016-09-02/meta-data/block-device-mapping/ (200, 30b) after 1 attempts
2019-03-29 11:25:04,607 - url_helper.py[DEBUG]: [0/6] open 'http://169.254.169.254/2016-09-02/meta-data/block-device-mapping/ephemeral1' with {'headers': {'User-Agent': 'Cloud-Init/18.3-9-g2e62cb8a-0ubuntu1~16.04.2'}, 'method': 'GET', 'timeout': 5.0, 'url': 'http://169.254.169.254/2016-09-02/meta-data/block-device-mapping/ephemeral1', 'allow_redirects': True} configuration
2019-03-29 11:25:04,608 - url_helper.py[DEBUG]: Read from http://169.254.169.254/2016-09-02/meta-data/block-device-mapping/ephemeral1 (200, 3b) after 1 attempts
2019-03-29 11:25:04,609 - url_helper.py[DEBUG]: [0/6] open 'http://169.254.169.254/2016-09-02/meta-data/block-device-mapping/ami' with {'headers': {'User-Agent': 'Cloud-Init/18.3-9-g2e62cb8a-0ubuntu1~16.04.2'}, 'method': 'GET', 'timeout': 5.0, 'url': 'http://169.254.169.254/2016-09-02/meta-data/block-device-mapping/ami', 'allow_redirects': True} configuration
2019-03-29 11:25:04,610 - url_helper.py[DEBUG]: Read from http://169.254.169.254/2016-09-02/meta-data/block-device-mapping/ami (200, 9b) after 1 attempts
2019-03-29 11:25:04,610 - url_helper.py[DEBUG]: [0/6] open 'http://169.254.169.254/2016-09-02/meta-data/block-device-mapping/root' with {'headers': {'User-Agent': 'Cloud-Init/18.3-9-g2e62cb8a-0ubuntu1~16.04.2'}, 'method': 'GET', 'timeout': 5.0, 'url': 'http://169.254.169.254/2016-09-02/meta-data/block-device-mapping/root', 'allow_redirects': True} configuration
2019-03-29 11:25:04,612 - url_helper.py[DEBUG]: Read from http://169.254.169.254/2016-09-02/meta-data/block-device-mapping/root (200, 9b) after 1 attempts
2019-03-29 11:25:04,612 - url_helper.py[DEBUG]: [0/6] open 'http://169.254.169.254/2016-09-02/meta-data/block-device-mapping/ephemeral0' with {'headers': {'User-Agent': 'Cloud-Init/18.3-9-g2e62cb8a-0ubuntu1~16.04.2'}, 'method': 'GET', 'timeout': 5.0, 'url': 'http://169.254.169.254/2016-09-02/meta-data/block-device-mapping/ephemeral0', 'allow_redirects': True} configuration
2019-03-29 11:25:04,613 - url_helper.py[DEBUG]: Read from http://169.254.169.254/2016-09-02/meta-data/block-device-mapping/ephemeral0 (200, 3b) after 1 attempts
2019-03-29 11:25:04,613 - url_helper.py[DEBUG]: [0/6] open 'http://169.254.169.254/2016-09-02/meta-data/iam/' with {'headers': {'User-Agent': 'Cloud-Init/18.3-9-g2e62cb8a-0ubuntu1~16.04.2'}, 'method': 'GET', 'timeout': 5.0, 'url': 'http://169.254.169.254/2016-09-02/meta-data/iam/', 'allow_redirects': True} configuration
2019-03-29 11:25:04,615 - url_helper.py[DEBUG]: Read from http://169.254.169.254/2016-09-02/meta-data/iam/ (200, 26b) after 1 attempts
2019-03-29 11:25:04,615 - url_helper.py[DEBUG]: [0/6] open 'http://169.254.169.254/2016-09-02/meta-data/iam/info' with {'headers': {'User-Agent': 'Cloud-Init/18.3-9-g2e62cb8a-0ubuntu1~16.04.2'}, 'method': 'GET', 'timeout': 5.0, 'url': 'http://169.254.169.254/2016-09-02/meta-data/iam/info', 'allow_redirects': True} configuration
2019-03-29 11:25:04,616 - url_helper.py[DEBUG]: Read from http://169.254.169.254/2016-09-02/meta-data/iam/info (200, 245b) after 1 attempts
2019-03-29 11:25:04,617 - url_helper.py[DEBUG]: [0/6] open 'http://169.254.169.254/2016-09-02/meta-data/metrics/' with {'headers': {'User-Agent': 'Cloud-Init/18.3-9-g2e62cb8a-0ubuntu1~16.04.2'}, 'method': 'GET', 'timeout': 5.0, 'url': 'http://169.254.169.254/2016-09-02/meta-data/metrics/', 'allow_redirects': True} configuration
2019-03-29 11:25:04,618 - url_helper.py[DEBUG]: Read from http://169.254.169.254/2016-09-02/meta-data/metrics/ (200, 7b) after 1 attempts
2019-03-29 11:25:04,618 - url_helper.py[DEBUG]: [0/6] open 'http://169.254.169.254/2016-09-02/meta-data/metrics/vhostmd' with {'headers': {'User-Agent': 'Cloud-Init/18.3-9-g2e62cb8a-0ubuntu1~16.04.2'}, 'method': 'GET', 'timeout': 5.0, 'url': 'http://169.254.169.254/2016-09-02/meta-data/metrics/vhostmd', 'allow_redirects': True} configuration
2019-03-29 11:25:04,620 - url_helper.py[DEBUG]: Read from http://169.254.169.254/2016-09-02/meta-data/metrics/vhostmd (200, 38b) after 1 attempts
2019-03-29 11:25:04,620 - url_helper.py[DEBUG]: [0/6] open 'http://169.254.169.254/2016-09-02/meta-data/network/' with {'headers': {'User-Agent': 'Cloud-Init/18.3-9-g2e62cb8a-0ubuntu1~16.04.2'}, 'method': 'GET', 'timeout': 5.0, 'url': 'http://169.254.169.254/2016-09-02/meta-data/network/', 'allow_redirects': True} configuration
2019-03-29 11:25:04,621 - url_helper.py[DEBUG]: Read from http://169.254.169.254/2016-09-02/meta-data/network/ (200, 11b) after 1 attempts
2019-03-29 11:25:04,622 - url_helper.py[DEBUG]: [0/6] open 'http://169.254.169.254/2016-09-02/meta-data/network/interfaces/' with {'headers': {'User-Agent': 'Cloud-Init/18.3-9-g2e62cb8a-0ubuntu1~16.04.2'}, 'method': 'GET', 'timeout': 5.0, 'url': 'http://169.254.169.254/2016-09-02/meta-data/network/interfaces/', 'allow_redirects': True} configuration
2019-03-29 11:25:04,623 - url_helper.py[DEBUG]: Read from http://169.254.169.254/2016-09-02/meta-data/network/interfaces/ (200, 5b) after 1 attempts
2019-03-29 11:25:04,623 - url_helper.py[DEBUG]: [0/6] open 'http://169.254.169.254/2016-09-02/meta-data/network/interfaces/macs/' with {'headers': {'User-Agent': 'Cloud-Init/18.3-9-g2e62cb8a-0ubuntu1~16.04.2'}, 'method': 'GET', 'timeout': 5.0, 'url': 'http://169.254.169.254/2016-09-02/meta-data/network/interfaces/macs/', 'allow_redirects': True} configuration
2019-03-29 11:25:04,625 - url_helper.py[DEBUG]: Read from http://169.254.169.254/2016-09-02/meta-data/network/interfaces/macs/ (200, 18b) after 1 attempts
2019-03-29 11:25:04,625 - url_helper.py[DEBUG]: [0/6] open 'http://169.254.169.254/2016-09-02/meta-data/network/interfaces/macs/06:a9:33:51:95:b8/' with {'headers': {'User-Agent': 'Cloud-Init/18.3-9-g2e62cb8a-0ubuntu1~16.04.2'}, 'method': 'GET', 'timeout': 5.0, 'url': 'http://169.254.169.254/2016-09-02/meta-data/network/interfaces/macs/06:a9:33:51:95:b8/', 'allow_redirects': True} configuration
2019-03-29 11:25:04,626 - url_helper.py[DEBUG]: Read from http://169.254.169.254/2016-09-02/meta-data/network/interfaces/macs/06:a9:33:51:95:b8/ (200, 230b) after 1 attempts
2019-03-29 11:25:04,626 - url_helper.py[DEBUG]: [0/6] open 'http://169.254.169.254/2016-09-02/meta-data/network/interfaces/macs/06:a9:33:51:95:b8/ipv4-associations/' with {'headers': {'User-Agent': 'Cloud-Init/18.3-9-g2e62cb8a-0ubuntu1~16.04.2'}, 'method': 'GET', 'timeout': 5.0, 'url': 'http://169.254.169.254/2016-09-02/meta-data/network/interfaces/macs/06:a9:33:51:95:b8/ipv4-associations/', 'allow_redirects': True} configuration
2019-03-29 11:25:04,628 - url_helper.py[DEBUG]: Read from http://169.254.169.254/2016-09-02/meta-data/network/interfaces/macs/06:a9:33:51:95:b8/ipv4-associations/ (200, 14b) after 1 attempts
2019-03-29 11:25:04,628 - url_helper.py[DEBUG]: [0/6] open 'http://169.254.169.254/2016-09-02/meta-data/network/interfaces/macs/06:a9:33:51:95:b8/ipv4-associations/34.253.194.244' with {'headers': {'User-Agent': 'Cloud-Init/18.3-9-g2e62cb8a-0ubuntu1~16.04.2'}, 'method': 'GET', 'timeout': 5.0, 'url': 'http://169.254.169.254/2016-09-02/meta-data/network/interfaces/macs/06:a9:33:51:95:b8/ipv4-associations/34.253.194.244', 'allow_redirects': True} configuration
2019-03-29 11:25:04,629 - url_helper.py[DEBUG]: Read from http://169.254.169.254/2016-09-02/meta-data/network/interfaces/macs/06:a9:33:51:95:b8/ipv4-associations/34.253.194.244 (200, 10b) after 1 attempts
2019-03-29 11:25:04,630 - url_helper.py[DEBUG]: [0/6] open 'http://169.254.169.254/2016-09-02/meta-data/network/interfaces/macs/06:a9:33:51:95:b8/device-number' with {'headers': {'User-Agent': 'Cloud-Init/18.3-9-g2e62cb8a-0ubuntu1~16.04.2'}, 'method': 'GET', 'timeout': 5.0, 'url': 'http://169.254.169.254/2016-09-02/meta-data/network/interfaces/macs/06:a9:33:51:95:b8/device-number', 'allow_redirects': True} configuration
2019-03-29 11:25:04,631 - url_helper.py[DEBUG]: Read from http://169.254.169.254/2016-09-02/meta-data/network/interfaces/macs/06:a9:33:51:95:b8/device-number (200, 1b) after 1 attempts
2019-03-29 11:25:04,631 - url_helper.py[DEBUG]: [0/6] open 'http://169.254.169.254/2016-09-02/meta-data/network/interfaces/macs/06:a9:33:51:95:b8/vpc-ipv4-cidr-block' with {'headers': {'User-Agent': 'Cloud-Init/18.3-9-g2e62cb8a-0ubuntu1~16.04.2'}, 'method': 'GET', 'timeout': 5.0, 'url': 'http://169.254.169.254/2016-09-02/meta-data/network/interfaces/macs/06:a9:33:51:95:b8/vpc-ipv4-cidr-block', 'allow_redirects': True} configuration
2019-03-29 11:25:04,633 - url_helper.py[DEBUG]: Read from http://169.254.169.254/2016-09-02/meta-data/network/interfaces/macs/06:a9:33:51:95:b8/vpc-ipv4-cidr-block (200, 11b) after 1 attempts
2019-03-29 11:25:04,633 - url_helper.py[DEBUG]: [0/6] open 'http://169.254.169.254/2016-09-02/meta-data/network/interfaces/macs/06:a9:33:51:95:b8/owner-id' with {'headers': {'User-Agent': 'Cloud-Init/18.3-9-g2e62cb8a-0ubuntu1~16.04.2'}, 'method': 'GET', 'timeout': 5.0, 'url': 'http://169.254.169.254/2016-09-02/meta-data/network/interfaces/macs/06:a9:33:51:95:b8/owner-id', 'allow_redirects': True} configuration
2019-03-29 11:25:04,634 - url_helper.py[DEBUG]: Read from http://169.254.169.254/2016-09-02/meta-data/network/interfaces/macs/06:a9:33:51:95:b8/owner-id (200, 12b) after 1 attempts
2019-03-29 11:25:04,634 - url_helper.py[DEBUG]: [0/6] open 'http://169.254.169.254/2016-09-02/meta-data/network/interfaces/macs/06:a9:33:51:95:b8/vpc-id' with {'headers': {'User-Agent': 'Cloud-Init/18.3-9-g2e62cb8a-0ubuntu1~16.04.2'}, 'method': 'GET', 'timeout': 5.0, 'url': 'http://169.254.169.254/2016-09-02/meta-data/network/interfaces/macs/06:a9:33:51:95:b8/vpc-id', 'allow_redirects': True} configuration
2019-03-29 11:25:04,636 - url_helper.py[DEBUG]: Read from http://169.254.169.254/2016-09-02/meta-data/network/interfaces/macs/06:a9:33:51:95:b8/vpc-id (200, 21b) after 1 attempts
2019-03-29 11:25:04,636 - url_helper.py[DEBUG]: [0/6] open 'http://169.254.169.254/2016-09-02/meta-data/network/interfaces/macs/06:a9:33:51:95:b8/mac' with {'headers': {'User-Agent': 'Cloud-Init/18.3-9-g2e62cb8a-0ubuntu1~16.04.2'}, 'method': 'GET', 'timeout': 5.0, 'url': 'http://169.254.169.254/2016-09-02/meta-data/network/interfaces/macs/06:a9:33:51:95:b8/mac', 'allow_redirects': True} configuration
2019-03-29 11:25:04,637 - url_helper.py[DEBUG]: Read from http://169.254.169.254/2016-09-02/meta-data/network/interfaces/macs/06:a9:33:51:95:b8/mac (200, 17b) after 1 attempts
2019-03-29 11:25:04,638 - url_helper.py[DEBUG]: [0/6] open 'http://169.254.169.254/2016-09-02/meta-data/network/interfaces/macs/06:a9:33:51:95:b8/local-hostname' with {'headers': {'User-Agent': 'Cloud-Init/18.3-9-g2e62cb8a-0ubuntu1~16.04.2'}, 'method': 'GET', 'timeout': 5.0, 'url': 'http://169.254.169.254/2016-09-02/meta-data/network/interfaces/macs/06:a9:33:51:95:b8/local-hostname', 'allow_redirects': True} configuration
2019-03-29 11:25:04,639 - url_helper.py[DEBUG]: Read from http://169.254.169.254/2016-09-02/meta-data/network/interfaces/macs/06:a9:33:51:95:b8/local-hostname (200, 40b) after 1 attempts
2019-03-29 11:25:04,639 - url_helper.py[DEBUG]: [0/6] open 'http://169.254.169.254/2016-09-02/meta-data/network/interfaces/macs/06:a9:33:51:95:b8/security-groups' with {'headers': {'User-Agent': 'Cloud-Init/18.3-9-g2e62cb8a-0ubuntu1~16.04.2'}, 'method': 'GET', 'timeout': 5.0, 'url': 'http://169.254.169.254/2016-09-02/meta-data/network/interfaces/macs/06:a9:33:51:95:b8/security-groups', 'allow_redirects': True} configuration
2019-03-29 11:25:04,641 - url_helper.py[DEBUG]: Read from http://169.254.169.254/2016-09-02/meta-data/network/interfaces/macs/06:a9:33:51:95:b8/security-groups (200, 328b) after 1 attempts
2019-03-29 11:25:04,641 - url_helper.py[DEBUG]: [0/6] open 'http://169.254.169.254/2016-09-02/meta-data/network/interfaces/macs/06:a9:33:51:95:b8/subnet-id' with {'headers': {'User-Agent': 'Cloud-Init/18.3-9-g2e62cb8a-0ubuntu1~16.04.2'}, 'method': 'GET', 'timeout': 5.0, 'url': 'http://169.254.169.254/2016-09-02/meta-data/network/interfaces/macs/06:a9:33:51:95:b8/subnet-id', 'allow_redirects': True} configuration
2019-03-29 11:25:04,643 - url_helper.py[DEBUG]: Read from http://169.254.169.254/2016-09-02/meta-data/network/interfaces/macs/06:a9:33:51:95:b8/subnet-id (200, 24b) after 1 attempts
2019-03-29 11:25:04,643 - url_helper.py[DEBUG]: [0/6] open 'http://169.254.169.254/2016-09-02/meta-data/network/interfaces/macs/06:a9:33:51:95:b8/subnet-ipv4-cidr-block' with {'headers': {'User-Agent': 'Cloud-Init/18.3-9-g2e62cb8a-0ubuntu1~16.04.2'}, 'method': 'GET', 'timeout': 5.0, 'url': 'http://169.254.169.254/2016-09-02/meta-data/network/interfaces/macs/06:a9:33:51:95:b8/subnet-ipv4-cidr-block', 'allow_redirects': True} configuration
2019-03-29 11:25:04,645 - url_helper.py[DEBUG]: Read from http://169.254.169.254/2016-09-02/meta-data/network/interfaces/macs/06:a9:33:51:95:b8/subnet-ipv4-cidr-block (200, 11b) after 1 attempts
2019-03-29 11:25:04,645 - url_helper.py[DEBUG]: [0/6] open 'http://169.254.169.254/2016-09-02/meta-data/network/interfaces/macs/06:a9:33:51:95:b8/local-ipv4s' with {'headers': {'User-Agent': 'Cloud-Init/18.3-9-g2e62cb8a-0ubuntu1~16.04.2'}, 'method': 'GET', 'timeout': 5.0, 'url': 'http://169.254.169.254/2016-09-02/meta-data/network/interfaces/macs/06:a9:33:51:95:b8/local-ipv4s', 'allow_redirects': True} configuration
2019-03-29 11:25:04,646 - url_helper.py[DEBUG]: Read from http://169.254.169.254/2016-09-02/meta-data/network/interfaces/macs/06:a9:33:51:95:b8/local-ipv4s (200, 10b) after 1 attempts
2019-03-29 11:25:04,646 - url_helper.py[DEBUG]: [0/6] open 'http://169.254.169.254/2016-09-02/meta-data/network/interfaces/macs/06:a9:33:51:95:b8/public-ipv4s' with {'headers': {'User-Agent': 'Cloud-Init/18.3-9-g2e62cb8a-0ubuntu1~16.04.2'}, 'method': 'GET', 'timeout': 5.0, 'url': 'http://169.254.169.254/2016-09-02/meta-data/network/interfaces/macs/06:a9:33:51:95:b8/public-ipv4s', 'allow_redirects': True} configuration
2019-03-29 11:25:04,648 - url_helper.py[DEBUG]: Read from http://169.254.169.254/2016-09-02/meta-data/network/interfaces/macs/06:a9:33:51:95:b8/public-ipv4s (200, 14b) after 1 attempts
2019-03-29 11:25:04,648 - url_helper.py[DEBUG]: [0/6] open 'http://169.254.169.254/2016-09-02/meta-data/network/interfaces/macs/06:a9:33:51:95:b8/interface-id' with {'headers': {'User-Agent': 'Cloud-Init/18.3-9-g2e62cb8a-0ubuntu1~16.04.2'}, 'method': 'GET', 'timeout': 5.0, 'url': 'http://169.254.169.254/2016-09-02/meta-data/network/interfaces/macs/06:a9:33:51:95:b8/interface-id', 'allow_redirects': True} configuration
2019-03-29 11:25:04,649 - url_helper.py[DEBUG]: Read from http://169.254.169.254/2016-09-02/meta-data/network/interfaces/macs/06:a9:33:51:95:b8/interface-id (200, 21b) after 1 attempts
2019-03-29 11:25:04,650 - url_helper.py[DEBUG]: [0/6] open 'http://169.254.169.254/2016-09-02/meta-data/network/interfaces/macs/06:a9:33:51:95:b8/public-hostname' with {'headers': {'User-Agent': 'Cloud-Init/18.3-9-g2e62cb8a-0ubuntu1~16.04.2'}, 'method': 'GET', 'timeout': 5.0, 'url': 'http://169.254.169.254/2016-09-02/meta-data/network/interfaces/macs/06:a9:33:51:95:b8/public-hostname', 'allow_redirects': True} configuration
2019-03-29 11:25:04,651 - url_helper.py[DEBUG]: Read from http://169.254.169.254/2016-09-02/meta-data/network/interfaces/macs/06:a9:33:51:95:b8/public-hostname (200, 50b) after 1 attempts
2019-03-29 11:25:04,651 - url_helper.py[DEBUG]: [0/6] open 'http://169.254.169.254/2016-09-02/meta-data/network/interfaces/macs/06:a9:33:51:95:b8/vpc-ipv4-cidr-blocks' with {'headers': {'User-Agent': 'Cloud-Init/18.3-9-g2e62cb8a-0ubuntu1~16.04.2'}, 'method': 'GET', 'timeout': 5.0, 'url': 'http://169.254.169.254/2016-09-02/meta-data/network/interfaces/macs/06:a9:33:51:95:b8/vpc-ipv4-cidr-blocks', 'allow_redirects': True} configuration
2019-03-29 11:25:04,653 - url_helper.py[DEBUG]: Read from http://169.254.169.254/2016-09-02/meta-data/network/interfaces/macs/06:a9:33:51:95:b8/vpc-ipv4-cidr-blocks (200, 11b) after 1 attempts
2019-03-29 11:25:04,653 - url_helper.py[DEBUG]: [0/6] open 'http://169.254.169.254/2016-09-02/meta-data/network/interfaces/macs/06:a9:33:51:95:b8/security-group-ids' with {'headers': {'User-Agent': 'Cloud-Init/18.3-9-g2e62cb8a-0ubuntu1~16.04.2'}, 'method': 'GET', 'timeout': 5.0, 'url': 'http://169.254.169.254/2016-09-02/meta-data/network/interfaces/macs/06:a9:33:51:95:b8/security-group-ids', 'allow_redirects': True} configuration
2019-03-29 11:25:04,654 - url_helper.py[DEBUG]: Read from http://169.254.169.254/2016-09-02/meta-data/network/interfaces/macs/06:a9:33:51:95:b8/security-group-ids (200, 83b) after 1 attempts
2019-03-29 11:25:04,654 - url_helper.py[DEBUG]: [0/6] open 'http://169.254.169.254/2016-09-02/meta-data/placement/' with {'headers': {'User-Agent': 'Cloud-Init/18.3-9-g2e62cb8a-0ubuntu1~16.04.2'}, 'method': 'GET', 'timeout': 5.0, 'url': 'http://169.254.169.254/2016-09-02/meta-data/placement/', 'allow_redirects': True} configuration
2019-03-29 11:25:04,656 - url_helper.py[DEBUG]: Read from http://169.254.169.254/2016-09-02/meta-data/placement/ (200, 17b) after 1 attempts
2019-03-29 11:25:04,656 - url_helper.py[DEBUG]: [0/6] open 'http://169.254.169.254/2016-09-02/meta-data/placement/availability-zone' with {'headers': {'User-Agent': 'Cloud-Init/18.3-9-g2e62cb8a-0ubuntu1~16.04.2'}, 'method': 'GET', 'timeout': 5.0, 'url': 'http://169.254.169.254/2016-09-02/meta-data/placement/availability-zone', 'allow_redirects': True} configuration
2019-03-29 11:25:04,657 - url_helper.py[DEBUG]: Read from http://169.254.169.254/2016-09-02/meta-data/placement/availability-zone (200, 10b) after 1 attempts
2019-03-29 11:25:04,658 - url_helper.py[DEBUG]: [0/6] open 'http://169.254.169.254/2016-09-02/meta-data/public-keys/' with {'headers': {'User-Agent': 'Cloud-Init/18.3-9-g2e62cb8a-0ubuntu1~16.04.2'}, 'method': 'GET', 'timeout': 5.0, 'url': 'http://169.254.169.254/2016-09-02/meta-data/public-keys/', 'allow_redirects': True} configuration
2019-03-29 11:25:04,659 - url_helper.py[DEBUG]: Read from http://169.254.169.254/2016-09-02/meta-data/public-keys/ (200, 68b) after 1 attempts
2019-03-29 11:25:04,659 - url_helper.py[DEBUG]: [0/6] open 'http://169.254.169.254/2016-09-02/meta-data/public-keys/0/openssh-key' with {'headers': {'User-Agent': 'Cloud-Init/18.3-9-g2e62cb8a-0ubuntu1~16.04.2'}, 'method': 'GET', 'timeout': 5.0, 'url': 'http://169.254.169.254/2016-09-02/meta-data/public-keys/0/openssh-key', 'allow_redirects': True} configuration
2019-03-29 11:25:04,661 - url_helper.py[DEBUG]: Read from http://169.254.169.254/2016-09-02/meta-data/public-keys/0/openssh-key (200, 448b) after 1 attempts
2019-03-29 11:25:04,661 - url_helper.py[DEBUG]: [0/6] open 'http://169.254.169.254/2016-09-02/meta-data/services/' with {'headers': {'User-Agent': 'Cloud-Init/18.3-9-g2e62cb8a-0ubuntu1~16.04.2'}, 'method': 'GET', 'timeout': 5.0, 'url': 'http://169.254.169.254/2016-09-02/meta-data/services/', 'allow_redirects': True} configuration
2019-03-29 11:25:04,662 - url_helper.py[DEBUG]: Read from http://169.254.169.254/2016-09-02/meta-data/services/ (200, 16b) after 1 attempts
2019-03-29 11:25:04,662 - url_helper.py[DEBUG]: [0/6] open 'http://169.254.169.254/2016-09-02/meta-data/services/domain' with {'headers': {'User-Agent': 'Cloud-Init/18.3-9-g2e62cb8a-0ubuntu1~16.04.2'}, 'method': 'GET', 'timeout': 5.0, 'url': 'http://169.254.169.254/2016-09-02/meta-data/services/domain', 'allow_redirects': True} configuration
2019-03-29 11:25:04,664 - url_helper.py[DEBUG]: Read from http://169.254.169.254/2016-09-02/meta-data/services/domain (200, 13b) after 1 attempts
2019-03-29 11:25:04,664 - url_helper.py[DEBUG]: [0/6] open 'http://169.254.169.254/2016-09-02/meta-data/services/partition' with {'headers': {'User-Agent': 'Cloud-Init/18.3-9-g2e62cb8a-0ubuntu1~16.04.2'}, 'method': 'GET', 'timeout': 5.0, 'url': 'http://169.254.169.254/2016-09-02/meta-data/services/partition', 'allow_redirects': True} configuration
2019-03-29 11:25:04,665 - url_helper.py[DEBUG]: Read from http://169.254.169.254/2016-09-02/meta-data/services/partition (200, 3b) after 1 attempts
2019-03-29 11:25:04,666 - url_helper.py[DEBUG]: [0/6] open 'http://169.254.169.254/2016-09-02/meta-data/public-hostname' with {'headers': {'User-Agent': 'Cloud-Init/18.3-9-g2e62cb8a-0ubuntu1~16.04.2'}, 'method': 'GET', 'timeout': 5.0, 'url': 'http://169.254.169.254/2016-09-02/meta-data/public-hostname', 'allow_redirects': True} configuration
2019-03-29 11:25:04,667 - url_helper.py[DEBUG]: Read from http://169.254.169.254/2016-09-02/meta-data/public-hostname (200, 50b) after 1 attempts
2019-03-29 11:25:04,667 - url_helper.py[DEBUG]: [0/6] open 'http://169.254.169.254/2016-09-02/meta-data/mac' with {'headers': {'User-Agent': 'Cloud-Init/18.3-9-g2e62cb8a-0ubuntu1~16.04.2'}, 'method': 'GET', 'timeout': 5.0, 'url': 'http://169.254.169.254/2016-09-02/meta-data/mac', 'allow_redirects': True} configuration
2019-03-29 11:25:04,668 - url_helper.py[DEBUG]: Read from http://169.254.169.254/2016-09-02/meta-data/mac (200, 17b) after 1 attempts
2019-03-29 11:25:04,669 - url_helper.py[DEBUG]: [0/6] open 'http://169.254.169.254/2016-09-02/meta-data/reservation-id' with {'headers': {'User-Agent': 'Cloud-Init/18.3-9-g2e62cb8a-0ubuntu1~16.04.2'}, 'method': 'GET', 'timeout': 5.0, 'url': 'http://169.254.169.254/2016-09-02/meta-data/reservation-id', 'allow_redirects': True} configuration
2019-03-29 11:25:04,670 - url_helper.py[DEBUG]: Read from http://169.254.169.254/2016-09-02/meta-data/reservation-id (200, 19b) after 1 attempts
2019-03-29 11:25:04,670 - url_helper.py[DEBUG]: [0/6] open 'http://169.254.169.254/2016-09-02/meta-data/ami-id' with {'headers': {'User-Agent': 'Cloud-Init/18.3-9-g2e62cb8a-0ubuntu1~16.04.2'}, 'method': 'GET', 'timeout': 5.0, 'url': 'http://169.254.169.254/2016-09-02/meta-data/ami-id', 'allow_redirects': True} configuration
2019-03-29 11:25:04,672 - url_helper.py[DEBUG]: Read from http://169.254.169.254/2016-09-02/meta-data/ami-id (200, 21b) after 1 attempts
2019-03-29 11:25:04,672 - url_helper.py[DEBUG]: [0/6] open 'http://169.254.169.254/2016-09-02/meta-data/security-groups' with {'headers': {'User-Agent': 'Cloud-Init/18.3-9-g2e62cb8a-0ubuntu1~16.04.2'}, 'method': 'GET', 'timeout': 5.0, 'url': 'http://169.254.169.254/2016-09-02/meta-data/security-groups', 'allow_redirects': True} configuration
2019-03-29 11:25:04,673 - url_helper.py[DEBUG]: Read from http://169.254.169.254/2016-09-02/meta-data/security-groups (200, 328b) after 1 attempts
2019-03-29 11:25:04,673 - url_helper.py[DEBUG]: [0/6] open 'http://169.254.169.254/2016-09-02/meta-data/local-ipv4' with {'headers': {'User-Agent': 'Cloud-Init/18.3-9-g2e62cb8a-0ubuntu1~16.04.2'}, 'method': 'GET', 'timeout': 5.0, 'url': 'http://169.254.169.254/2016-09-02/meta-data/local-ipv4', 'allow_redirects': True} configuration
2019-03-29 11:25:04,675 - url_helper.py[DEBUG]: Read from http://169.254.169.254/2016-09-02/meta-data/local-ipv4 (200, 10b) after 1 attempts
2019-03-29 11:25:04,675 - url_helper.py[DEBUG]: [0/6] open 'http://169.254.169.254/2016-09-02/meta-data/instance-type' with {'headers': {'User-Agent': 'Cloud-Init/18.3-9-g2e62cb8a-0ubuntu1~16.04.2'}, 'method': 'GET', 'timeout': 5.0, 'url': 'http://169.254.169.254/2016-09-02/meta-data/instance-type', 'allow_redirects': True} configuration
2019-03-29 11:25:04,676 - url_helper.py[DEBUG]: Read from http://169.254.169.254/2016-09-02/meta-data/instance-type (200, 10b) after 1 attempts
2019-03-29 11:25:04,676 - url_helper.py[DEBUG]: [0/6] open 'http://169.254.169.254/2016-09-02/meta-data/public-ipv4' with {'headers': {'User-Agent': 'Cloud-Init/18.3-9-g2e62cb8a-0ubuntu1~16.04.2'}, 'method': 'GET', 'timeout': 5.0, 'url': 'http://169.254.169.254/2016-09-02/meta-data/public-ipv4', 'allow_redirects': True} configuration
2019-03-29 11:25:04,678 - url_helper.py[DEBUG]: Read from http://169.254.169.254/2016-09-02/meta-data/public-ipv4 (200, 14b) after 1 attempts
2019-03-29 11:25:04,678 - url_helper.py[DEBUG]: [0/6] open 'http://169.254.169.254/2016-09-02/meta-data/profile' with {'headers': {'User-Agent': 'Cloud-Init/18.3-9-g2e62cb8a-0ubuntu1~16.04.2'}, 'method': 'GET', 'timeout': 5.0, 'url': 'http://169.254.169.254/2016-09-02/meta-data/profile', 'allow_redirects': True} configuration
2019-03-29 11:25:04,680 - url_helper.py[DEBUG]: Read from http://169.254.169.254/2016-09-02/meta-data/profile (200, 11b) after 1 attempts
2019-03-29 11:25:04,680 - url_helper.py[DEBUG]: [0/6] open 'http://169.254.169.254/2016-09-02/meta-data/ami-manifest-path' with {'headers': {'User-Agent': 'Cloud-Init/18.3-9-g2e62cb8a-0ubuntu1~16.04.2'}, 'method': 'GET', 'timeout': 5.0, 'url': 'http://169.254.169.254/2016-09-02/meta-data/ami-manifest-path', 'allow_redirects': True} configuration
2019-03-29 11:25:04,681 - url_helper.py[DEBUG]: Read from http://169.254.169.254/2016-09-02/meta-data/ami-manifest-path (200, 9b) after 1 attempts
2019-03-29 11:25:04,681 - url_helper.py[DEBUG]: [0/6] open 'http://169.254.169.254/2016-09-02/meta-data/instance-action' with {'headers': {'User-Agent': 'Cloud-Init/18.3-9-g2e62cb8a-0ubuntu1~16.04.2'}, 'method': 'GET', 'timeout': 5.0, 'url': 'http://169.254.169.254/2016-09-02/meta-data/instance-action', 'allow_redirects': True} configuration
2019-03-29 11:25:04,683 - url_helper.py[DEBUG]: Read from http://169.254.169.254/2016-09-02/meta-data/instance-action (200, 4b) after 1 attempts
2019-03-29 11:25:04,683 - url_helper.py[DEBUG]: [0/6] open 'http://169.254.169.254/2016-09-02/meta-data/hostname' with {'headers': {'User-Agent': 'Cloud-Init/18.3-9-g2e62cb8a-0ubuntu1~16.04.2'}, 'method': 'GET', 'timeout': 5.0, 'url': 'http://169.254.169.254/2016-09-02/meta-data/hostname', 'allow_redirects': True} configuration
2019-03-29 11:25:04,684 - url_helper.py[DEBUG]: Read from http://169.254.169.254/2016-09-02/meta-data/hostname (200, 40b) after 1 attempts
2019-03-29 11:25:04,685 - url_helper.py[DEBUG]: [0/6] open 'http://169.254.169.254/2016-09-02/meta-data/local-hostname' with {'headers': {'User-Agent': 'Cloud-Init/18.3-9-g2e62cb8a-0ubuntu1~16.04.2'}, 'method': 'GET', 'timeout': 5.0, 'url': 'http://169.254.169.254/2016-09-02/meta-data/local-hostname', 'allow_redirects': True} configuration
2019-03-29 11:25:04,686 - url_helper.py[DEBUG]: Read from http://169.254.169.254/2016-09-02/meta-data/local-hostname (200, 40b) after 1 attempts
2019-03-29 11:25:04,686 - url_helper.py[DEBUG]: [0/6] open 'http://169.254.169.254/2016-09-02/meta-data/ami-launch-index' with {'headers': {'User-Agent': 'Cloud-Init/18.3-9-g2e62cb8a-0ubuntu1~16.04.2'}, 'method': 'GET', 'timeout': 5.0, 'url': 'http://169.254.169.254/2016-09-02/meta-data/ami-launch-index', 'allow_redirects': True} configuration
2019-03-29 11:25:04,687 - url_helper.py[DEBUG]: Read from http://169.254.169.254/2016-09-02/meta-data/ami-launch-index (200, 1b) after 1 attempts
2019-03-29 11:25:04,688 - url_helper.py[DEBUG]: [0/6] open 'http://169.254.169.254/2016-09-02/meta-data/instance-id' with {'headers': {'User-Agent': 'Cloud-Init/18.3-9-g2e62cb8a-0ubuntu1~16.04.2'}, 'method': 'GET', 'timeout': 5.0, 'url': 'http://169.254.169.254/2016-09-02/meta-data/instance-id', 'allow_redirects': True} configuration
2019-03-29 11:25:04,689 - url_helper.py[DEBUG]: Read from http://169.254.169.254/2016-09-02/meta-data/instance-id (200, 19b) after 1 attempts
2019-03-29 11:25:04,689 - url_helper.py[DEBUG]: [0/6] open 'http://169.254.169.254/2016-09-02/dynamic/instance-identity' with {'headers': {'User-Agent': 'Cloud-Init/18.3-9-g2e62cb8a-0ubuntu1~16.04.2'}, 'method': 'GET', 'timeout': 5.0, 'url': 'http://169.254.169.254/2016-09-02/dynamic/instance-identity', 'allow_redirects': True} configuration
2019-03-29 11:25:04,692 - url_helper.py[DEBUG]: Read from http://169.254.169.254/2016-09-02/dynamic/instance-identity (200, 33b) after 1 attempts
2019-03-29 11:25:04,692 - url_helper.py[DEBUG]: [0/6] open 'http://169.254.169.254/2016-09-02/dynamic/instance-identity/rsa2048' with {'headers': {'User-Agent': 'Cloud-Init/18.3-9-g2e62cb8a-0ubuntu1~16.04.2'}, 'method': 'GET', 'timeout': 5.0, 'url': 'http://169.254.169.254/2016-09-02/dynamic/instance-identity/rsa2048', 'allow_redirects': True} configuration
2019-03-29 11:25:04,693 - url_helper.py[DEBUG]: Read from http://169.254.169.254/2016-09-02/dynamic/instance-identity/rsa2048 (200, 1434b) after 1 attempts
2019-03-29 11:25:04,693 - url_helper.py[DEBUG]: [0/6] open 'http://169.254.169.254/2016-09-02/dynamic/instance-identity/document' with {'headers': {'User-Agent': 'Cloud-Init/18.3-9-g2e62cb8a-0ubuntu1~16.04.2'}, 'method': 'GET', 'timeout': 5.0, 'url': 'http://169.254.169.254/2016-09-02/dynamic/instance-identity/document', 'allow_redirects': True} configuration
2019-03-29 11:25:04,695 - url_helper.py[DEBUG]: Read from http://169.254.169.254/2016-09-02/dynamic/instance-identity/document (200, 476b) after 1 attempts
2019-03-29 11:25:04,695 - url_helper.py[DEBUG]: [0/6] open 'http://169.254.169.254/2016-09-02/dynamic/instance-identity/pkcs7' with {'headers': {'User-Agent': 'Cloud-Init/18.3-9-g2e62cb8a-0ubuntu1~16.04.2'}, 'method': 'GET', 'timeout': 5.0, 'url': 'http://169.254.169.254/2016-09-02/dynamic/instance-identity/pkcs7', 'allow_redirects': True} configuration
2019-03-29 11:25:04,697 - url_helper.py[DEBUG]: Read from http://169.254.169.254/2016-09-02/dynamic/instance-identity/pkcs7 (200, 1118b) after 1 attempts
2019-03-29 11:25:04,697 - url_helper.py[DEBUG]: [0/6] open 'http://169.254.169.254/2016-09-02/dynamic/instance-identity/signature' with {'headers': {'User-Agent': 'Cloud-Init/18.3-9-g2e62cb8a-0ubuntu1~16.04.2'}, 'method': 'GET', 'timeout': 5.0, 'url': 'http://169.254.169.254/2016-09-02/dynamic/instance-identity/signature', 'allow_redirects': True} configuration
2019-03-29 11:25:04,698 - url_helper.py[DEBUG]: Read from http://169.254.169.254/2016-09-02/dynamic/instance-identity/signature (200, 174b) after 1 attempts
2019-03-29 11:25:04,698 - util.py[DEBUG]: Crawl of metadata service took 0.106 seconds
2019-03-29 11:25:04,698 - util.py[DEBUG]: Running command ['ip', '-4', 'route', 'del', 'default', 'dev', 'ens3'] with allowed return codes [0] (shell=False, capture=True)
2019-03-29 11:25:04,700 - util.py[DEBUG]: Running command ['ip', '-family', 'inet', 'link', 'set', 'dev', 'ens3', 'down'] with allowed return codes [0] (shell=False, capture=True)
2019-03-29 11:25:04,736 - util.py[DEBUG]: Running command ['ip', '-family', 'inet', 'addr', 'del', '10.0.0.206/24', 'dev', 'ens3'] with allowed return codes [0] (shell=False, capture=True)
2019-03-29 11:25:04,739 - handlers.py[DEBUG]: finish: init-local/search-Ec2Local: SUCCESS: found local data from DataSourceEc2Local
2019-03-29 11:25:04,739 - stages.py[INFO]: Loaded datasource DataSourceEc2Local - DataSourceEc2Local
2019-03-29 11:25:04,739 - util.py[DEBUG]: Reading from /etc/cloud/cloud.cfg (quiet=False)
2019-03-29 11:25:04,740 - util.py[DEBUG]: Read 3169 bytes from /etc/cloud/cloud.cfg
2019-03-29 11:25:04,740 - util.py[DEBUG]: Attempting to load yaml from string of length 3169 with allowed root types (<class 'dict'>,)
2019-03-29 11:25:04,750 - util.py[DEBUG]: Reading from /etc/cloud/cloud.cfg.d/90_dpkg.cfg (quiet=False)
2019-03-29 11:25:04,750 - util.py[DEBUG]: Read 238 bytes from /etc/cloud/cloud.cfg.d/90_dpkg.cfg
2019-03-29 11:25:04,750 - util.py[DEBUG]: Attempting to load yaml from string of length 238 with allowed root types (<class 'dict'>,)
2019-03-29 11:25:04,751 - util.py[DEBUG]: Reading from /etc/cloud/cloud.cfg.d/05_logging.cfg (quiet=False)
2019-03-29 11:25:04,751 - util.py[DEBUG]: Read 2057 bytes from /etc/cloud/cloud.cfg.d/05_logging.cfg
2019-03-29 11:25:04,751 - util.py[DEBUG]: Attempting to load yaml from string of length 2057 with allowed root types (<class 'dict'>,)
2019-03-29 11:25:04,755 - util.py[DEBUG]: Reading from /run/cloud-init/cloud.cfg (quiet=False)
2019-03-29 11:25:04,755 - util.py[DEBUG]: Read 44 bytes from /run/cloud-init/cloud.cfg
2019-03-29 11:25:04,755 - util.py[DEBUG]: Attempting to load yaml from string of length 44 with allowed root types (<class 'dict'>,)
2019-03-29 11:25:04,755 - util.py[DEBUG]: Attempting to load yaml from string of length 0 with allowed root types (<class 'dict'>,)
2019-03-29 11:25:04,755 - util.py[DEBUG]: loaded blob returned None, returning default.
2019-03-29 11:25:04,756 - util.py[DEBUG]: Attempting to remove /var/lib/cloud/instance
2019-03-29 11:25:04,756 - util.py[DEBUG]: Creating symbolic link from '/var/lib/cloud/instance' => '/var/lib/cloud/instances/i-07596f108f8d78958'
2019-03-29 11:25:04,757 - util.py[DEBUG]: Reading from /var/lib/cloud/instances/i-07596f108f8d78958/datasource (quiet=False)
2019-03-29 11:25:04,757 - util.py[DEBUG]: Writing to /var/lib/cloud/instances/i-07596f108f8d78958/datasource - wb: [644] 39 bytes
2019-03-29 11:25:04,757 - util.py[DEBUG]: Writing to /var/lib/cloud/data/previous-datasource - wb: [644] 39 bytes
2019-03-29 11:25:04,758 - util.py[DEBUG]: Reading from /var/lib/cloud/data/instance-id (quiet=False)
2019-03-29 11:25:04,758 - stages.py[DEBUG]: previous iid found to be NO_PREVIOUS_INSTANCE_ID
2019-03-29 11:25:04,758 - util.py[DEBUG]: Writing to /var/lib/cloud/data/instance-id - wb: [644] 20 bytes
2019-03-29 11:25:04,758 - util.py[DEBUG]: Writing to /run/cloud-init/.instance-id - wb: [644] 20 bytes
2019-03-29 11:25:04,758 - util.py[DEBUG]: Writing to /var/lib/cloud/data/previous-instance-id - wb: [644] 24 bytes
2019-03-29 11:25:04,759 - util.py[DEBUG]: Writing to /var/lib/cloud/instance/obj.pkl - wb: [400] 9797 bytes
2019-03-29 11:25:04,759 - main.py[DEBUG]: [local] init will now be targeting instance id: i-07596f108f8d78958. new=True
2019-03-29 11:25:04,759 - util.py[DEBUG]: Reading from /etc/cloud/cloud.cfg (quiet=False)
2019-03-29 11:25:04,760 - util.py[DEBUG]: Read 3169 bytes from /etc/cloud/cloud.cfg
2019-03-29 11:25:04,760 - util.py[DEBUG]: Attempting to load yaml from string of length 3169 with allowed root types (<class 'dict'>,)
2019-03-29 11:25:04,770 - util.py[DEBUG]: Reading from /etc/cloud/cloud.cfg.d/90_dpkg.cfg (quiet=False)
2019-03-29 11:25:04,770 - util.py[DEBUG]: Read 238 bytes from /etc/cloud/cloud.cfg.d/90_dpkg.cfg
2019-03-29 11:25:04,770 - util.py[DEBUG]: Attempting to load yaml from string of length 238 with allowed root types (<class 'dict'>,)
2019-03-29 11:25:04,771 - util.py[DEBUG]: Reading from /etc/cloud/cloud.cfg.d/05_logging.cfg (quiet=False)
2019-03-29 11:25:04,771 - util.py[DEBUG]: Read 2057 bytes from /etc/cloud/cloud.cfg.d/05_logging.cfg
2019-03-29 11:25:04,771 - util.py[DEBUG]: Attempting to load yaml from string of length 2057 with allowed root types (<class 'dict'>,)
2019-03-29 11:25:04,774 - util.py[DEBUG]: Reading from /run/cloud-init/cloud.cfg (quiet=False)
2019-03-29 11:25:04,774 - util.py[DEBUG]: Read 44 bytes from /run/cloud-init/cloud.cfg
2019-03-29 11:25:04,774 - util.py[DEBUG]: Attempting to load yaml from string of length 44 with allowed root types (<class 'dict'>,)
2019-03-29 11:25:04,775 - util.py[DEBUG]: Attempting to load yaml from string of length 0 with allowed root types (<class 'dict'>,)
2019-03-29 11:25:04,775 - util.py[DEBUG]: loaded blob returned None, returning default.
2019-03-29 11:25:04,776 - stages.py[DEBUG]: Using distro class <class 'cloudinit.distros.ubuntu.Distro'>
2019-03-29 11:25:04,776 - cc_set_hostname.py[DEBUG]: Setting the hostname to ip-10-0-0-206.eu-west-1.compute.internal (ip-10-0-0-206)
2019-03-29 11:25:04,777 - util.py[DEBUG]: Reading from /etc/hostname (quiet=False)
2019-03-29 11:25:04,777 - util.py[DEBUG]: Read 7 bytes from /etc/hostname
2019-03-29 11:25:04,777 - util.py[DEBUG]: Writing to /etc/hostname - wb: [644] 14 bytes
2019-03-29 11:25:04,777 - __init__.py[DEBUG]: Non-persistently setting the system hostname to ip-10-0-0-206
2019-03-29 11:25:04,777 - util.py[DEBUG]: Running command ['hostname', 'ip-10-0-0-206'] with allowed return codes [0] (shell=False, capture=True)
2019-03-29 11:25:04,780 - util.py[DEBUG]: Reading from /sys/class/net/ens3/address (quiet=False)
2019-03-29 11:25:04,780 - util.py[DEBUG]: Read 18 bytes from /sys/class/net/ens3/address
2019-03-29 11:25:04,780 - stages.py[DEBUG]: applying net config names for {'version': 1, 'config': [{'type': 'physical', 'subnets': [{'type': 'dhcp4'}], 'name': 'ens3', 'mac_address': '06:a9:33:51:95:b8'}]}
2019-03-29 11:25:04,781 - util.py[DEBUG]: Reading from /sys/class/net/ens3/device/device (quiet=False)
2019-03-29 11:25:04,781 - util.py[DEBUG]: Read 7 bytes from /sys/class/net/ens3/device/device
2019-03-29 11:25:04,781 - util.py[DEBUG]: Reading from /sys/class/net/lo/addr_assign_type (quiet=False)
2019-03-29 11:25:04,781 - util.py[DEBUG]: Read 2 bytes from /sys/class/net/lo/addr_assign_type
2019-03-29 11:25:04,781 - util.py[DEBUG]: Reading from /sys/class/net/lo/uevent (quiet=False)
2019-03-29 11:25:04,781 - util.py[DEBUG]: Read 23 bytes from /sys/class/net/lo/uevent
2019-03-29 11:25:04,781 - util.py[DEBUG]: Reading from /sys/class/net/lo/address (quiet=False)
2019-03-29 11:25:04,781 - util.py[DEBUG]: Read 18 bytes from /sys/class/net/lo/address
2019-03-29 11:25:04,781 - util.py[DEBUG]: Reading from /sys/class/net/lo/device/device (quiet=False)
2019-03-29 11:25:04,781 - util.py[DEBUG]: Reading from /sys/class/net/ens3/addr_assign_type (quiet=False)
2019-03-29 11:25:04,781 - util.py[DEBUG]: Read 2 bytes from /sys/class/net/ens3/addr_assign_type
2019-03-29 11:25:04,781 - util.py[DEBUG]: Reading from /sys/class/net/ens3/uevent (quiet=False)
2019-03-29 11:25:04,781 - util.py[DEBUG]: Read 25 bytes from /sys/class/net/ens3/uevent
2019-03-29 11:25:04,782 - util.py[DEBUG]: Reading from /sys/class/net/ens3/address (quiet=False)
2019-03-29 11:25:04,782 - util.py[DEBUG]: Read 18 bytes from /sys/class/net/ens3/address
2019-03-29 11:25:04,782 - util.py[DEBUG]: Reading from /sys/class/net/ens3/device/device (quiet=False)
2019-03-29 11:25:04,782 - util.py[DEBUG]: Read 7 bytes from /sys/class/net/ens3/device/device
2019-03-29 11:25:04,782 - util.py[DEBUG]: Reading from /sys/class/net/lo/operstate (quiet=False)
2019-03-29 11:25:04,782 - util.py[DEBUG]: Read 8 bytes from /sys/class/net/lo/operstate
2019-03-29 11:25:04,782 - util.py[DEBUG]: Reading from /sys/class/net/ens3/operstate (quiet=False)
2019-03-29 11:25:04,782 - util.py[DEBUG]: Read 5 bytes from /sys/class/net/ens3/operstate
2019-03-29 11:25:04,782 - util.py[DEBUG]: Running command ['ip', '-6', 'addr', 'show', 'permanent', 'scope', 'global'] with allowed return codes [0] (shell=False, capture=True)
2019-03-29 11:25:04,784 - util.py[DEBUG]: Running command ['ip', '-4', 'addr', 'show'] with allowed return codes [0] (shell=False, capture=True)
2019-03-29 11:25:04,786 - __init__.py[DEBUG]: no work necessary for renaming of [['06:a9:33:51:95:b8', 'ens3', 'ixgbevf', '0x10ed']]
2019-03-29 11:25:04,787 - stages.py[INFO]: Applying network configuration from ds bringup=False: {'version': 1, 'config': [{'type': 'physical', 'subnets': [{'type': 'dhcp4'}], 'name': 'ens3', 'mac_address': '06:a9:33:51:95:b8'}]}
2019-03-29 11:25:04,787 - __init__.py[DEBUG]: Selected renderer 'eni' from priority list: None
2019-03-29 11:25:04,789 - util.py[DEBUG]: Writing to /etc/network/interfaces.d/50-cloud-init.cfg - wb: [644] 367 bytes
2019-03-29 11:25:04,789 - util.py[DEBUG]: Writing to /etc/udev/rules.d/70-persistent-net.rules - wb: [644] 96 bytes
2019-03-29 11:25:04,790 - main.py[DEBUG]: [local] Exiting. datasource DataSourceEc2Local not in local mode.
2019-03-29 11:25:04,791 - util.py[DEBUG]: Reading from /proc/uptime (quiet=False)
2019-03-29 11:25:04,791 - util.py[DEBUG]: Read 12 bytes from /proc/uptime
2019-03-29 11:25:04,791 - util.py[DEBUG]: cloud-init mode 'init' took 0.633 seconds (0.64)
2019-03-29 11:25:04,791 - handlers.py[DEBUG]: finish: init-local: SUCCESS: searching for local datasources
2019-03-29 11:25:05,314 - util.py[DEBUG]: Cloud-init v. 18.3-9-g2e62cb8a-0ubuntu1~16.04.2 running 'init' at Fri, 29 Mar 2019 11:25:05 +0000. Up 8.88 seconds.
2019-03-29 11:25:05,315 - main.py[DEBUG]: No kernel command line url found.
2019-03-29 11:25:05,315 - main.py[DEBUG]: Closing stdin.
2019-03-29 11:25:05,316 - util.py[DEBUG]: Writing to /var/log/cloud-init.log - ab: [644] 0 bytes
2019-03-29 11:25:05,317 - util.py[DEBUG]: Changing the ownership of /var/log/cloud-init.log to 104:4
2019-03-29 11:25:05,317 - util.py[DEBUG]: Running command ['ip', 'addr', 'show'] with allowed return codes [0] (shell=False, capture=True)
2019-03-29 11:25:05,320 - util.py[DEBUG]: Running command ['ip', '-o', 'route', 'list'] with allowed return codes [0] (shell=False, capture=True)
2019-03-29 11:25:05,322 - util.py[DEBUG]: Running command ['ip', '--oneline', '-6', 'route', 'list', 'table', 'all'] with allowed return codes [0, 1] (shell=False, capture=True)
2019-03-29 11:25:05,324 - main.py[DEBUG]: Checking to see if files that we need already exist from a previous run that would allow us to stop early.
2019-03-29 11:25:05,324 - main.py[DEBUG]: Execution continuing, no previous run detected that would allow us to stop early.
2019-03-29 11:25:05,325 - handlers.py[DEBUG]: start: init-network/check-cache: attempting to read from cache [trust]
2019-03-29 11:25:05,325 - util.py[DEBUG]: Reading from /var/lib/cloud/instance/obj.pkl (quiet=False)
2019-03-29 11:25:05,325 - util.py[DEBUG]: Read 9797 bytes from /var/lib/cloud/instance/obj.pkl
2019-03-29 11:25:05,327 - util.py[DEBUG]: Reading from /run/cloud-init/.instance-id (quiet=False)
2019-03-29 11:25:05,327 - util.py[DEBUG]: Read 20 bytes from /run/cloud-init/.instance-id
2019-03-29 11:25:05,327 - stages.py[DEBUG]: restored from cache with run check: DataSourceEc2Local
2019-03-29 11:25:05,327 - handlers.py[DEBUG]: finish: init-network/check-cache: SUCCESS: restored from cache with run check: DataSourceEc2Local
2019-03-29 11:25:05,327 - util.py[DEBUG]: Reading from /etc/cloud/cloud.cfg (quiet=False)
2019-03-29 11:25:05,327 - util.py[DEBUG]: Read 3169 bytes from /etc/cloud/cloud.cfg
2019-03-29 11:25:05,327 - util.py[DEBUG]: Attempting to load yaml from string of length 3169 with allowed root types (<class 'dict'>,)
2019-03-29 11:25:05,338 - util.py[DEBUG]: Reading from /etc/cloud/cloud.cfg.d/90_dpkg.cfg (quiet=False)
2019-03-29 11:25:05,338 - util.py[DEBUG]: Read 238 bytes from /etc/cloud/cloud.cfg.d/90_dpkg.cfg
2019-03-29 11:25:05,338 - util.py[DEBUG]: Attempting to load yaml from string of length 238 with allowed root types (<class 'dict'>,)
2019-03-29 11:25:05,340 - util.py[DEBUG]: Reading from /etc/cloud/cloud.cfg.d/05_logging.cfg (quiet=False)
2019-03-29 11:25:05,340 - util.py[DEBUG]: Read 2057 bytes from /etc/cloud/cloud.cfg.d/05_logging.cfg
2019-03-29 11:25:05,340 - util.py[DEBUG]: Attempting to load yaml from string of length 2057 with allowed root types (<class 'dict'>,)
2019-03-29 11:25:05,343 - util.py[DEBUG]: Reading from /run/cloud-init/cloud.cfg (quiet=False)
2019-03-29 11:25:05,343 - util.py[DEBUG]: Read 44 bytes from /run/cloud-init/cloud.cfg
2019-03-29 11:25:05,343 - util.py[DEBUG]: Attempting to load yaml from string of length 44 with allowed root types (<class 'dict'>,)
2019-03-29 11:25:05,344 - util.py[DEBUG]: Attempting to load yaml from string of length 0 with allowed root types (<class 'dict'>,)
2019-03-29 11:25:05,344 - util.py[DEBUG]: loaded blob returned None, returning default.
2019-03-29 11:25:05,344 - util.py[DEBUG]: Attempting to remove /var/lib/cloud/instance
2019-03-29 11:25:05,344 - util.py[DEBUG]: Creating symbolic link from '/var/lib/cloud/instance' => '/var/lib/cloud/instances/i-07596f108f8d78958'
2019-03-29 11:25:05,345 - util.py[DEBUG]: Reading from /var/lib/cloud/instances/i-07596f108f8d78958/datasource (quiet=False)
2019-03-29 11:25:05,345 - util.py[DEBUG]: Read 39 bytes from /var/lib/cloud/instances/i-07596f108f8d78958/datasource
2019-03-29 11:25:05,345 - util.py[DEBUG]: Writing to /var/lib/cloud/instances/i-07596f108f8d78958/datasource - wb: [644] 39 bytes
2019-03-29 11:25:05,345 - util.py[DEBUG]: Writing to /var/lib/cloud/data/previous-datasource - wb: [644] 39 bytes
2019-03-29 11:25:05,346 - util.py[DEBUG]: Reading from /var/lib/cloud/data/instance-id (quiet=False)
2019-03-29 11:25:05,346 - util.py[DEBUG]: Read 20 bytes from /var/lib/cloud/data/instance-id
2019-03-29 11:25:05,346 - stages.py[DEBUG]: previous iid found to be i-07596f108f8d78958
2019-03-29 11:25:05,346 - util.py[DEBUG]: Writing to /var/lib/cloud/data/instance-id - wb: [644] 20 bytes
2019-03-29 11:25:05,346 - util.py[DEBUG]: Writing to /run/cloud-init/.instance-id - wb: [644] 20 bytes
2019-03-29 11:25:05,347 - util.py[DEBUG]: Writing to /var/lib/cloud/data/previous-instance-id - wb: [644] 20 bytes
2019-03-29 11:25:05,347 - util.py[DEBUG]: Writing to /var/lib/cloud/instance/obj.pkl - wb: [400] 9876 bytes
2019-03-29 11:25:05,348 - main.py[DEBUG]: [net] init will now be targeting instance id: i-07596f108f8d78958. new=False
2019-03-29 11:25:05,348 - util.py[DEBUG]: Reading from /etc/cloud/cloud.cfg (quiet=False)
2019-03-29 11:25:05,348 - util.py[DEBUG]: Read 3169 bytes from /etc/cloud/cloud.cfg
2019-03-29 11:25:05,348 - util.py[DEBUG]: Attempting to load yaml from string of length 3169 with allowed root types (<class 'dict'>,)
2019-03-29 11:25:05,358 - util.py[DEBUG]: Reading from /etc/cloud/cloud.cfg.d/90_dpkg.cfg (quiet=False)
2019-03-29 11:25:05,358 - util.py[DEBUG]: Read 238 bytes from /etc/cloud/cloud.cfg.d/90_dpkg.cfg
2019-03-29 11:25:05,358 - util.py[DEBUG]: Attempting to load yaml from string of length 238 with allowed root types (<class 'dict'>,)
2019-03-29 11:25:05,359 - util.py[DEBUG]: Reading from /etc/cloud/cloud.cfg.d/05_logging.cfg (quiet=False)
2019-03-29 11:25:05,359 - util.py[DEBUG]: Read 2057 bytes from /etc/cloud/cloud.cfg.d/05_logging.cfg
2019-03-29 11:25:05,359 - util.py[DEBUG]: Attempting to load yaml from string of length 2057 with allowed root types (<class 'dict'>,)
2019-03-29 11:25:05,362 - util.py[DEBUG]: Reading from /run/cloud-init/cloud.cfg (quiet=False)
2019-03-29 11:25:05,363 - util.py[DEBUG]: Read 44 bytes from /run/cloud-init/cloud.cfg
2019-03-29 11:25:05,363 - util.py[DEBUG]: Attempting to load yaml from string of length 44 with allowed root types (<class 'dict'>,)
2019-03-29 11:25:05,363 - util.py[DEBUG]: Attempting to load yaml from string of length 0 with allowed root types (<class 'dict'>,)
2019-03-29 11:25:05,363 - util.py[DEBUG]: loaded blob returned None, returning default.
2019-03-29 11:25:05,364 - util.py[DEBUG]: Reading from /sys/class/net/ens3/address (quiet=False)
2019-03-29 11:25:05,364 - util.py[DEBUG]: Read 18 bytes from /sys/class/net/ens3/address
2019-03-29 11:25:05,364 - stages.py[DEBUG]: applying net config names for {'config': [{'subnets': [{'type': 'dhcp4'}], 'mac_address': '06:a9:33:51:95:b8', 'name': 'ens3', 'type': 'physical'}], 'version': 1}
2019-03-29 11:25:05,365 - stages.py[DEBUG]: Using distro class <class 'cloudinit.distros.ubuntu.Distro'>
2019-03-29 11:25:05,365 - util.py[DEBUG]: Reading from /sys/class/net/ens3/device/device (quiet=False)
2019-03-29 11:25:05,365 - util.py[DEBUG]: Read 7 bytes from /sys/class/net/ens3/device/device
2019-03-29 11:25:05,365 - util.py[DEBUG]: Reading from /sys/class/net/lo/addr_assign_type (quiet=False)
2019-03-29 11:25:05,365 - util.py[DEBUG]: Read 2 bytes from /sys/class/net/lo/addr_assign_type
2019-03-29 11:25:05,365 - util.py[DEBUG]: Reading from /sys/class/net/lo/uevent (quiet=False)
2019-03-29 11:25:05,365 - util.py[DEBUG]: Read 23 bytes from /sys/class/net/lo/uevent
2019-03-29 11:25:05,365 - util.py[DEBUG]: Reading from /sys/class/net/lo/address (quiet=False)
2019-03-29 11:25:05,366 - util.py[DEBUG]: Read 18 bytes from /sys/class/net/lo/address
2019-03-29 11:25:05,366 - util.py[DEBUG]: Reading from /sys/class/net/lo/device/device (quiet=False)
2019-03-29 11:25:05,366 - util.py[DEBUG]: Reading from /sys/class/net/ens3/addr_assign_type (quiet=False)
2019-03-29 11:25:05,366 - util.py[DEBUG]: Read 2 bytes from /sys/class/net/ens3/addr_assign_type
2019-03-29 11:25:05,366 - util.py[DEBUG]: Reading from /sys/class/net/ens3/uevent (quiet=False)
2019-03-29 11:25:05,366 - util.py[DEBUG]: Read 25 bytes from /sys/class/net/ens3/uevent
2019-03-29 11:25:05,366 - util.py[DEBUG]: Reading from /sys/class/net/ens3/address (quiet=False)
2019-03-29 11:25:05,366 - util.py[DEBUG]: Read 18 bytes from /sys/class/net/ens3/address
2019-03-29 11:25:05,366 - util.py[DEBUG]: Reading from /sys/class/net/ens3/device/device (quiet=False)
2019-03-29 11:25:05,366 - util.py[DEBUG]: Read 7 bytes from /sys/class/net/ens3/device/device
2019-03-29 11:25:05,366 - util.py[DEBUG]: Reading from /sys/class/net/lo/operstate (quiet=False)
2019-03-29 11:25:05,366 - util.py[DEBUG]: Read 8 bytes from /sys/class/net/lo/operstate
2019-03-29 11:25:05,366 - util.py[DEBUG]: Reading from /sys/class/net/ens3/operstate (quiet=False)
2019-03-29 11:25:05,366 - util.py[DEBUG]: Read 3 bytes from /sys/class/net/ens3/operstate
2019-03-29 11:25:05,367 - util.py[DEBUG]: Running command ['ip', '-6', 'addr', 'show', 'permanent', 'scope', 'global'] with allowed return codes [0] (shell=False, capture=True)
2019-03-29 11:25:05,368 - util.py[DEBUG]: Running command ['ip', '-4', 'addr', 'show'] with allowed return codes [0] (shell=False, capture=True)
2019-03-29 11:25:05,370 - __init__.py[DEBUG]: no work necessary for renaming of [['06:a9:33:51:95:b8', 'ens3', 'ixgbevf', '0x10ed']]
2019-03-29 11:25:05,370 - stages.py[DEBUG]: No network config applied. Neither a new instance nor datasource network update on 'System boot' event
2019-03-29 11:25:05,371 - handlers.py[DEBUG]: start: init-network/setup-datasource: setting up datasource
2019-03-29 11:25:05,371 - handlers.py[DEBUG]: finish: init-network/setup-datasource: SUCCESS: setting up datasource
2019-03-29 11:25:05,371 - util.py[DEBUG]: Writing to /var/lib/cloud/instances/i-07596f108f8d78958/user-data.txt - wb: [600] 0 bytes
2019-03-29 11:25:05,373 - util.py[DEBUG]: Writing to /var/lib/cloud/instances/i-07596f108f8d78958/user-data.txt.i - wb: [600] 308 bytes
2019-03-29 11:25:05,374 - util.py[DEBUG]: Writing to /var/lib/cloud/instances/i-07596f108f8d78958/vendor-data.txt - wb: [600] 0 bytes
2019-03-29 11:25:05,375 - util.py[DEBUG]: Writing to /var/lib/cloud/instances/i-07596f108f8d78958/vendor-data.txt.i - wb: [600] 308 bytes
2019-03-29 11:25:05,376 - util.py[DEBUG]: Reading from /var/lib/cloud/data/set-hostname (quiet=False)
2019-03-29 11:25:05,376 - util.py[DEBUG]: Read 86 bytes from /var/lib/cloud/data/set-hostname
2019-03-29 11:25:05,376 - cc_set_hostname.py[DEBUG]: No hostname changes. Skipping set-hostname
2019-03-29 11:25:05,376 - util.py[DEBUG]: Writing to /var/lib/cloud/instances/i-07596f108f8d78958/sem/consume_data - wb: [644] 25 bytes
2019-03-29 11:25:05,377 - helpers.py[DEBUG]: Running consume_data using lock (<FileLock using file '/var/lib/cloud/instances/i-07596f108f8d78958/sem/consume_data'>)
2019-03-29 11:25:05,377 - handlers.py[DEBUG]: start: init-network/consume-user-data: reading and applying user-data
2019-03-29 11:25:05,377 - launch_index.py[DEBUG]: Discarding 0 multipart messages which do not match launch index 0
2019-03-29 11:25:05,377 - stages.py[DEBUG]: Added default handler for {'text/cloud-config-jsonp', 'text/cloud-config'} from CloudConfigPartHandler: [['text/cloud-config-jsonp', 'text/cloud-config']]
2019-03-29 11:25:05,377 - stages.py[DEBUG]: Added default handler for {'text/x-shellscript'} from ShellScriptPartHandler: [['text/x-shellscript']]
2019-03-29 11:25:05,377 - stages.py[DEBUG]: Added default handler for {'text/cloud-boothook'} from BootHookPartHandler: [['text/cloud-boothook']]
2019-03-29 11:25:05,378 - stages.py[DEBUG]: Added default handler for {'text/upstart-job'} from UpstartJobPartHandler: [['text/upstart-job']]
2019-03-29 11:25:05,378 - __init__.py[DEBUG]: Calling handler UpstartJobPartHandler: [['text/upstart-job']] (__begin__, None, 2) with frequency once-per-instance
2019-03-29 11:25:05,378 - __init__.py[DEBUG]: Calling handler ShellScriptPartHandler: [['text/x-shellscript']] (__begin__, None, 2) with frequency once-per-instance
2019-03-29 11:25:05,378 - __init__.py[DEBUG]: Calling handler CloudConfigPartHandler: [['text/cloud-config-jsonp', 'text/cloud-config']] (__begin__, None, 3) with frequency once-per-instance
2019-03-29 11:25:05,378 - __init__.py[DEBUG]: Calling handler BootHookPartHandler: [['text/cloud-boothook']] (__begin__, None, 2) with frequency once-per-instance
2019-03-29 11:25:05,378 - __init__.py[DEBUG]: {'Content-Type': 'text/x-not-multipart', 'MIME-Version': '1.0', 'Content-Disposition': 'attachment; filename="part-001"'}
2019-03-29 11:25:05,378 - __init__.py[DEBUG]: Empty payload of type text/x-not-multipart
2019-03-29 11:25:05,378 - __init__.py[DEBUG]: Calling handler UpstartJobPartHandler: [['text/upstart-job']] (__end__, None, 2) with frequency once-per-instance
2019-03-29 11:25:05,378 - __init__.py[DEBUG]: Calling handler ShellScriptPartHandler: [['text/x-shellscript']] (__end__, None, 2) with frequency once-per-instance
2019-03-29 11:25:05,378 - __init__.py[DEBUG]: Calling handler CloudConfigPartHandler: [['text/cloud-config-jsonp', 'text/cloud-config']] (__end__, None, 3) with frequency once-per-instance
2019-03-29 11:25:05,378 - util.py[DEBUG]: Writing to /var/lib/cloud/instances/i-07596f108f8d78958/cloud-config.txt - wb: [600] 0 bytes
2019-03-29 11:25:05,379 - __init__.py[DEBUG]: Calling handler BootHookPartHandler: [['text/cloud-boothook']] (__end__, None, 2) with frequency once-per-instance
2019-03-29 11:25:05,379 - handlers.py[DEBUG]: finish: init-network/consume-user-data: SUCCESS: reading and applying user-data
2019-03-29 11:25:05,379 - handlers.py[DEBUG]: start: init-network/consume-vendor-data: reading and applying vendor-data
2019-03-29 11:25:05,379 - stages.py[DEBUG]: no vendordata from datasource
2019-03-29 11:25:05,379 - handlers.py[DEBUG]: finish: init-network/consume-vendor-data: SUCCESS: reading and applying vendor-data
2019-03-29 11:25:05,379 - util.py[DEBUG]: Reading from /etc/cloud/cloud.cfg (quiet=False)
2019-03-29 11:25:05,379 - util.py[DEBUG]: Read 3169 bytes from /etc/cloud/cloud.cfg
2019-03-29 11:25:05,379 - util.py[DEBUG]: Attempting to load yaml from string of length 3169 with allowed root types (<class 'dict'>,)
2019-03-29 11:25:05,390 - util.py[DEBUG]: Reading from /etc/cloud/cloud.cfg.d/90_dpkg.cfg (quiet=False)
2019-03-29 11:25:05,390 - util.py[DEBUG]: Read 238 bytes from /etc/cloud/cloud.cfg.d/90_dpkg.cfg
2019-03-29 11:25:05,390 - util.py[DEBUG]: Attempting to load yaml from string of length 238 with allowed root types (<class 'dict'>,)
2019-03-29 11:25:05,391 - util.py[DEBUG]: Reading from /etc/cloud/cloud.cfg.d/05_logging.cfg (quiet=False)
2019-03-29 11:25:05,391 - util.py[DEBUG]: Read 2057 bytes from /etc/cloud/cloud.cfg.d/05_logging.cfg
2019-03-29 11:25:05,391 - util.py[DEBUG]: Attempting to load yaml from string of length 2057 with allowed root types (<class 'dict'>,)
2019-03-29 11:25:05,394 - util.py[DEBUG]: Reading from /run/cloud-init/cloud.cfg (quiet=False)
2019-03-29 11:25:05,394 - util.py[DEBUG]: Read 44 bytes from /run/cloud-init/cloud.cfg
2019-03-29 11:25:05,395 - util.py[DEBUG]: Attempting to load yaml from string of length 44 with allowed root types (<class 'dict'>,)
2019-03-29 11:25:05,395 - util.py[DEBUG]: Attempting to load yaml from string of length 0 with allowed root types (<class 'dict'>,)
2019-03-29 11:25:05,395 - util.py[DEBUG]: loaded blob returned None, returning default.
2019-03-29 11:25:05,395 - util.py[DEBUG]: Reading from /var/lib/cloud/instance/cloud-config.txt (quiet=False)
2019-03-29 11:25:05,395 - util.py[DEBUG]: Read 0 bytes from /var/lib/cloud/instance/cloud-config.txt
2019-03-29 11:25:05,396 - util.py[DEBUG]: Attempting to load yaml from string of length 0 with allowed root types (<class 'dict'>,)
2019-03-29 11:25:05,396 - util.py[DEBUG]: loaded blob returned None, returning default.
2019-03-29 11:25:05,396 - util.py[DEBUG]: Reading from /var/lib/cloud/instance/cloud-config.txt (quiet=False)
2019-03-29 11:25:05,396 - util.py[DEBUG]: Read 0 bytes from /var/lib/cloud/instance/cloud-config.txt
2019-03-29 11:25:05,396 - util.py[DEBUG]: Attempting to load yaml from string of length 0 with allowed root types (<class 'dict'>,)
2019-03-29 11:25:05,396 - util.py[DEBUG]: loaded blob returned None, returning default.
2019-03-29 11:25:05,398 - handlers.py[DEBUG]: start: init-network/activate-datasource: activating datasource
2019-03-29 11:25:05,398 - util.py[DEBUG]: Writing to /var/lib/cloud/instance/obj.pkl - wb: [400] 9363 bytes
2019-03-29 11:25:05,399 - handlers.py[DEBUG]: finish: init-network/activate-datasource: SUCCESS: activating datasource
2019-03-29 11:25:05,399 - main.py[DEBUG]: used datasource 'DataSourceEc2Local' from 'Ec2' was in di_report's list: ['Ec2', 'None']
2019-03-29 11:25:05,491 - stages.py[DEBUG]: Using distro class <class 'cloudinit.distros.ubuntu.Distro'>
2019-03-29 11:25:05,491 - stages.py[DEBUG]: Running module migrator (<module 'cloudinit.config.cc_migrator' from '/usr/lib/python3/dist-packages/cloudinit/config/cc_migrator.py'>) with frequency always
2019-03-29 11:25:05,492 - handlers.py[DEBUG]: start: init-network/config-migrator: running config-migrator with frequency always
2019-03-29 11:25:05,492 - helpers.py[DEBUG]: Running config-migrator using lock (<cloudinit.helpers.DummyLock object at 0x7fe4124b3470>)
2019-03-29 11:25:05,492 - cc_migrator.py[DEBUG]: Migrated 0 semaphore files to there canonicalized names
2019-03-29 11:25:05,492 - handlers.py[DEBUG]: finish: init-network/config-migrator: SUCCESS: config-migrator ran successfully
2019-03-29 11:25:05,492 - stages.py[DEBUG]: Running module seed_random (<module 'cloudinit.config.cc_seed_random' from '/usr/lib/python3/dist-packages/cloudinit/config/cc_seed_random.py'>) with frequency once-per-instance
2019-03-29 11:25:05,492 - handlers.py[DEBUG]: start: init-network/config-seed_random: running config-seed_random with frequency once-per-instance
2019-03-29 11:25:05,492 - util.py[DEBUG]: Writing to /var/lib/cloud/instances/i-07596f108f8d78958/sem/config_seed_random - wb: [644] 24 bytes
2019-03-29 11:25:05,493 - helpers.py[DEBUG]: Running config-seed_random using lock (<FileLock using file '/var/lib/cloud/instances/i-07596f108f8d78958/sem/config_seed_random'>)
2019-03-29 11:25:05,493 - cc_seed_random.py[DEBUG]: no command provided
2019-03-29 11:25:05,493 - handlers.py[DEBUG]: finish: init-network/config-seed_random: SUCCESS: config-seed_random ran successfully
2019-03-29 11:25:05,493 - stages.py[DEBUG]: Running module bootcmd (<module 'cloudinit.config.cc_bootcmd' from '/usr/lib/python3/dist-packages/cloudinit/config/cc_bootcmd.py'>) with frequency always
2019-03-29 11:25:05,493 - handlers.py[DEBUG]: start: init-network/config-bootcmd: running config-bootcmd with frequency always
2019-03-29 11:25:05,493 - helpers.py[DEBUG]: Running config-bootcmd using lock (<cloudinit.helpers.DummyLock object at 0x7fe4124bac18>)
2019-03-29 11:25:05,493 - cc_bootcmd.py[DEBUG]: Skipping module named bootcmd, no 'bootcmd' key in configuration
2019-03-29 11:25:05,494 - handlers.py[DEBUG]: finish: init-network/config-bootcmd: SUCCESS: config-bootcmd ran successfully
2019-03-29 11:25:05,494 - stages.py[DEBUG]: Running module write-files (<module 'cloudinit.config.cc_write_files' from '/usr/lib/python3/dist-packages/cloudinit/config/cc_write_files.py'>) with frequency once-per-instance
2019-03-29 11:25:05,494 - handlers.py[DEBUG]: start: init-network/config-write-files: running config-write-files with frequency once-per-instance
2019-03-29 11:25:05,494 - util.py[DEBUG]: Writing to /var/lib/cloud/instances/i-07596f108f8d78958/sem/config_write_files - wb: [644] 25 bytes
2019-03-29 11:25:05,494 - helpers.py[DEBUG]: Running config-write-files using lock (<FileLock using file '/var/lib/cloud/instances/i-07596f108f8d78958/sem/config_write_files'>)
2019-03-29 11:25:05,494 - cc_write_files.py[DEBUG]: Skipping module named write-files, no/empty 'write_files' key in configuration
2019-03-29 11:25:05,494 - handlers.py[DEBUG]: finish: init-network/config-write-files: SUCCESS: config-write-files ran successfully
2019-03-29 11:25:05,494 - stages.py[DEBUG]: Running module growpart (<module 'cloudinit.config.cc_growpart' from '/usr/lib/python3/dist-packages/cloudinit/config/cc_growpart.py'>) with frequency always
2019-03-29 11:25:05,495 - handlers.py[DEBUG]: start: init-network/config-growpart: running config-growpart with frequency always
2019-03-29 11:25:05,495 - helpers.py[DEBUG]: Running config-growpart using lock (<cloudinit.helpers.DummyLock object at 0x7fe4124bad68>)
2019-03-29 11:25:05,495 - cc_growpart.py[DEBUG]: No 'growpart' entry in cfg.  Using default: {'devices': ['/'], 'ignore_growroot_disabled': False, 'mode': 'auto'}
2019-03-29 11:25:05,495 - util.py[DEBUG]: Running command ['growpart', '--help'] with allowed return codes [0] (shell=False, capture=True)
2019-03-29 11:25:05,510 - util.py[DEBUG]: Reading from /proc/1306/mountinfo (quiet=False)
2019-03-29 11:25:05,511 - util.py[DEBUG]: Read 2627 bytes from /proc/1306/mountinfo
2019-03-29 11:25:05,511 - util.py[DEBUG]: Running command ['systemd-detect-virt', '--quiet', '--container'] with allowed return codes [0] (shell=False, capture=True)
2019-03-29 11:25:05,513 - util.py[DEBUG]: Running command ['running-in-container'] with allowed return codes [0] (shell=False, capture=True)
2019-03-29 11:25:05,514 - util.py[DEBUG]: Running command ['lxc-is-container'] with allowed return codes [0] (shell=False, capture=True)
2019-03-29 11:25:05,516 - util.py[DEBUG]: Reading from /proc/1/environ (quiet=False)
2019-03-29 11:25:05,516 - util.py[DEBUG]: Read 150 bytes from /proc/1/environ
2019-03-29 11:25:05,516 - util.py[DEBUG]: Reading from /proc/self/status (quiet=False)
2019-03-29 11:25:05,517 - util.py[DEBUG]: Read 971 bytes from /proc/self/status
2019-03-29 11:25:05,519 - util.py[DEBUG]: Reading from /etc/os-release (quiet=False)
2019-03-29 11:25:05,519 - util.py[DEBUG]: Read 298 bytes from /etc/os-release
2019-03-29 11:25:05,520 - util.py[DEBUG]: Reading from /sys/class/block/xvda1/partition (quiet=False)
2019-03-29 11:25:05,520 - util.py[DEBUG]: Read 2 bytes from /sys/class/block/xvda1/partition
2019-03-29 11:25:05,520 - util.py[DEBUG]: Reading from /sys/devices/vbd-768/block/xvda/dev (quiet=False)
2019-03-29 11:25:05,520 - util.py[DEBUG]: Read 6 bytes from /sys/devices/vbd-768/block/xvda/dev
2019-03-29 11:25:05,520 - util.py[DEBUG]: Running command ['growpart', '--dry-run', '/dev/xvda', '1'] with allowed return codes [0] (shell=False, capture=True)
2019-03-29 11:25:05,647 - util.py[DEBUG]: Running command ['growpart', '/dev/xvda', '1'] with allowed return codes [0] (shell=False, capture=True)
2019-03-29 11:25:05,697 - util.py[DEBUG]: resize_devices took 0.187 seconds
2019-03-29 11:25:05,698 - cc_growpart.py[INFO]: '/' resized: changed (/dev/xvda, 1) from 8588869120 to 107373116928
2019-03-29 11:25:05,698 - handlers.py[DEBUG]: finish: init-network/config-growpart: SUCCESS: config-growpart ran successfully
2019-03-29 11:25:05,698 - stages.py[DEBUG]: Running module resizefs (<module 'cloudinit.config.cc_resizefs' from '/usr/lib/python3/dist-packages/cloudinit/config/cc_resizefs.py'>) with frequency always
2019-03-29 11:25:05,698 - handlers.py[DEBUG]: start: init-network/config-resizefs: running config-resizefs with frequency always
2019-03-29 11:25:05,698 - helpers.py[DEBUG]: Running config-resizefs using lock (<cloudinit.helpers.DummyLock object at 0x7fe4124ba128>)
2019-03-29 11:25:05,699 - schema.py[DEBUG]: Ignoring schema validation. python-jsonschema is not present
2019-03-29 11:25:05,699 - util.py[DEBUG]: Reading from /proc/1306/mountinfo (quiet=False)
2019-03-29 11:25:05,699 - util.py[DEBUG]: Read 2627 bytes from /proc/1306/mountinfo
2019-03-29 11:25:05,699 - cc_resizefs.py[DEBUG]: resize_info: dev=/dev/xvda1 mnt_point=/ path=/
2019-03-29 11:25:05,699 - util.py[DEBUG]: Running command ['systemd-detect-virt', '--quiet', '--container'] with allowed return codes [0] (shell=False, capture=True)
2019-03-29 11:25:05,701 - util.py[DEBUG]: Running command ['running-in-container'] with allowed return codes [0] (shell=False, capture=True)
2019-03-29 11:25:05,702 - util.py[DEBUG]: Running command ['lxc-is-container'] with allowed return codes [0] (shell=False, capture=True)
2019-03-29 11:25:05,703 - util.py[DEBUG]: Reading from /proc/1/environ (quiet=False)
2019-03-29 11:25:05,703 - util.py[DEBUG]: Read 150 bytes from /proc/1/environ
2019-03-29 11:25:05,703 - util.py[DEBUG]: Reading from /proc/self/status (quiet=False)
2019-03-29 11:25:05,704 - util.py[DEBUG]: Read 972 bytes from /proc/self/status
2019-03-29 11:25:05,704 - cc_resizefs.py[DEBUG]: Resizing / (ext4) using resize2fs /dev/xvda1
2019-03-29 11:25:05,704 - util.py[DEBUG]: Running command ('resize2fs', '/dev/xvda1') with allowed return codes [0] (shell=False, capture=True)
2019-03-29 11:25:05,799 - util.py[DEBUG]: Resizing took 0.095 seconds
2019-03-29 11:25:05,799 - cc_resizefs.py[DEBUG]: Resized root filesystem (type=ext4, val=True)
2019-03-29 11:25:05,799 - handlers.py[DEBUG]: finish: init-network/config-resizefs: SUCCESS: config-resizefs ran successfully
2019-03-29 11:25:05,799 - stages.py[DEBUG]: Running module disk_setup (<module 'cloudinit.config.cc_disk_setup' from '/usr/lib/python3/dist-packages/cloudinit/config/cc_disk_setup.py'>) with frequency once-per-instance
2019-03-29 11:25:05,799 - handlers.py[DEBUG]: start: init-network/config-disk_setup: running config-disk_setup with frequency once-per-instance
2019-03-29 11:25:05,799 - util.py[DEBUG]: Writing to /var/lib/cloud/instances/i-07596f108f8d78958/sem/config_disk_setup - wb: [644] 25 bytes
2019-03-29 11:25:05,800 - helpers.py[DEBUG]: Running config-disk_setup using lock (<FileLock using file '/var/lib/cloud/instances/i-07596f108f8d78958/sem/config_disk_setup'>)
2019-03-29 11:25:05,800 - handlers.py[DEBUG]: finish: init-network/config-disk_setup: SUCCESS: config-disk_setup ran successfully
2019-03-29 11:25:05,800 - stages.py[DEBUG]: Running module mounts (<module 'cloudinit.config.cc_mounts' from '/usr/lib/python3/dist-packages/cloudinit/config/cc_mounts.py'>) with frequency once-per-instance
2019-03-29 11:25:05,800 - handlers.py[DEBUG]: start: init-network/config-mounts: running config-mounts with frequency once-per-instance
2019-03-29 11:25:05,800 - util.py[DEBUG]: Writing to /var/lib/cloud/instances/i-07596f108f8d78958/sem/config_mounts - wb: [644] 25 bytes
2019-03-29 11:25:05,801 - helpers.py[DEBUG]: Running config-mounts using lock (<FileLock using file '/var/lib/cloud/instances/i-07596f108f8d78958/sem/config_mounts'>)
2019-03-29 11:25:05,801 - cc_mounts.py[DEBUG]: mounts configuration is []
2019-03-29 11:25:05,801 - util.py[DEBUG]: Reading from /etc/fstab (quiet=False)
2019-03-29 11:25:05,801 - util.py[DEBUG]: Read 51 bytes from /etc/fstab
2019-03-29 11:25:05,801 - cc_mounts.py[DEBUG]: Attempting to determine the real name of ephemeral0
2019-03-29 11:25:05,802 - cc_mounts.py[DEBUG]: changed default device ephemeral0 => None
2019-03-29 11:25:05,802 - cc_mounts.py[DEBUG]: Ignoring nonexistent default named mount ephemeral0
2019-03-29 11:25:05,802 - cc_mounts.py[DEBUG]: Attempting to determine the real name of swap
2019-03-29 11:25:05,802 - DataSourceEc2.py[DEBUG]: Unable to convert swap to a device
2019-03-29 11:25:05,802 - cc_mounts.py[DEBUG]: changed default device swap => None
2019-03-29 11:25:05,802 - cc_mounts.py[DEBUG]: Ignoring nonexistent default named mount swap
2019-03-29 11:25:05,802 - cc_mounts.py[DEBUG]: no need to setup swap
2019-03-29 11:25:05,802 - cc_mounts.py[DEBUG]: No modifications to fstab needed
2019-03-29 11:25:05,802 - handlers.py[DEBUG]: finish: init-network/config-mounts: SUCCESS: config-mounts ran successfully
2019-03-29 11:25:05,802 - stages.py[DEBUG]: Running module set_hostname (<module 'cloudinit.config.cc_set_hostname' from '/usr/lib/python3/dist-packages/cloudinit/config/cc_set_hostname.py'>) with frequency once-per-instance
2019-03-29 11:25:05,802 - handlers.py[DEBUG]: start: init-network/config-set_hostname: running config-set_hostname with frequency once-per-instance
2019-03-29 11:25:05,802 - util.py[DEBUG]: Writing to /var/lib/cloud/instances/i-07596f108f8d78958/sem/config_set_hostname - wb: [644] 25 bytes
2019-03-29 11:25:05,803 - helpers.py[DEBUG]: Running config-set_hostname using lock (<FileLock using file '/var/lib/cloud/instances/i-07596f108f8d78958/sem/config_set_hostname'>)
2019-03-29 11:25:05,803 - util.py[DEBUG]: Reading from /var/lib/cloud/data/set-hostname (quiet=False)
2019-03-29 11:25:05,803 - util.py[DEBUG]: Read 86 bytes from /var/lib/cloud/data/set-hostname
2019-03-29 11:25:05,803 - cc_set_hostname.py[DEBUG]: No hostname changes. Skipping set-hostname
2019-03-29 11:25:05,803 - handlers.py[DEBUG]: finish: init-network/config-set_hostname: SUCCESS: config-set_hostname ran successfully
2019-03-29 11:25:05,803 - stages.py[DEBUG]: Running module update_hostname (<module 'cloudinit.config.cc_update_hostname' from '/usr/lib/python3/dist-packages/cloudinit/config/cc_update_hostname.py'>) with frequency always
2019-03-29 11:25:05,803 - handlers.py[DEBUG]: start: init-network/config-update_hostname: running config-update_hostname with frequency always
2019-03-29 11:25:05,803 - helpers.py[DEBUG]: Running config-update_hostname using lock (<cloudinit.helpers.DummyLock object at 0x7fe4124ba4a8>)
2019-03-29 11:25:05,803 - cc_update_hostname.py[DEBUG]: Updating hostname to ip-10-0-0-206.eu-west-1.compute.internal (ip-10-0-0-206)
2019-03-29 11:25:05,803 - util.py[DEBUG]: Reading from /etc/hostname (quiet=False)
2019-03-29 11:25:05,803 - util.py[DEBUG]: Read 14 bytes from /etc/hostname
2019-03-29 11:25:05,803 - __init__.py[DEBUG]: Attempting to update hostname to ip-10-0-0-206 in 1 files
2019-03-29 11:25:05,804 - util.py[DEBUG]: Reading from /var/lib/cloud/data/previous-hostname (quiet=False)
2019-03-29 11:25:05,804 - util.py[DEBUG]: Writing to /var/lib/cloud/data/previous-hostname - wb: [644] 14 bytes
2019-03-29 11:25:05,804 - handlers.py[DEBUG]: finish: init-network/config-update_hostname: SUCCESS: config-update_hostname ran successfully
2019-03-29 11:25:05,804 - stages.py[DEBUG]: Running module update_etc_hosts (<module 'cloudinit.config.cc_update_etc_hosts' from '/usr/lib/python3/dist-packages/cloudinit/config/cc_update_etc_hosts.py'>) with frequency always
2019-03-29 11:25:05,804 - handlers.py[DEBUG]: start: init-network/config-update_etc_hosts: running config-update_etc_hosts with frequency always
2019-03-29 11:25:05,804 - helpers.py[DEBUG]: Running config-update_etc_hosts using lock (<cloudinit.helpers.DummyLock object at 0x7fe4124bd8d0>)
2019-03-29 11:25:05,804 - cc_update_etc_hosts.py[DEBUG]: Configuration option 'manage_etc_hosts' is not set, not managing /etc/hosts in module update_etc_hosts
2019-03-29 11:25:05,804 - handlers.py[DEBUG]: finish: init-network/config-update_etc_hosts: SUCCESS: config-update_etc_hosts ran successfully
2019-03-29 11:25:05,804 - stages.py[DEBUG]: Running module ca-certs (<module 'cloudinit.config.cc_ca_certs' from '/usr/lib/python3/dist-packages/cloudinit/config/cc_ca_certs.py'>) with frequency once-per-instance
2019-03-29 11:25:05,805 - handlers.py[DEBUG]: start: init-network/config-ca-certs: running config-ca-certs with frequency once-per-instance
2019-03-29 11:25:05,805 - util.py[DEBUG]: Writing to /var/lib/cloud/instances/i-07596f108f8d78958/sem/config_ca_certs - wb: [644] 25 bytes
2019-03-29 11:25:05,805 - helpers.py[DEBUG]: Running config-ca-certs using lock (<FileLock using file '/var/lib/cloud/instances/i-07596f108f8d78958/sem/config_ca_certs'>)
2019-03-29 11:25:05,805 - cc_ca_certs.py[DEBUG]: Skipping module named ca-certs, no 'ca-certs' key in configuration
2019-03-29 11:25:05,805 - handlers.py[DEBUG]: finish: init-network/config-ca-certs: SUCCESS: config-ca-certs ran successfully
2019-03-29 11:25:05,805 - stages.py[DEBUG]: Running module rsyslog (<module 'cloudinit.config.cc_rsyslog' from '/usr/lib/python3/dist-packages/cloudinit/config/cc_rsyslog.py'>) with frequency once-per-instance
2019-03-29 11:25:05,805 - handlers.py[DEBUG]: start: init-network/config-rsyslog: running config-rsyslog with frequency once-per-instance
2019-03-29 11:25:05,806 - util.py[DEBUG]: Writing to /var/lib/cloud/instances/i-07596f108f8d78958/sem/config_rsyslog - wb: [644] 25 bytes
2019-03-29 11:25:05,806 - helpers.py[DEBUG]: Running config-rsyslog using lock (<FileLock using file '/var/lib/cloud/instances/i-07596f108f8d78958/sem/config_rsyslog'>)
2019-03-29 11:25:05,806 - cc_rsyslog.py[DEBUG]: Skipping module named rsyslog, no 'rsyslog' key in configuration
2019-03-29 11:25:05,806 - handlers.py[DEBUG]: finish: init-network/config-rsyslog: SUCCESS: config-rsyslog ran successfully
2019-03-29 11:25:05,806 - stages.py[DEBUG]: Running module users-groups (<module 'cloudinit.config.cc_users_groups' from '/usr/lib/python3/dist-packages/cloudinit/config/cc_users_groups.py'>) with frequency once-per-instance
2019-03-29 11:25:05,806 - handlers.py[DEBUG]: start: init-network/config-users-groups: running config-users-groups with frequency once-per-instance
2019-03-29 11:25:05,806 - util.py[DEBUG]: Writing to /var/lib/cloud/instances/i-07596f108f8d78958/sem/config_users_groups - wb: [644] 25 bytes
2019-03-29 11:25:05,807 - helpers.py[DEBUG]: Running config-users-groups using lock (<FileLock using file '/var/lib/cloud/instances/i-07596f108f8d78958/sem/config_users_groups'>)
2019-03-29 11:25:05,807 - util.py[DEBUG]: Reading from /etc/os-release (quiet=True)
2019-03-29 11:25:05,807 - util.py[DEBUG]: Read 298 bytes from /etc/os-release
2019-03-29 11:25:05,808 - util.py[DEBUG]: Reading from /etc/system-image/channel.ini (quiet=True)
2019-03-29 11:25:05,808 - util.py[DEBUG]: Read 0 bytes from /etc/system-image/channel.ini
2019-03-29 11:25:05,808 - __init__.py[DEBUG]: Adding user ubuntu
2019-03-29 11:25:05,808 - util.py[DEBUG]: Running hidden command to protect sensitive input/output logstring: ['useradd', 'ubuntu', '--comment', 'Ubuntu', '--groups', 'adm,audio,cdrom,dialout,dip,floppy,lxd,netdev,plugdev,sudo,video', '--shell', '/bin/bash', '-m']
2019-03-29 11:25:05,928 - util.py[DEBUG]: Running command ['passwd', '-l', 'ubuntu'] with allowed return codes [0] (shell=False, capture=True)
2019-03-29 11:25:05,959 - util.py[DEBUG]: Reading from /etc/sudoers (quiet=False)
2019-03-29 11:25:05,959 - util.py[DEBUG]: Read 755 bytes from /etc/sudoers
2019-03-29 11:25:05,961 - util.py[DEBUG]: Writing to /etc/sudoers.d/90-cloud-init-users - wb: [440] 151 bytes
2019-03-29 11:25:05,961 - handlers.py[DEBUG]: finish: init-network/config-users-groups: SUCCESS: config-users-groups ran successfully
2019-03-29 11:25:05,961 - stages.py[DEBUG]: Running module ssh (<module 'cloudinit.config.cc_ssh' from '/usr/lib/python3/dist-packages/cloudinit/config/cc_ssh.py'>) with frequency once-per-instance
2019-03-29 11:25:05,961 - handlers.py[DEBUG]: start: init-network/config-ssh: running config-ssh with frequency once-per-instance
2019-03-29 11:25:05,962 - util.py[DEBUG]: Writing to /var/lib/cloud/instances/i-07596f108f8d78958/sem/config_ssh - wb: [644] 25 bytes
2019-03-29 11:25:05,962 - helpers.py[DEBUG]: Running config-ssh using lock (<FileLock using file '/var/lib/cloud/instances/i-07596f108f8d78958/sem/config_ssh'>)
2019-03-29 11:25:05,963 - util.py[DEBUG]: Running command ['ssh-keygen', '-t', 'rsa', '-N', '', '-f', '/etc/ssh/ssh_host_rsa_key'] with allowed return codes [0] (shell=False, capture=True)
2019-03-29 11:25:06,019 - util.py[DEBUG]: Running command ['ssh-keygen', '-t', 'dsa', '-N', '', '-f', '/etc/ssh/ssh_host_dsa_key'] with allowed return codes [0] (shell=False, capture=True)
2019-03-29 11:25:06,139 - util.py[DEBUG]: Running command ['ssh-keygen', '-t', 'ecdsa', '-N', '', '-f', '/etc/ssh/ssh_host_ecdsa_key'] with allowed return codes [0] (shell=False, capture=True)
2019-03-29 11:25:06,142 - util.py[DEBUG]: Running command ['ssh-keygen', '-t', 'ed25519', '-N', '', '-f', '/etc/ssh/ssh_host_ed25519_key'] with allowed return codes [0] (shell=False, capture=True)
2019-03-29 11:25:06,147 - util.py[DEBUG]: Changing the ownership of /home/ubuntu/.ssh to 1000:1000
2019-03-29 11:25:06,148 - util.py[DEBUG]: Reading from /etc/ssh/sshd_config (quiet=False)
2019-03-29 11:25:06,148 - util.py[DEBUG]: Read 2540 bytes from /etc/ssh/sshd_config
2019-03-29 11:25:06,149 - util.py[DEBUG]: Writing to /home/ubuntu/.ssh/authorized_keys - wb: [600] 448 bytes
2019-03-29 11:25:06,149 - util.py[DEBUG]: Changing the ownership of /home/ubuntu/.ssh/authorized_keys to 1000:1000
2019-03-29 11:25:06,150 - util.py[DEBUG]: Changing the ownership of /root/.ssh to 0:0
2019-03-29 11:25:06,150 - util.py[DEBUG]: Reading from /etc/ssh/sshd_config (quiet=False)
2019-03-29 11:25:06,150 - util.py[DEBUG]: Read 2540 bytes from /etc/ssh/sshd_config
2019-03-29 11:25:06,151 - util.py[DEBUG]: Writing to /root/.ssh/authorized_keys - wb: [600] 603 bytes
2019-03-29 11:25:06,151 - util.py[DEBUG]: Changing the ownership of /root/.ssh/authorized_keys to 0:0
2019-03-29 11:25:06,151 - handlers.py[DEBUG]: finish: init-network/config-ssh: SUCCESS: config-ssh ran successfully
2019-03-29 11:25:06,151 - main.py[DEBUG]: Ran 15 modules with 0 failures
2019-03-29 11:25:06,152 - util.py[DEBUG]: Reading from /proc/uptime (quiet=False)
2019-03-29 11:25:06,152 - util.py[DEBUG]: Read 12 bytes from /proc/uptime
2019-03-29 11:25:06,152 - util.py[DEBUG]: cloud-init mode 'init' took 0.865 seconds (0.87)
2019-03-29 11:25:06,152 - handlers.py[DEBUG]: finish: init-network: SUCCESS: searching for network datasources
2019-03-29 11:25:19,215 - util.py[DEBUG]: Cloud-init v. 18.3-9-g2e62cb8a-0ubuntu1~16.04.2 running 'modules:config' at Fri, 29 Mar 2019 11:25:19 +0000. Up 22.76 seconds.
2019-03-29 11:25:19,260 - stages.py[DEBUG]: Using distro class <class 'cloudinit.distros.ubuntu.Distro'>
2019-03-29 11:25:19,260 - stages.py[DEBUG]: Running module emit_upstart (<module 'cloudinit.config.cc_emit_upstart' from '/usr/lib/python3/dist-packages/cloudinit/config/cc_emit_upstart.py'>) with frequency always
2019-03-29 11:25:19,261 - handlers.py[DEBUG]: start: modules-config/config-emit_upstart: running config-emit_upstart with frequency always
2019-03-29 11:25:19,261 - helpers.py[DEBUG]: Running config-emit_upstart using lock (<cloudinit.helpers.DummyLock object at 0x7f347eadda90>)
2019-03-29 11:25:19,261 - cc_emit_upstart.py[DEBUG]: no /sbin/initctl located
2019-03-29 11:25:19,261 - cc_emit_upstart.py[DEBUG]: not upstart system, 'emit_upstart' disabled
2019-03-29 11:25:19,261 - handlers.py[DEBUG]: finish: modules-config/config-emit_upstart: SUCCESS: config-emit_upstart ran successfully
2019-03-29 11:25:19,261 - stages.py[DEBUG]: Running module snap (<module 'cloudinit.config.cc_snap' from '/usr/lib/python3/dist-packages/cloudinit/config/cc_snap.py'>) with frequency once-per-instance
2019-03-29 11:25:19,261 - handlers.py[DEBUG]: start: modules-config/config-snap: running config-snap with frequency once-per-instance
2019-03-29 11:25:19,262 - util.py[DEBUG]: Writing to /var/lib/cloud/instances/i-07596f108f8d78958/sem/config_snap - wb: [644] 25 bytes
2019-03-29 11:25:19,262 - helpers.py[DEBUG]: Running config-snap using lock (<FileLock using file '/var/lib/cloud/instances/i-07596f108f8d78958/sem/config_snap'>)
2019-03-29 11:25:19,262 - cc_snap.py[DEBUG]: Skipping module named snap, no 'snap' key in configuration
2019-03-29 11:25:19,262 - handlers.py[DEBUG]: finish: modules-config/config-snap: SUCCESS: config-snap ran successfully
2019-03-29 11:25:19,262 - stages.py[DEBUG]: Running module snap_config (<module 'cloudinit.config.cc_snap_config' from '/usr/lib/python3/dist-packages/cloudinit/config/cc_snap_config.py'>) with frequency once-per-instance
2019-03-29 11:25:19,262 - handlers.py[DEBUG]: start: modules-config/config-snap_config: running config-snap_config with frequency once-per-instance
2019-03-29 11:25:19,262 - util.py[DEBUG]: Writing to /var/lib/cloud/instances/i-07596f108f8d78958/sem/config_snap_config - wb: [644] 25 bytes
2019-03-29 11:25:19,263 - helpers.py[DEBUG]: Running config-snap_config using lock (<FileLock using file '/var/lib/cloud/instances/i-07596f108f8d78958/sem/config_snap_config'>)
2019-03-29 11:25:19,263 - cc_snap_config.py[DEBUG]: No snappy config provided, skipping
2019-03-29 11:25:19,263 - handlers.py[DEBUG]: finish: modules-config/config-snap_config: SUCCESS: config-snap_config ran successfully
2019-03-29 11:25:19,263 - stages.py[DEBUG]: Running module ssh-import-id (<module 'cloudinit.config.cc_ssh_import_id' from '/usr/lib/python3/dist-packages/cloudinit/config/cc_ssh_import_id.py'>) with frequency once-per-instance
2019-03-29 11:25:19,263 - handlers.py[DEBUG]: start: modules-config/config-ssh-import-id: running config-ssh-import-id with frequency once-per-instance
2019-03-29 11:25:19,263 - util.py[DEBUG]: Writing to /var/lib/cloud/instances/i-07596f108f8d78958/sem/config_ssh_import_id - wb: [644] 24 bytes
2019-03-29 11:25:19,264 - helpers.py[DEBUG]: Running config-ssh-import-id using lock (<FileLock using file '/var/lib/cloud/instances/i-07596f108f8d78958/sem/config_ssh_import_id'>)
2019-03-29 11:25:19,264 - handlers.py[DEBUG]: finish: modules-config/config-ssh-import-id: SUCCESS: config-ssh-import-id ran successfully
2019-03-29 11:25:19,264 - stages.py[DEBUG]: Running module locale (<module 'cloudinit.config.cc_locale' from '/usr/lib/python3/dist-packages/cloudinit/config/cc_locale.py'>) with frequency once-per-instance
2019-03-29 11:25:19,264 - handlers.py[DEBUG]: start: modules-config/config-locale: running config-locale with frequency once-per-instance
2019-03-29 11:25:19,264 - util.py[DEBUG]: Writing to /var/lib/cloud/instances/i-07596f108f8d78958/sem/config_locale - wb: [644] 25 bytes
2019-03-29 11:25:19,265 - helpers.py[DEBUG]: Running config-locale using lock (<FileLock using file '/var/lib/cloud/instances/i-07596f108f8d78958/sem/config_locale'>)
2019-03-29 11:25:19,265 - util.py[DEBUG]: Reading from /etc/default/locale (quiet=False)
2019-03-29 11:25:19,265 - util.py[DEBUG]: Read 35 bytes from /etc/default/locale
2019-03-29 11:25:19,265 - cc_locale.py[DEBUG]: Setting locale to en_US.UTF-8
2019-03-29 11:25:19,265 - util.py[DEBUG]: Reading from /etc/default/locale (quiet=False)
2019-03-29 11:25:19,265 - util.py[DEBUG]: Read 35 bytes from /etc/default/locale
2019-03-29 11:25:19,265 - debian.py[DEBUG]: Generating locales for en_US.UTF-8
2019-03-29 11:25:19,265 - util.py[DEBUG]: Running command ['locale-gen', 'en_US.UTF-8'] with allowed return codes [0] (shell=False, capture=False)
2019-03-29 11:25:19,967 - debian.py[DEBUG]: Updating /etc/default/locale with locale setting LANG=en_US.UTF-8
2019-03-29 11:25:19,967 - util.py[DEBUG]: Running command ['update-locale', '--locale-file=/etc/default/locale', 'LANG=en_US.UTF-8'] with allowed return codes [0] (shell=False, capture=False)
2019-03-29 11:25:20,191 - handlers.py[DEBUG]: finish: modules-config/config-locale: SUCCESS: config-locale ran successfully
2019-03-29 11:25:20,191 - stages.py[DEBUG]: Running module set-passwords (<module 'cloudinit.config.cc_set_passwords' from '/usr/lib/python3/dist-packages/cloudinit/config/cc_set_passwords.py'>) with frequency once-per-instance
2019-03-29 11:25:20,191 - handlers.py[DEBUG]: start: modules-config/config-set-passwords: running config-set-passwords with frequency once-per-instance
2019-03-29 11:25:20,191 - util.py[DEBUG]: Writing to /var/lib/cloud/instances/i-07596f108f8d78958/sem/config_set_passwords - wb: [644] 24 bytes
2019-03-29 11:25:20,192 - helpers.py[DEBUG]: Running config-set-passwords using lock (<FileLock using file '/var/lib/cloud/instances/i-07596f108f8d78958/sem/config_set_passwords'>)
2019-03-29 11:25:20,192 - cc_set_passwords.py[DEBUG]: Leaving ssh config 'PasswordAuthentication' unchanged. ssh_pwauth=None
2019-03-29 11:25:20,192 - handlers.py[DEBUG]: finish: modules-config/config-set-passwords: SUCCESS: config-set-passwords ran successfully
2019-03-29 11:25:20,192 - stages.py[DEBUG]: Running module grub-dpkg (<module 'cloudinit.config.cc_grub_dpkg' from '/usr/lib/python3/dist-packages/cloudinit/config/cc_grub_dpkg.py'>) with frequency once-per-instance
2019-03-29 11:25:20,192 - handlers.py[DEBUG]: start: modules-config/config-grub-dpkg: running config-grub-dpkg with frequency once-per-instance
2019-03-29 11:25:20,193 - util.py[DEBUG]: Writing to /var/lib/cloud/instances/i-07596f108f8d78958/sem/config_grub_dpkg - wb: [644] 24 bytes
2019-03-29 11:25:20,193 - helpers.py[DEBUG]: Running config-grub-dpkg using lock (<FileLock using file '/var/lib/cloud/instances/i-07596f108f8d78958/sem/config_grub_dpkg'>)
2019-03-29 11:25:20,193 - cc_grub_dpkg.py[DEBUG]: Setting grub debconf-set-selections with '/dev/xvda','false'
2019-03-29 11:25:20,193 - util.py[DEBUG]: Running command ['debconf-set-selections'] with allowed return codes [0] (shell=False, capture=True)
2019-03-29 11:25:20,633 - handlers.py[DEBUG]: finish: modules-config/config-grub-dpkg: SUCCESS: config-grub-dpkg ran successfully
2019-03-29 11:25:20,633 - stages.py[DEBUG]: Running module apt-pipelining (<module 'cloudinit.config.cc_apt_pipelining' from '/usr/lib/python3/dist-packages/cloudinit/config/cc_apt_pipelining.py'>) with frequency once-per-instance
2019-03-29 11:25:20,634 - handlers.py[DEBUG]: start: modules-config/config-apt-pipelining: running config-apt-pipelining with frequency once-per-instance
2019-03-29 11:25:20,634 - util.py[DEBUG]: Writing to /var/lib/cloud/instances/i-07596f108f8d78958/sem/config_apt_pipelining - wb: [644] 23 bytes
2019-03-29 11:25:20,634 - helpers.py[DEBUG]: Running config-apt-pipelining using lock (<FileLock using file '/var/lib/cloud/instances/i-07596f108f8d78958/sem/config_apt_pipelining'>)
2019-03-29 11:25:20,635 - util.py[DEBUG]: Writing to /etc/apt/apt.conf.d/90cloud-init-pipelining - wb: [644] 80 bytes
2019-03-29 11:25:20,636 - cc_apt_pipelining.py[DEBUG]: Wrote /etc/apt/apt.conf.d/90cloud-init-pipelining with apt pipeline depth setting 0
2019-03-29 11:25:20,636 - handlers.py[DEBUG]: finish: modules-config/config-apt-pipelining: SUCCESS: config-apt-pipelining ran successfully
2019-03-29 11:25:20,636 - stages.py[DEBUG]: Running module apt-configure (<module 'cloudinit.config.cc_apt_configure' from '/usr/lib/python3/dist-packages/cloudinit/config/cc_apt_configure.py'>) with frequency once-per-instance
2019-03-29 11:25:20,636 - handlers.py[DEBUG]: start: modules-config/config-apt-configure: running config-apt-configure with frequency once-per-instance
2019-03-29 11:25:20,636 - util.py[DEBUG]: Writing to /var/lib/cloud/instances/i-07596f108f8d78958/sem/config_apt_configure - wb: [644] 25 bytes
2019-03-29 11:25:20,637 - helpers.py[DEBUG]: Running config-apt-configure using lock (<FileLock using file '/var/lib/cloud/instances/i-07596f108f8d78958/sem/config_apt_configure'>)
2019-03-29 11:25:20,637 - cc_apt_configure.py[DEBUG]: debconf_selections was not set in config
2019-03-29 11:25:20,637 - util.py[DEBUG]: Reading from /etc/os-release (quiet=True)
2019-03-29 11:25:20,637 - util.py[DEBUG]: Read 298 bytes from /etc/os-release
2019-03-29 11:25:20,637 - util.py[DEBUG]: Reading from /etc/system-image/channel.ini (quiet=True)
2019-03-29 11:25:20,637 - util.py[DEBUG]: Read 0 bytes from /etc/system-image/channel.ini
2019-03-29 11:25:20,638 - cc_apt_configure.py[DEBUG]: handling apt config: {}
2019-03-29 11:25:20,638 - util.py[DEBUG]: Running command ['lsb_release', '--all'] with allowed return codes [0] (shell=False, capture=True)
2019-03-29 11:25:20,723 - util.py[DEBUG]: Running command ['dpkg', '--print-architecture'] with allowed return codes [0] (shell=False, capture=True)
2019-03-29 11:25:20,725 - cc_apt_configure.py[DEBUG]: got primary mirror: None
2019-03-29 11:25:20,726 - cc_apt_configure.py[DEBUG]: got security mirror: None
2019-03-29 11:25:20,726 - util.py[DEBUG]: Running command ['dpkg', '--print-architecture'] with allowed return codes [0] (shell=False, capture=True)
2019-03-29 11:25:20,777 - util.py[DEBUG]: Resolving URL: http://eu-west-1.ec2.archive.ubuntu.com/ubuntu/ took 0.049 seconds
2019-03-29 11:25:20,777 - __init__.py[DEBUG]: filtered distro mirror info: {'security': 'http://security.ubuntu.com/ubuntu', 'primary': 'http://eu-west-1.ec2.archive.ubuntu.com/ubuntu/'}
2019-03-29 11:25:20,777 - cc_apt_configure.py[DEBUG]: Apt Mirror info: {'security': 'http://security.ubuntu.com/ubuntu', 'SECURITY': 'http://security.ubuntu.com/ubuntu', 'MIRROR': 'http://eu-west-1.ec2.archive.ubuntu.com/ubuntu/', 'PRIMARY': 'http://eu-west-1.ec2.archive.ubuntu.com/ubuntu/', 'primary': 'http://eu-west-1.ec2.archive.ubuntu.com/ubuntu/'}
2019-03-29 11:25:20,778 - cc_apt_configure.py[INFO]: No custom template provided, fall back to builtin
2019-03-29 11:25:20,779 - util.py[DEBUG]: Reading from /etc/cloud/templates/sources.list.ubuntu.tmpl (quiet=False)
2019-03-29 11:25:20,779 - util.py[DEBUG]: Read 2841 bytes from /etc/cloud/templates/sources.list.ubuntu.tmpl
2019-03-29 11:25:20,786 - util.py[DEBUG]: Writing to /etc/apt/sources.list - wb: [644] 3335 bytes
2019-03-29 11:25:20,786 - util.py[DEBUG]: Running command ['dpkg', '--print-architecture'] with allowed return codes [0] (shell=False, capture=True)
2019-03-29 11:25:20,790 - cc_apt_configure.py[DEBUG]: Renaming apt list /var/lib/apt/lists/archive.ubuntu.com_ubuntu_dists_xenial-updates_main_i18n_Translation-en to /var/lib/apt/lists/eu-west-1.ec2.archive.ubuntu.com_ubuntu_dists_xenial-updates_main_i18n_Translation-en
2019-03-29 11:25:20,790 - cc_apt_configure.py[DEBUG]: Renaming apt list /var/lib/apt/lists/archive.ubuntu.com_ubuntu_dists_xenial-updates_main_binary-amd64_Packages to /var/lib/apt/lists/eu-west-1.ec2.archive.ubuntu.com_ubuntu_dists_xenial-updates_main_binary-amd64_Packages
2019-03-29 11:25:20,791 - cc_apt_configure.py[DEBUG]: Renaming apt list /var/lib/apt/lists/archive.ubuntu.com_ubuntu_dists_xenial-updates_restricted_binary-amd64_Packages to /var/lib/apt/lists/eu-west-1.ec2.archive.ubuntu.com_ubuntu_dists_xenial-updates_restricted_binary-amd64_Packages
2019-03-29 11:25:20,791 - cc_apt_configure.py[DEBUG]: Renaming apt list /var/lib/apt/lists/archive.ubuntu.com_ubuntu_dists_xenial_main_i18n_Translation-en to /var/lib/apt/lists/eu-west-1.ec2.archive.ubuntu.com_ubuntu_dists_xenial_main_i18n_Translation-en
2019-03-29 11:25:20,791 - cc_apt_configure.py[DEBUG]: Renaming apt list /var/lib/apt/lists/archive.ubuntu.com_ubuntu_dists_xenial-updates_restricted_i18n_Translation-en to /var/lib/apt/lists/eu-west-1.ec2.archive.ubuntu.com_ubuntu_dists_xenial-updates_restricted_i18n_Translation-en
2019-03-29 11:25:20,791 - cc_apt_configure.py[DEBUG]: Renaming apt list /var/lib/apt/lists/archive.ubuntu.com_ubuntu_dists_xenial-updates_InRelease to /var/lib/apt/lists/eu-west-1.ec2.archive.ubuntu.com_ubuntu_dists_xenial-updates_InRelease
2019-03-29 11:25:20,791 - cc_apt_configure.py[DEBUG]: Renaming apt list /var/lib/apt/lists/archive.ubuntu.com_ubuntu_dists_xenial_InRelease to /var/lib/apt/lists/eu-west-1.ec2.archive.ubuntu.com_ubuntu_dists_xenial_InRelease
2019-03-29 11:25:20,791 - cc_apt_configure.py[DEBUG]: Renaming apt list /var/lib/apt/lists/archive.ubuntu.com_ubuntu_dists_xenial_restricted_i18n_Translation-en to /var/lib/apt/lists/eu-west-1.ec2.archive.ubuntu.com_ubuntu_dists_xenial_restricted_i18n_Translation-en
2019-03-29 11:25:20,791 - cc_apt_configure.py[DEBUG]: Renaming apt list /var/lib/apt/lists/archive.ubuntu.com_ubuntu_dists_xenial_restricted_binary-amd64_Packages to /var/lib/apt/lists/eu-west-1.ec2.archive.ubuntu.com_ubuntu_dists_xenial_restricted_binary-amd64_Packages
2019-03-29 11:25:20,791 - cc_apt_configure.py[DEBUG]: Renaming apt list /var/lib/apt/lists/archive.ubuntu.com_ubuntu_dists_xenial_main_binary-amd64_Packages to /var/lib/apt/lists/eu-west-1.ec2.archive.ubuntu.com_ubuntu_dists_xenial_main_binary-amd64_Packages
2019-03-29 11:25:20,791 - handlers.py[DEBUG]: finish: modules-config/config-apt-configure: SUCCESS: config-apt-configure ran successfully
2019-03-29 11:25:20,791 - stages.py[DEBUG]: Running module ubuntu-advantage (<module 'cloudinit.config.cc_ubuntu_advantage' from '/usr/lib/python3/dist-packages/cloudinit/config/cc_ubuntu_advantage.py'>) with frequency once-per-instance
2019-03-29 11:25:20,791 - handlers.py[DEBUG]: start: modules-config/config-ubuntu-advantage: running config-ubuntu-advantage with frequency once-per-instance
2019-03-29 11:25:20,792 - util.py[DEBUG]: Writing to /var/lib/cloud/instances/i-07596f108f8d78958/sem/config_ubuntu_advantage - wb: [644] 25 bytes
2019-03-29 11:25:20,792 - helpers.py[DEBUG]: Running config-ubuntu-advantage using lock (<FileLock using file '/var/lib/cloud/instances/i-07596f108f8d78958/sem/config_ubuntu_advantage'>)
2019-03-29 11:25:20,792 - cc_ubuntu_advantage.py[DEBUG]: Skipping module named ubuntu-advantage, no 'ubuntu-advantage' key in configuration
2019-03-29 11:25:20,792 - handlers.py[DEBUG]: finish: modules-config/config-ubuntu-advantage: SUCCESS: config-ubuntu-advantage ran successfully
2019-03-29 11:25:20,792 - stages.py[DEBUG]: Running module ntp (<module 'cloudinit.config.cc_ntp' from '/usr/lib/python3/dist-packages/cloudinit/config/cc_ntp.py'>) with frequency once-per-instance
2019-03-29 11:25:20,792 - handlers.py[DEBUG]: start: modules-config/config-ntp: running config-ntp with frequency once-per-instance
2019-03-29 11:25:20,793 - util.py[DEBUG]: Writing to /var/lib/cloud/instances/i-07596f108f8d78958/sem/config_ntp - wb: [644] 25 bytes
2019-03-29 11:25:20,793 - helpers.py[DEBUG]: Running config-ntp using lock (<FileLock using file '/var/lib/cloud/instances/i-07596f108f8d78958/sem/config_ntp'>)
2019-03-29 11:25:20,793 - cc_ntp.py[DEBUG]: Skipping module named ntp, not present or disabled by cfg
2019-03-29 11:25:20,793 - handlers.py[DEBUG]: finish: modules-config/config-ntp: SUCCESS: config-ntp ran successfully
2019-03-29 11:25:20,793 - stages.py[DEBUG]: Running module timezone (<module 'cloudinit.config.cc_timezone' from '/usr/lib/python3/dist-packages/cloudinit/config/cc_timezone.py'>) with frequency once-per-instance
2019-03-29 11:25:20,793 - handlers.py[DEBUG]: start: modules-config/config-timezone: running config-timezone with frequency once-per-instance
2019-03-29 11:25:20,793 - util.py[DEBUG]: Writing to /var/lib/cloud/instances/i-07596f108f8d78958/sem/config_timezone - wb: [644] 24 bytes
2019-03-29 11:25:20,794 - helpers.py[DEBUG]: Running config-timezone using lock (<FileLock using file '/var/lib/cloud/instances/i-07596f108f8d78958/sem/config_timezone'>)
2019-03-29 11:25:20,794 - cc_timezone.py[DEBUG]: Skipping module named timezone, no 'timezone' specified
2019-03-29 11:25:20,794 - handlers.py[DEBUG]: finish: modules-config/config-timezone: SUCCESS: config-timezone ran successfully
2019-03-29 11:25:20,794 - stages.py[DEBUG]: Running module disable-ec2-metadata (<module 'cloudinit.config.cc_disable_ec2_metadata' from '/usr/lib/python3/dist-packages/cloudinit/config/cc_disable_ec2_metadata.py'>) with frequency always
2019-03-29 11:25:20,794 - handlers.py[DEBUG]: start: modules-config/config-disable-ec2-metadata: running config-disable-ec2-metadata with frequency always
2019-03-29 11:25:20,794 - helpers.py[DEBUG]: Running config-disable-ec2-metadata using lock (<cloudinit.helpers.DummyLock object at 0x7f347e2d9208>)
2019-03-29 11:25:20,794 - cc_disable_ec2_metadata.py[DEBUG]: Skipping module named disable-ec2-metadata, disabling the ec2 route not enabled
2019-03-29 11:25:20,794 - handlers.py[DEBUG]: finish: modules-config/config-disable-ec2-metadata: SUCCESS: config-disable-ec2-metadata ran successfully
2019-03-29 11:25:20,794 - stages.py[DEBUG]: Running module runcmd (<module 'cloudinit.config.cc_runcmd' from '/usr/lib/python3/dist-packages/cloudinit/config/cc_runcmd.py'>) with frequency once-per-instance
2019-03-29 11:25:20,795 - handlers.py[DEBUG]: start: modules-config/config-runcmd: running config-runcmd with frequency once-per-instance
2019-03-29 11:25:20,795 - util.py[DEBUG]: Writing to /var/lib/cloud/instances/i-07596f108f8d78958/sem/config_runcmd - wb: [644] 25 bytes
2019-03-29 11:25:20,795 - helpers.py[DEBUG]: Running config-runcmd using lock (<FileLock using file '/var/lib/cloud/instances/i-07596f108f8d78958/sem/config_runcmd'>)
2019-03-29 11:25:20,795 - cc_runcmd.py[DEBUG]: Skipping module named runcmd, no 'runcmd' key in configuration
2019-03-29 11:25:20,795 - handlers.py[DEBUG]: finish: modules-config/config-runcmd: SUCCESS: config-runcmd ran successfully
2019-03-29 11:25:20,795 - stages.py[DEBUG]: Running module byobu (<module 'cloudinit.config.cc_byobu' from '/usr/lib/python3/dist-packages/cloudinit/config/cc_byobu.py'>) with frequency once-per-instance
2019-03-29 11:25:20,795 - handlers.py[DEBUG]: start: modules-config/config-byobu: running config-byobu with frequency once-per-instance
2019-03-29 11:25:20,795 - util.py[DEBUG]: Writing to /var/lib/cloud/instances/i-07596f108f8d78958/sem/config_byobu - wb: [644] 25 bytes
2019-03-29 11:25:20,796 - helpers.py[DEBUG]: Running config-byobu using lock (<FileLock using file '/var/lib/cloud/instances/i-07596f108f8d78958/sem/config_byobu'>)
2019-03-29 11:25:20,796 - cc_byobu.py[DEBUG]: Skipping module named byobu, no 'byobu' values found
2019-03-29 11:25:20,796 - handlers.py[DEBUG]: finish: modules-config/config-byobu: SUCCESS: config-byobu ran successfully
2019-03-29 11:25:20,796 - main.py[DEBUG]: Ran 15 modules with 0 failures
2019-03-29 11:25:20,797 - util.py[DEBUG]: Reading from /proc/uptime (quiet=False)
2019-03-29 11:25:20,797 - util.py[DEBUG]: Read 13 bytes from /proc/uptime
2019-03-29 11:25:20,797 - util.py[DEBUG]: cloud-init mode 'modules' took 1.628 seconds (1.62)
2019-03-29 11:25:20,797 - handlers.py[DEBUG]: finish: modules-config: SUCCESS: running modules for config
2019-03-29 11:25:21,099 - util.py[DEBUG]: Cloud-init v. 18.3-9-g2e62cb8a-0ubuntu1~16.04.2 running 'modules:final' at Fri, 29 Mar 2019 11:25:21 +0000. Up 24.64 seconds.
2019-03-29 11:25:21,134 - stages.py[DEBUG]: Using distro class <class 'cloudinit.distros.ubuntu.Distro'>
2019-03-29 11:25:21,135 - stages.py[DEBUG]: Running module snappy (<module 'cloudinit.config.cc_snappy' from '/usr/lib/python3/dist-packages/cloudinit/config/cc_snappy.py'>) with frequency once-per-instance
2019-03-29 11:25:21,135 - handlers.py[DEBUG]: start: modules-final/config-snappy: running config-snappy with frequency once-per-instance
2019-03-29 11:25:21,135 - util.py[DEBUG]: Writing to /var/lib/cloud/instances/i-07596f108f8d78958/sem/config_snappy - wb: [644] 25 bytes
2019-03-29 11:25:21,136 - helpers.py[DEBUG]: Running config-snappy using lock (<FileLock using file '/var/lib/cloud/instances/i-07596f108f8d78958/sem/config_snappy'>)
2019-03-29 11:25:21,136 - util.py[DEBUG]: Reading from /etc/os-release (quiet=True)
2019-03-29 11:25:21,136 - util.py[DEBUG]: Read 298 bytes from /etc/os-release
2019-03-29 11:25:21,136 - util.py[DEBUG]: Reading from /etc/system-image/channel.ini (quiet=True)
2019-03-29 11:25:21,136 - util.py[DEBUG]: Read 0 bytes from /etc/system-image/channel.ini
2019-03-29 11:25:21,136 - cc_snappy.py[DEBUG]: snappy: 'auto' mode, and system not snappy
2019-03-29 11:25:21,137 - handlers.py[DEBUG]: finish: modules-final/config-snappy: SUCCESS: config-snappy ran successfully
2019-03-29 11:25:21,137 - stages.py[DEBUG]: Running module package-update-upgrade-install (<module 'cloudinit.config.cc_package_update_upgrade_install' from '/usr/lib/python3/dist-packages/cloudinit/config/cc_package_update_upgrade_install.py'>) with frequency once-per-instance
2019-03-29 11:25:21,137 - handlers.py[DEBUG]: start: modules-final/config-package-update-upgrade-install: running config-package-update-upgrade-install with frequency once-per-instance
2019-03-29 11:25:21,137 - util.py[DEBUG]: Writing to /var/lib/cloud/instances/i-07596f108f8d78958/sem/config_package_update_upgrade_install - wb: [644] 24 bytes
2019-03-29 11:25:21,138 - helpers.py[DEBUG]: Running config-package-update-upgrade-install using lock (<FileLock using file '/var/lib/cloud/instances/i-07596f108f8d78958/sem/config_package_update_upgrade_install'>)
2019-03-29 11:25:21,138 - handlers.py[DEBUG]: finish: modules-final/config-package-update-upgrade-install: SUCCESS: config-package-update-upgrade-install ran successfully
2019-03-29 11:25:21,138 - stages.py[DEBUG]: Running module fan (<module 'cloudinit.config.cc_fan' from '/usr/lib/python3/dist-packages/cloudinit/config/cc_fan.py'>) with frequency once-per-instance
2019-03-29 11:25:21,138 - handlers.py[DEBUG]: start: modules-final/config-fan: running config-fan with frequency once-per-instance
2019-03-29 11:25:21,138 - util.py[DEBUG]: Writing to /var/lib/cloud/instances/i-07596f108f8d78958/sem/config_fan - wb: [644] 24 bytes
2019-03-29 11:25:21,138 - helpers.py[DEBUG]: Running config-fan using lock (<FileLock using file '/var/lib/cloud/instances/i-07596f108f8d78958/sem/config_fan'>)
2019-03-29 11:25:21,138 - cc_fan.py[DEBUG]: fan: no 'fan' config entry. disabling
2019-03-29 11:25:21,139 - handlers.py[DEBUG]: finish: modules-final/config-fan: SUCCESS: config-fan ran successfully
2019-03-29 11:25:21,139 - stages.py[DEBUG]: Running module landscape (<module 'cloudinit.config.cc_landscape' from '/usr/lib/python3/dist-packages/cloudinit/config/cc_landscape.py'>) with frequency once-per-instance
2019-03-29 11:25:21,139 - handlers.py[DEBUG]: start: modules-final/config-landscape: running config-landscape with frequency once-per-instance
2019-03-29 11:25:21,139 - util.py[DEBUG]: Writing to /var/lib/cloud/instances/i-07596f108f8d78958/sem/config_landscape - wb: [644] 24 bytes
2019-03-29 11:25:21,139 - helpers.py[DEBUG]: Running config-landscape using lock (<FileLock using file '/var/lib/cloud/instances/i-07596f108f8d78958/sem/config_landscape'>)
2019-03-29 11:25:21,139 - handlers.py[DEBUG]: finish: modules-final/config-landscape: SUCCESS: config-landscape ran successfully
2019-03-29 11:25:21,139 - stages.py[DEBUG]: Running module lxd (<module 'cloudinit.config.cc_lxd' from '/usr/lib/python3/dist-packages/cloudinit/config/cc_lxd.py'>) with frequency once-per-instance
2019-03-29 11:25:21,140 - handlers.py[DEBUG]: start: modules-final/config-lxd: running config-lxd with frequency once-per-instance
2019-03-29 11:25:21,140 - util.py[DEBUG]: Writing to /var/lib/cloud/instances/i-07596f108f8d78958/sem/config_lxd - wb: [644] 24 bytes
2019-03-29 11:25:21,140 - helpers.py[DEBUG]: Running config-lxd using lock (<FileLock using file '/var/lib/cloud/instances/i-07596f108f8d78958/sem/config_lxd'>)
2019-03-29 11:25:21,140 - cc_lxd.py[DEBUG]: Skipping module named lxd, not present or disabled by cfg
2019-03-29 11:25:21,140 - handlers.py[DEBUG]: finish: modules-final/config-lxd: SUCCESS: config-lxd ran successfully
2019-03-29 11:25:21,140 - stages.py[DEBUG]: Running module puppet (<module 'cloudinit.config.cc_puppet' from '/usr/lib/python3/dist-packages/cloudinit/config/cc_puppet.py'>) with frequency once-per-instance
2019-03-29 11:25:21,140 - handlers.py[DEBUG]: start: modules-final/config-puppet: running config-puppet with frequency once-per-instance
2019-03-29 11:25:21,141 - util.py[DEBUG]: Writing to /var/lib/cloud/instances/i-07596f108f8d78958/sem/config_puppet - wb: [644] 25 bytes
2019-03-29 11:25:21,141 - helpers.py[DEBUG]: Running config-puppet using lock (<FileLock using file '/var/lib/cloud/instances/i-07596f108f8d78958/sem/config_puppet'>)
2019-03-29 11:25:21,141 - cc_puppet.py[DEBUG]: Skipping module named puppet, no 'puppet' configuration found
2019-03-29 11:25:21,141 - handlers.py[DEBUG]: finish: modules-final/config-puppet: SUCCESS: config-puppet ran successfully
2019-03-29 11:25:21,141 - stages.py[DEBUG]: Running module chef (<module 'cloudinit.config.cc_chef' from '/usr/lib/python3/dist-packages/cloudinit/config/cc_chef.py'>) with frequency once-per-instance
2019-03-29 11:25:21,141 - handlers.py[DEBUG]: start: modules-final/config-chef: running config-chef with frequency once-per-instance
2019-03-29 11:25:21,141 - util.py[DEBUG]: Writing to /var/lib/cloud/instances/i-07596f108f8d78958/sem/config_chef - wb: [644] 25 bytes
2019-03-29 11:25:21,142 - helpers.py[DEBUG]: Running config-chef using lock (<FileLock using file '/var/lib/cloud/instances/i-07596f108f8d78958/sem/config_chef'>)
2019-03-29 11:25:21,142 - cc_chef.py[DEBUG]: Skipping module named chef, no 'chef' key in configuration
2019-03-29 11:25:21,142 - handlers.py[DEBUG]: finish: modules-final/config-chef: SUCCESS: config-chef ran successfully
2019-03-29 11:25:21,142 - stages.py[DEBUG]: Running module mcollective (<module 'cloudinit.config.cc_mcollective' from '/usr/lib/python3/dist-packages/cloudinit/config/cc_mcollective.py'>) with frequency once-per-instance
2019-03-29 11:25:21,142 - handlers.py[DEBUG]: start: modules-final/config-mcollective: running config-mcollective with frequency once-per-instance
2019-03-29 11:25:21,142 - util.py[DEBUG]: Writing to /var/lib/cloud/instances/i-07596f108f8d78958/sem/config_mcollective - wb: [644] 25 bytes
2019-03-29 11:25:21,142 - helpers.py[DEBUG]: Running config-mcollective using lock (<FileLock using file '/var/lib/cloud/instances/i-07596f108f8d78958/sem/config_mcollective'>)
2019-03-29 11:25:21,143 - cc_mcollective.py[DEBUG]: Skipping module named mcollective, no 'mcollective' key in configuration
2019-03-29 11:25:21,143 - handlers.py[DEBUG]: finish: modules-final/config-mcollective: SUCCESS: config-mcollective ran successfully
2019-03-29 11:25:21,143 - stages.py[DEBUG]: Running module salt-minion (<module 'cloudinit.config.cc_salt_minion' from '/usr/lib/python3/dist-packages/cloudinit/config/cc_salt_minion.py'>) with frequency once-per-instance
2019-03-29 11:25:21,143 - handlers.py[DEBUG]: start: modules-final/config-salt-minion: running config-salt-minion with frequency once-per-instance
2019-03-29 11:25:21,143 - util.py[DEBUG]: Writing to /var/lib/cloud/instances/i-07596f108f8d78958/sem/config_salt_minion - wb: [644] 25 bytes
2019-03-29 11:25:21,143 - helpers.py[DEBUG]: Running config-salt-minion using lock (<FileLock using file '/var/lib/cloud/instances/i-07596f108f8d78958/sem/config_salt_minion'>)
2019-03-29 11:25:21,143 - cc_salt_minion.py[DEBUG]: Skipping module named salt-minion, no 'salt_minion' key in configuration
2019-03-29 11:25:21,143 - handlers.py[DEBUG]: finish: modules-final/config-salt-minion: SUCCESS: config-salt-minion ran successfully
2019-03-29 11:25:21,143 - stages.py[DEBUG]: Running module rightscale_userdata (<module 'cloudinit.config.cc_rightscale_userdata' from '/usr/lib/python3/dist-packages/cloudinit/config/cc_rightscale_userdata.py'>) with frequency once-per-instance
2019-03-29 11:25:21,144 - handlers.py[DEBUG]: start: modules-final/config-rightscale_userdata: running config-rightscale_userdata with frequency once-per-instance
2019-03-29 11:25:21,144 - util.py[DEBUG]: Writing to /var/lib/cloud/instances/i-07596f108f8d78958/sem/config_rightscale_userdata - wb: [644] 25 bytes
2019-03-29 11:25:21,144 - helpers.py[DEBUG]: Running config-rightscale_userdata using lock (<FileLock using file '/var/lib/cloud/instances/i-07596f108f8d78958/sem/config_rightscale_userdata'>)
2019-03-29 11:25:21,144 - cc_rightscale_userdata.py[DEBUG]: Failed to get raw userdata in module rightscale_userdata
2019-03-29 11:25:21,144 - handlers.py[DEBUG]: finish: modules-final/config-rightscale_userdata: SUCCESS: config-rightscale_userdata ran successfully
2019-03-29 11:25:21,144 - stages.py[DEBUG]: Running module scripts-vendor (<module 'cloudinit.config.cc_scripts_vendor' from '/usr/lib/python3/dist-packages/cloudinit/config/cc_scripts_vendor.py'>) with frequency once-per-instance
2019-03-29 11:25:21,145 - handlers.py[DEBUG]: start: modules-final/config-scripts-vendor: running config-scripts-vendor with frequency once-per-instance
2019-03-29 11:25:21,145 - util.py[DEBUG]: Writing to /var/lib/cloud/instances/i-07596f108f8d78958/sem/config_scripts_vendor - wb: [644] 24 bytes
2019-03-29 11:25:21,145 - helpers.py[DEBUG]: Running config-scripts-vendor using lock (<FileLock using file '/var/lib/cloud/instances/i-07596f108f8d78958/sem/config_scripts_vendor'>)
2019-03-29 11:25:21,145 - handlers.py[DEBUG]: finish: modules-final/config-scripts-vendor: SUCCESS: config-scripts-vendor ran successfully
2019-03-29 11:25:21,145 - stages.py[DEBUG]: Running module scripts-per-once (<module 'cloudinit.config.cc_scripts_per_once' from '/usr/lib/python3/dist-packages/cloudinit/config/cc_scripts_per_once.py'>) with frequency once
2019-03-29 11:25:21,145 - handlers.py[DEBUG]: start: modules-final/config-scripts-per-once: running config-scripts-per-once with frequency once
2019-03-29 11:25:21,145 - util.py[DEBUG]: Writing to /var/lib/cloud/sem/config_scripts_per_once.once - wb: [644] 25 bytes
2019-03-29 11:25:21,146 - helpers.py[DEBUG]: Running config-scripts-per-once using lock (<FileLock using file '/var/lib/cloud/sem/config_scripts_per_once.once'>)
2019-03-29 11:25:21,146 - handlers.py[DEBUG]: finish: modules-final/config-scripts-per-once: SUCCESS: config-scripts-per-once ran successfully
2019-03-29 11:25:21,146 - stages.py[DEBUG]: Running module scripts-per-boot (<module 'cloudinit.config.cc_scripts_per_boot' from '/usr/lib/python3/dist-packages/cloudinit/config/cc_scripts_per_boot.py'>) with frequency always
2019-03-29 11:25:21,146 - handlers.py[DEBUG]: start: modules-final/config-scripts-per-boot: running config-scripts-per-boot with frequency always
2019-03-29 11:25:21,146 - helpers.py[DEBUG]: Running config-scripts-per-boot using lock (<cloudinit.helpers.DummyLock object at 0x7f0e190fa860>)
2019-03-29 11:25:21,146 - handlers.py[DEBUG]: finish: modules-final/config-scripts-per-boot: SUCCESS: config-scripts-per-boot ran successfully
2019-03-29 11:25:21,146 - stages.py[DEBUG]: Running module scripts-per-instance (<module 'cloudinit.config.cc_scripts_per_instance' from '/usr/lib/python3/dist-packages/cloudinit/config/cc_scripts_per_instance.py'>) with frequency once-per-instance
2019-03-29 11:25:21,146 - handlers.py[DEBUG]: start: modules-final/config-scripts-per-instance: running config-scripts-per-instance with frequency once-per-instance
2019-03-29 11:25:21,147 - util.py[DEBUG]: Writing to /var/lib/cloud/instances/i-07596f108f8d78958/sem/config_scripts_per_instance - wb: [644] 25 bytes
2019-03-29 11:25:21,147 - helpers.py[DEBUG]: Running config-scripts-per-instance using lock (<FileLock using file '/var/lib/cloud/instances/i-07596f108f8d78958/sem/config_scripts_per_instance'>)
2019-03-29 11:25:21,147 - handlers.py[DEBUG]: finish: modules-final/config-scripts-per-instance: SUCCESS: config-scripts-per-instance ran successfully
2019-03-29 11:25:21,147 - stages.py[DEBUG]: Running module scripts-user (<module 'cloudinit.config.cc_scripts_user' from '/usr/lib/python3/dist-packages/cloudinit/config/cc_scripts_user.py'>) with frequency once-per-instance
2019-03-29 11:25:21,147 - handlers.py[DEBUG]: start: modules-final/config-scripts-user: running config-scripts-user with frequency once-per-instance
2019-03-29 11:25:21,147 - util.py[DEBUG]: Writing to /var/lib/cloud/instances/i-07596f108f8d78958/sem/config_scripts_user - wb: [644] 25 bytes
2019-03-29 11:25:21,148 - helpers.py[DEBUG]: Running config-scripts-user using lock (<FileLock using file '/var/lib/cloud/instances/i-07596f108f8d78958/sem/config_scripts_user'>)
2019-03-29 11:25:21,148 - handlers.py[DEBUG]: finish: modules-final/config-scripts-user: SUCCESS: config-scripts-user ran successfully
2019-03-29 11:25:21,148 - stages.py[DEBUG]: Running module ssh-authkey-fingerprints (<module 'cloudinit.config.cc_ssh_authkey_fingerprints' from '/usr/lib/python3/dist-packages/cloudinit/config/cc_ssh_authkey_fingerprints.py'>) with frequency once-per-instance
2019-03-29 11:25:21,148 - handlers.py[DEBUG]: start: modules-final/config-ssh-authkey-fingerprints: running config-ssh-authkey-fingerprints with frequency once-per-instance
2019-03-29 11:25:21,148 - util.py[DEBUG]: Writing to /var/lib/cloud/instances/i-07596f108f8d78958/sem/config_ssh_authkey_fingerprints - wb: [644] 25 bytes
2019-03-29 11:25:21,149 - helpers.py[DEBUG]: Running config-ssh-authkey-fingerprints using lock (<FileLock using file '/var/lib/cloud/instances/i-07596f108f8d78958/sem/config_ssh_authkey_fingerprints'>)
2019-03-29 11:25:21,149 - util.py[DEBUG]: Reading from /etc/ssh/sshd_config (quiet=False)
2019-03-29 11:25:21,149 - util.py[DEBUG]: Read 2540 bytes from /etc/ssh/sshd_config
2019-03-29 11:25:21,149 - util.py[DEBUG]: Reading from /home/ubuntu/.ssh/authorized_keys (quiet=False)
2019-03-29 11:25:21,149 - util.py[DEBUG]: Read 448 bytes from /home/ubuntu/.ssh/authorized_keys
2019-03-29 11:25:21,180 - handlers.py[DEBUG]: finish: modules-final/config-ssh-authkey-fingerprints: SUCCESS: config-ssh-authkey-fingerprints ran successfully
2019-03-29 11:25:21,180 - stages.py[DEBUG]: Running module keys-to-console (<module 'cloudinit.config.cc_keys_to_console' from '/usr/lib/python3/dist-packages/cloudinit/config/cc_keys_to_console.py'>) with frequency once-per-instance
2019-03-29 11:25:21,180 - handlers.py[DEBUG]: start: modules-final/config-keys-to-console: running config-keys-to-console with frequency once-per-instance
2019-03-29 11:25:21,180 - util.py[DEBUG]: Writing to /var/lib/cloud/instances/i-07596f108f8d78958/sem/config_keys_to_console - wb: [644] 25 bytes
2019-03-29 11:25:21,181 - helpers.py[DEBUG]: Running config-keys-to-console using lock (<FileLock using file '/var/lib/cloud/instances/i-07596f108f8d78958/sem/config_keys_to_console'>)
2019-03-29 11:25:21,181 - util.py[DEBUG]: Running command ['/usr/lib/cloud-init/write-ssh-key-fingerprints', '', 'ssh-dss'] with allowed return codes [0] (shell=False, capture=True)
2019-03-29 11:25:21,209 - handlers.py[DEBUG]: finish: modules-final/config-keys-to-console: SUCCESS: config-keys-to-console ran successfully
2019-03-29 11:25:21,210 - stages.py[DEBUG]: Running module phone-home (<module 'cloudinit.config.cc_phone_home' from '/usr/lib/python3/dist-packages/cloudinit/config/cc_phone_home.py'>) with frequency once-per-instance
2019-03-29 11:25:21,210 - handlers.py[DEBUG]: start: modules-final/config-phone-home: running config-phone-home with frequency once-per-instance
2019-03-29 11:25:21,210 - util.py[DEBUG]: Writing to /var/lib/cloud/instances/i-07596f108f8d78958/sem/config_phone_home - wb: [644] 25 bytes
2019-03-29 11:25:21,211 - helpers.py[DEBUG]: Running config-phone-home using lock (<FileLock using file '/var/lib/cloud/instances/i-07596f108f8d78958/sem/config_phone_home'>)
2019-03-29 11:25:21,211 - cc_phone_home.py[DEBUG]: Skipping module named phone-home, no 'phone_home' configuration found
2019-03-29 11:25:21,211 - handlers.py[DEBUG]: finish: modules-final/config-phone-home: SUCCESS: config-phone-home ran successfully
2019-03-29 11:25:21,211 - stages.py[DEBUG]: Running module final-message (<module 'cloudinit.config.cc_final_message' from '/usr/lib/python3/dist-packages/cloudinit/config/cc_final_message.py'>) with frequency always
2019-03-29 11:25:21,211 - handlers.py[DEBUG]: start: modules-final/config-final-message: running config-final-message with frequency always
2019-03-29 11:25:21,211 - helpers.py[DEBUG]: Running config-final-message using lock (<cloudinit.helpers.DummyLock object at 0x7f0e18969ef0>)
2019-03-29 11:25:21,211 - util.py[DEBUG]: Reading from /proc/uptime (quiet=False)
2019-03-29 11:25:21,211 - util.py[DEBUG]: Read 13 bytes from /proc/uptime
2019-03-29 11:25:21,214 - util.py[DEBUG]: Cloud-init v. 18.3-9-g2e62cb8a-0ubuntu1~16.04.2 finished at Fri, 29 Mar 2019 11:25:21 +0000. Datasource DataSourceEc2Local.  Up 24.80 seconds
2019-03-29 11:25:21,214 - util.py[DEBUG]: Writing to /var/lib/cloud/instance/boot-finished - wb: [644] 79 bytes
2019-03-29 11:25:21,215 - handlers.py[DEBUG]: finish: modules-final/config-final-message: SUCCESS: config-final-message ran successfully
2019-03-29 11:25:21,215 - stages.py[DEBUG]: Running module power-state-change (<module 'cloudinit.config.cc_power_state_change' from '/usr/lib/python3/dist-packages/cloudinit/config/cc_power_state_change.py'>) with frequency once-per-instance
2019-03-29 11:25:21,215 - handlers.py[DEBUG]: start: modules-final/config-power-state-change: running config-power-state-change with frequency once-per-instance
2019-03-29 11:25:21,215 - util.py[DEBUG]: Writing to /var/lib/cloud/instances/i-07596f108f8d78958/sem/config_power_state_change - wb: [644] 24 bytes
2019-03-29 11:25:21,215 - helpers.py[DEBUG]: Running config-power-state-change using lock (<FileLock using file '/var/lib/cloud/instances/i-07596f108f8d78958/sem/config_power_state_change'>)
2019-03-29 11:25:21,215 - cc_power_state_change.py[DEBUG]: no power_state provided. doing nothing
2019-03-29 11:25:21,215 - handlers.py[DEBUG]: finish: modules-final/config-power-state-change: SUCCESS: config-power-state-change ran successfully
2019-03-29 11:25:21,216 - main.py[DEBUG]: Ran 20 modules with 0 failures
2019-03-29 11:25:21,216 - util.py[DEBUG]: Creating symbolic link from '/run/cloud-init/result.json' => '../../var/lib/cloud/data/result.json'
2019-03-29 11:25:21,216 - util.py[DEBUG]: Reading from /proc/uptime (quiet=False)
2019-03-29 11:25:21,216 - util.py[DEBUG]: Read 13 bytes from /proc/uptime
2019-03-29 11:25:21,216 - util.py[DEBUG]: cloud-init mode 'modules' took 0.164 seconds (0.16)
2019-03-29 11:25:21,217 - handlers.py[DEBUG]: finish: modules-final: SUCCESS: running modules for final
