2019-03-29 11:25:02,271 - util.py[DEBUG]: Cloud-init v. 18.3-9-g2e62cb8a-0ubuntu1~16.04.2 running 'init-local' at Fri, 29 Mar 2019 11:25:02 +0000. Up 7.74 seconds.
2019-03-29 11:25:02,271 - main.py[DEBUG]: No kernel command line url found.
2019-03-29 11:25:02,271 - main.py[DEBUG]: Closing stdin.
2019-03-29 11:25:02,274 - util.py[DEBUG]: Writing to /var/log/cloud-init.log - ab: [644] 0 bytes
2019-03-29 11:25:02,274 - util.py[DEBUG]: Changing the ownership of /var/log/cloud-init.log to 104:4
2019-03-29 11:25:02,275 - util.py[DEBUG]: Attempting to remove /var/lib/cloud/instance/boot-finished
2019-03-29 11:25:02,275 - util.py[DEBUG]: Attempting to remove /var/lib/cloud/data/no-net
2019-03-29 11:25:02,275 - handlers.py[DEBUG]: start: init-local/check-cache: attempting to read from cache [check]
2019-03-29 11:25:02,275 - util.py[DEBUG]: Reading from /var/lib/cloud/instance/obj.pkl (quiet=False)
2019-03-29 11:25:02,275 - stages.py[DEBUG]: no cache found
2019-03-29 11:25:02,275 - handlers.py[DEBUG]: finish: init-local/check-cache: SUCCESS: no cache found
2019-03-29 11:25:02,275 - util.py[DEBUG]: Attempting to remove /var/lib/cloud/instance
2019-03-29 11:25:02,277 - stages.py[DEBUG]: Using distro class <class 'cloudinit.distros.ubuntu.Distro'>
2019-03-29 11:25:02,278 - __init__.py[DEBUG]: Looking for data source in: ['NoCloud', 'ConfigDrive', 'OpenNebula', 'DigitalOcean', 'Azure', 'AltCloud', 'OVF', 'MAAS', 'GCE', 'OpenStack', 'CloudSigma', 'SmartOS', 'Bigstep', 'Scaleway', 'AliYun', 'Ec2', 'CloudStack', 'None'], via packages ['', 'cloudinit.sources'] that matches dependencies ['FILESYSTEM']
2019-03-29 11:25:02,319 - util.py[DEBUG]: Reading from /etc/os-release (quiet=False)
2019-03-29 11:25:02,319 - util.py[DEBUG]: Read 298 bytes from /etc/os-release
2019-03-29 11:25:02,359 - __init__.py[DEBUG]: Searching for local data source in: ['DataSourceNoCloud', 'DataSourceConfigDrive', 'DataSourceOpenNebula', 'DataSourceDigitalOcean', 'DataSourceAzure', 'DataSourceOVF', 'DataSourceOpenStackLocal', 'DataSourceCloudSigma', 'DataSourceSmartOS', 'DataSourceEc2Local']
2019-03-29 11:25:02,359 - handlers.py[DEBUG]: start: init-local/search-NoCloud: searching for local data from DataSourceNoCloud
2019-03-29 11:25:02,359 - __init__.py[DEBUG]: Seeing if we can get any data from <class 'cloudinit.sources.DataSourceNoCloud.DataSourceNoCloud'>
2019-03-29 11:25:02,359 - __init__.py[DEBUG]: Update datasource metadata and network config due to events: New instance first boot
2019-03-29 11:25:02,359 - util.py[DEBUG]: Running command ['systemd-detect-virt', '--quiet', '--container'] with allowed return codes [0] (shell=False, capture=True)
2019-03-29 11:25:02,361 - util.py[DEBUG]: Running command ['running-in-container'] with allowed return codes [0] (shell=False, capture=True)
2019-03-29 11:25:02,363 - util.py[DEBUG]: Running command ['lxc-is-container'] with allowed return codes [0] (shell=False, capture=True)
2019-03-29 11:25:02,365 - util.py[DEBUG]: Reading from /proc/1/environ (quiet=False)
2019-03-29 11:25:02,365 - util.py[DEBUG]: Read 150 bytes from /proc/1/environ
2019-03-29 11:25:02,365 - util.py[DEBUG]: Reading from /proc/self/status (quiet=False)
2019-03-29 11:25:02,365 - util.py[DEBUG]: Read 966 bytes from /proc/self/status
2019-03-29 11:25:02,365 - util.py[DEBUG]: querying dmi data /sys/class/dmi/id/product_serial
2019-03-29 11:25:02,365 - util.py[DEBUG]: Reading from /sys/class/dmi/id/product_serial (quiet=False)
2019-03-29 11:25:02,366 - util.py[DEBUG]: Read 37 bytes from /sys/class/dmi/id/product_serial
2019-03-29 11:25:02,366 - util.py[DEBUG]: dmi data /sys/class/dmi/id/product_serial returned ec260091-9413-bbdc-08bf-e2a098ca0faa
2019-03-29 11:25:02,366 - util.py[DEBUG]: Reading from /var/lib/cloud/seed/nocloud/user-data (quiet=False)
2019-03-29 11:25:02,366 - util.py[DEBUG]: Reading from /var/lib/cloud/seed/nocloud/meta-data (quiet=False)
2019-03-29 11:25:02,366 - util.py[DEBUG]: Reading from /var/lib/cloud/seed/nocloud/vendor-data (quiet=False)
2019-03-29 11:25:02,366 - util.py[DEBUG]: Reading from /var/lib/cloud/seed/nocloud/network-config (quiet=False)
2019-03-29 11:25:02,366 - util.py[DEBUG]: Reading from /var/lib/cloud/seed/nocloud-net/user-data (quiet=False)
2019-03-29 11:25:02,366 - util.py[DEBUG]: Reading from /var/lib/cloud/seed/nocloud-net/meta-data (quiet=False)
2019-03-29 11:25:02,366 - util.py[DEBUG]: Reading from /var/lib/cloud/seed/nocloud-net/vendor-data (quiet=False)
2019-03-29 11:25:02,366 - util.py[DEBUG]: Reading from /var/lib/cloud/seed/nocloud-net/network-config (quiet=False)
2019-03-29 11:25:02,366 - util.py[DEBUG]: Running command ['blkid', '-odevice', '/dev/sr0'] with allowed return codes [0, 2] (shell=False, capture=True)
2019-03-29 11:25:02,368 - util.py[DEBUG]: Running command ['blkid', '-odevice', '/dev/sr1'] with allowed return codes [0, 2] (shell=False, capture=True)
2019-03-29 11:25:02,370 - util.py[DEBUG]: Running command ['blkid', '-tTYPE=vfat', '-odevice'] with allowed return codes [0, 2] (shell=False, capture=True)
2019-03-29 11:25:02,384 - util.py[DEBUG]: Running command ['blkid', '-tTYPE=iso9660', '-odevice'] with allowed return codes [0, 2] (shell=False, capture=True)
2019-03-29 11:25:02,397 - util.py[DEBUG]: Running command ['blkid', '-tLABEL=cidata', '-odevice'] with allowed return codes [0, 2] (shell=False, capture=True)
2019-03-29 11:25:02,408 - handlers.py[DEBUG]: finish: init-local/search-NoCloud: SUCCESS: no local data found from DataSourceNoCloud
2019-03-29 11:25:02,409 - handlers.py[DEBUG]: start: init-local/search-ConfigDrive: searching for local data from DataSourceConfigDrive
2019-03-29 11:25:02,409 - __init__.py[DEBUG]: Seeing if we can get any data from <class 'cloudinit.sources.DataSourceConfigDrive.DataSourceConfigDrive'>
2019-03-29 11:25:02,409 - __init__.py[DEBUG]: Update datasource metadata and network config due to events: New instance first boot
2019-03-29 11:25:02,409 - util.py[DEBUG]: Running command ['blkid', '-odevice', '/dev/sr0'] with allowed return codes [0, 2] (shell=False, capture=True)
2019-03-29 11:25:02,410 - util.py[DEBUG]: Running command ['blkid', '-odevice', '/dev/sr1'] with allowed return codes [0, 2] (shell=False, capture=True)
2019-03-29 11:25:02,412 - util.py[DEBUG]: Running command ['blkid', '-odevice', '/dev/cd0'] with allowed return codes [0, 2] (shell=False, capture=True)
2019-03-29 11:25:02,413 - util.py[DEBUG]: Running command ['blkid', '-odevice', '/dev/cd1'] with allowed return codes [0, 2] (shell=False, capture=True)
2019-03-29 11:25:02,415 - util.py[DEBUG]: Running command ['blkid', '-tTYPE=vfat', '-odevice'] with allowed return codes [0, 2] (shell=False, capture=True)
2019-03-29 11:25:02,427 - util.py[DEBUG]: Running command ['blkid', '-tTYPE=iso9660', '-odevice'] with allowed return codes [0, 2] (shell=False, capture=True)
2019-03-29 11:25:02,439 - util.py[DEBUG]: Running command ['blkid', '-tLABEL=config-2', '-odevice'] with allowed return codes [0, 2] (shell=False, capture=True)
2019-03-29 11:25:02,450 - util.py[DEBUG]: Running command ['blkid', '-tLABEL=CONFIG-2', '-odevice'] with allowed return codes [0, 2] (shell=False, capture=True)
2019-03-29 11:25:02,462 - DataSourceConfigDrive.py[DEBUG]: devices=[] dslist=['NoCloud', 'ConfigDrive', 'OpenNebula', 'DigitalOcean', 'Azure', 'AltCloud', 'OVF', 'MAAS', 'GCE', 'OpenStack', 'CloudSigma', 'SmartOS', 'Bigstep', 'Scaleway', 'AliYun', 'Ec2', 'CloudStack', 'None']
2019-03-29 11:25:02,462 - handlers.py[DEBUG]: finish: init-local/search-ConfigDrive: SUCCESS: no local data found from DataSourceConfigDrive
2019-03-29 11:25:02,462 - handlers.py[DEBUG]: start: init-local/search-OpenNebula: searching for local data from DataSourceOpenNebula
2019-03-29 11:25:02,462 - __init__.py[DEBUG]: Seeing if we can get any data from <class 'cloudinit.sources.DataSourceOpenNebula.DataSourceOpenNebula'>
2019-03-29 11:25:02,462 - __init__.py[DEBUG]: Update datasource metadata and network config due to events: New instance first boot
2019-03-29 11:25:02,463 - util.py[DEBUG]: Running command ['blkid', '-tLABEL=CONTEXT', '-odevice'] with allowed return codes [0, 2] (shell=False, capture=True)
2019-03-29 11:25:02,474 - util.py[DEBUG]: Running command ['blkid', '-tLABEL=CDROM', '-odevice'] with allowed return codes [0, 2] (shell=False, capture=True)
2019-03-29 11:25:02,486 - util.py[DEBUG]: Running command ['blkid', '-tTYPE=iso9660', '-odevice'] with allowed return codes [0, 2] (shell=False, capture=True)
2019-03-29 11:25:02,498 - handlers.py[DEBUG]: finish: init-local/search-OpenNebula: SUCCESS: no local data found from DataSourceOpenNebula
2019-03-29 11:25:02,498 - handlers.py[DEBUG]: start: init-local/search-DigitalOcean: searching for local data from DataSourceDigitalOcean
2019-03-29 11:25:02,498 - __init__.py[DEBUG]: Seeing if we can get any data from <class 'cloudinit.sources.DataSourceDigitalOcean.DataSourceDigitalOcean'>
2019-03-29 11:25:02,498 - __init__.py[DEBUG]: Update datasource metadata and network config due to events: New instance first boot
2019-03-29 11:25:02,498 - util.py[DEBUG]: Running command ['systemd-detect-virt', '--quiet', '--container'] with allowed return codes [0] (shell=False, capture=True)
2019-03-29 11:25:02,500 - util.py[DEBUG]: Running command ['running-in-container'] with allowed return codes [0] (shell=False, capture=True)
2019-03-29 11:25:02,501 - util.py[DEBUG]: Running command ['lxc-is-container'] with allowed return codes [0] (shell=False, capture=True)
2019-03-29 11:25:02,503 - util.py[DEBUG]: Reading from /proc/1/environ (quiet=False)
2019-03-29 11:25:02,503 - util.py[DEBUG]: Read 150 bytes from /proc/1/environ
2019-03-29 11:25:02,503 - util.py[DEBUG]: Reading from /proc/self/status (quiet=False)
2019-03-29 11:25:02,503 - util.py[DEBUG]: Read 966 bytes from /proc/self/status
2019-03-29 11:25:02,503 - util.py[DEBUG]: querying dmi data /sys/class/dmi/id/sys_vendor
2019-03-29 11:25:02,503 - util.py[DEBUG]: Reading from /sys/class/dmi/id/sys_vendor (quiet=False)
2019-03-29 11:25:02,503 - util.py[DEBUG]: Read 4 bytes from /sys/class/dmi/id/sys_vendor
2019-03-29 11:25:02,503 - util.py[DEBUG]: dmi data /sys/class/dmi/id/sys_vendor returned Xen
2019-03-29 11:25:02,504 - handlers.py[DEBUG]: finish: init-local/search-DigitalOcean: SUCCESS: no local data found from DataSourceDigitalOcean
2019-03-29 11:25:02,504 - handlers.py[DEBUG]: start: init-local/search-Azure: searching for local data from DataSourceAzure
2019-03-29 11:25:02,504 - __init__.py[DEBUG]: Seeing if we can get any data from <class 'cloudinit.sources.DataSourceAzure.DataSourceAzure'>
2019-03-29 11:25:02,504 - __init__.py[DEBUG]: Update datasource metadata and network config due to events: New instance first boot
2019-03-29 11:25:02,504 - util.py[DEBUG]: Running command ['systemd-detect-virt', '--quiet', '--container'] with allowed return codes [0] (shell=False, capture=True)
2019-03-29 11:25:02,506 - util.py[DEBUG]: Running command ['running-in-container'] with allowed return codes [0] (shell=False, capture=True)
2019-03-29 11:25:02,507 - util.py[DEBUG]: Running command ['lxc-is-container'] with allowed return codes [0] (shell=False, capture=True)
2019-03-29 11:25:02,509 - util.py[DEBUG]: Reading from /proc/1/environ (quiet=False)
2019-03-29 11:25:02,510 - util.py[DEBUG]: Read 150 bytes from /proc/1/environ
2019-03-29 11:25:02,510 - util.py[DEBUG]: Reading from /proc/self/status (quiet=False)
2019-03-29 11:25:02,510 - util.py[DEBUG]: Read 966 bytes from /proc/self/status
2019-03-29 11:25:02,510 - util.py[DEBUG]: querying dmi data /sys/class/dmi/id/chassis_asset_tag
2019-03-29 11:25:02,510 - util.py[DEBUG]: Reading from /sys/class/dmi/id/chassis_asset_tag (quiet=False)
2019-03-29 11:25:02,510 - util.py[DEBUG]: Read 1 bytes from /sys/class/dmi/id/chassis_asset_tag
2019-03-29 11:25:02,510 - util.py[DEBUG]: dmi data /sys/class/dmi/id/chassis_asset_tag returned 
2019-03-29 11:25:02,510 - DataSourceAzure.py[DEBUG]: Non-Azure DMI asset tag '' discovered.
2019-03-29 11:25:02,510 - handlers.py[DEBUG]: finish: init-local/search-Azure: SUCCESS: no local data found from DataSourceAzure
2019-03-29 11:25:02,510 - handlers.py[DEBUG]: start: init-local/search-OVF: searching for local data from DataSourceOVF
2019-03-29 11:25:02,510 - __init__.py[DEBUG]: Seeing if we can get any data from <class 'cloudinit.sources.DataSourceOVF.DataSourceOVF'>
2019-03-29 11:25:02,510 - __init__.py[DEBUG]: Update datasource metadata and network config due to events: New instance first boot
2019-03-29 11:25:02,511 - util.py[DEBUG]: Running command ['systemd-detect-virt', '--quiet', '--container'] with allowed return codes [0] (shell=False, capture=True)
2019-03-29 11:25:02,512 - util.py[DEBUG]: Running command ['running-in-container'] with allowed return codes [0] (shell=False, capture=True)
2019-03-29 11:25:02,514 - util.py[DEBUG]: Running command ['lxc-is-container'] with allowed return codes [0] (shell=False, capture=True)
2019-03-29 11:25:02,516 - util.py[DEBUG]: Reading from /proc/1/environ (quiet=False)
2019-03-29 11:25:02,516 - util.py[DEBUG]: Read 150 bytes from /proc/1/environ
2019-03-29 11:25:02,516 - util.py[DEBUG]: Reading from /proc/self/status (quiet=False)
2019-03-29 11:25:02,516 - util.py[DEBUG]: Read 966 bytes from /proc/self/status
2019-03-29 11:25:02,516 - util.py[DEBUG]: querying dmi data /sys/class/dmi/id/product_name
2019-03-29 11:25:02,516 - util.py[DEBUG]: Reading from /sys/class/dmi/id/product_name (quiet=False)
2019-03-29 11:25:02,517 - util.py[DEBUG]: Read 9 bytes from /sys/class/dmi/id/product_name
2019-03-29 11:25:02,517 - util.py[DEBUG]: dmi data /sys/class/dmi/id/product_name returned HVM domU
2019-03-29 11:25:02,517 - util.py[DEBUG]: Reading from /proc/mounts (quiet=False)
2019-03-29 11:25:02,517 - util.py[DEBUG]: Read 1991 bytes from /proc/mounts
2019-03-29 11:25:02,517 - util.py[DEBUG]: Fetched {'tmpfs': {'fstype': 'tmpfs', 'mountpoint': '/sys/fs/cgroup', 'opts': 'ro,nosuid,nodev,noexec,mode=755'}, 'systemd-1': {'fstype': 'autofs', 'mountpoint': '/proc/sys/fs/binfmt_misc', 'opts': 'rw,relatime,fd=36,pgrp=1,timeout=0,minproto=5,maxproto=5,direct'}, 'debugfs': {'fstype': 'debugfs', 'mountpoint': '/sys/kernel/debug', 'opts': 'rw,relatime'}, 'udev': {'fstype': 'devtmpfs', 'mountpoint': '/dev', 'opts': 'rw,nosuid,relatime,size=30907648k,nr_inodes=7726912,mode=755'}, 'sysfs': {'fstype': 'sysfs', 'mountpoint': '/sys', 'opts': 'rw,nosuid,nodev,noexec,relatime'}, 'devpts': {'fstype': 'devpts', 'mountpoint': '/dev/pts', 'opts': 'rw,nosuid,noexec,relatime,gid=5,mode=620,ptmxmode=000'}, '/dev/xvda1': {'fstype': 'ext4', 'mountpoint': '/', 'opts': 'rw,relatime,discard,data=ordered'}, 'cgroup': {'fstype': 'cgroup', 'mountpoint': '/sys/fs/cgroup/devices', 'opts': 'rw,nosuid,nodev,noexec,relatime,devices'}, 'hugetlbfs': {'fstype': 'hugetlbfs', 'mountpoint': '/dev/hugepages', 'opts': 'rw,relatime'}, 'mqueue': {'fstype': 'mqueue', 'mountpoint': '/dev/mqueue', 'opts': 'rw,relatime'}, 'pstore': {'fstype': 'pstore', 'mountpoint': '/sys/fs/pstore', 'opts': 'rw,nosuid,nodev,noexec,relatime'}, 'securityfs': {'fstype': 'securityfs', 'mountpoint': '/sys/kernel/security', 'opts': 'rw,nosuid,nodev,noexec,relatime'}, 'proc': {'fstype': 'proc', 'mountpoint': '/proc', 'opts': 'rw,nosuid,nodev,noexec,relatime'}, 'fusectl': {'fstype': 'fusectl', 'mountpoint': '/sys/fs/fuse/connections', 'opts': 'rw,relatime'}} mounts from proc
2019-03-29 11:25:02,517 - util.py[DEBUG]: Running command ['blkid', '-tTYPE=iso9660', '-odevice'] with allowed return codes [0, 2] (shell=False, capture=True)
2019-03-29 11:25:02,529 - handlers.py[DEBUG]: finish: init-local/search-OVF: SUCCESS: no local data found from DataSourceOVF
2019-03-29 11:25:02,529 - handlers.py[DEBUG]: start: init-local/search-OpenStackLocal: searching for local data from DataSourceOpenStackLocal
2019-03-29 11:25:02,529 - __init__.py[DEBUG]: Seeing if we can get any data from <class 'cloudinit.sources.DataSourceOpenStack.DataSourceOpenStackLocal'>
2019-03-29 11:25:02,529 - __init__.py[DEBUG]: Update datasource metadata and network config due to events: New instance first boot
2019-03-29 11:25:02,529 - util.py[DEBUG]: Running command ['systemd-detect-virt', '--quiet', '--container'] with allowed return codes [0] (shell=False, capture=True)
2019-03-29 11:25:02,531 - util.py[DEBUG]: Running command ['running-in-container'] with allowed return codes [0] (shell=False, capture=True)
2019-03-29 11:25:02,533 - util.py[DEBUG]: Running command ['lxc-is-container'] with allowed return codes [0] (shell=False, capture=True)
2019-03-29 11:25:02,534 - util.py[DEBUG]: Reading from /proc/1/environ (quiet=False)
2019-03-29 11:25:02,535 - util.py[DEBUG]: Read 150 bytes from /proc/1/environ
2019-03-29 11:25:02,535 - util.py[DEBUG]: Reading from /proc/self/status (quiet=False)
2019-03-29 11:25:02,535 - util.py[DEBUG]: Read 966 bytes from /proc/self/status
2019-03-29 11:25:02,535 - util.py[DEBUG]: querying dmi data /sys/class/dmi/id/product_name
2019-03-29 11:25:02,535 - util.py[DEBUG]: Reading from /sys/class/dmi/id/product_name (quiet=False)
2019-03-29 11:25:02,535 - util.py[DEBUG]: Read 9 bytes from /sys/class/dmi/id/product_name
2019-03-29 11:25:02,535 - util.py[DEBUG]: dmi data /sys/class/dmi/id/product_name returned HVM domU
2019-03-29 11:25:02,535 - util.py[DEBUG]: Running command ['systemd-detect-virt', '--quiet', '--container'] with allowed return codes [0] (shell=False, capture=True)
2019-03-29 11:25:02,537 - util.py[DEBUG]: Running command ['running-in-container'] with allowed return codes [0] (shell=False, capture=True)
2019-03-29 11:25:02,538 - util.py[DEBUG]: Running command ['lxc-is-container'] with allowed return codes [0] (shell=False, capture=True)
2019-03-29 11:25:02,541 - util.py[DEBUG]: Reading from /proc/1/environ (quiet=False)
2019-03-29 11:25:02,541 - util.py[DEBUG]: Read 150 bytes from /proc/1/environ
2019-03-29 11:25:02,541 - util.py[DEBUG]: Reading from /proc/self/status (quiet=False)
2019-03-29 11:25:02,541 - util.py[DEBUG]: Read 967 bytes from /proc/self/status
2019-03-29 11:25:02,541 - util.py[DEBUG]: querying dmi data /sys/class/dmi/id/chassis_asset_tag
2019-03-29 11:25:02,541 - util.py[DEBUG]: Reading from /sys/class/dmi/id/chassis_asset_tag (quiet=False)
2019-03-29 11:25:02,541 - util.py[DEBUG]: Read 1 bytes from /sys/class/dmi/id/chassis_asset_tag
2019-03-29 11:25:02,541 - util.py[DEBUG]: dmi data /sys/class/dmi/id/chassis_asset_tag returned 
2019-03-29 11:25:02,541 - util.py[DEBUG]: Reading from /proc/1/environ (quiet=False)
2019-03-29 11:25:02,541 - util.py[DEBUG]: Read 150 bytes from /proc/1/environ
2019-03-29 11:25:02,541 - handlers.py[DEBUG]: finish: init-local/search-OpenStackLocal: SUCCESS: no local data found from DataSourceOpenStackLocal
2019-03-29 11:25:02,542 - handlers.py[DEBUG]: start: init-local/search-CloudSigma: searching for local data from DataSourceCloudSigma
2019-03-29 11:25:02,542 - __init__.py[DEBUG]: Seeing if we can get any data from <class 'cloudinit.sources.DataSourceCloudSigma.DataSourceCloudSigma'>
2019-03-29 11:25:02,542 - __init__.py[DEBUG]: Update datasource metadata and network config due to events: New instance first boot
2019-03-29 11:25:02,542 - DataSourceCloudSigma.py[DEBUG]: determining hypervisor product name via dmi data
2019-03-29 11:25:02,542 - util.py[DEBUG]: Running command ['systemd-detect-virt', '--quiet', '--container'] with allowed return codes [0] (shell=False, capture=True)
2019-03-29 11:25:02,543 - util.py[DEBUG]: Running command ['running-in-container'] with allowed return codes [0] (shell=False, capture=True)
2019-03-29 11:25:02,545 - util.py[DEBUG]: Running command ['lxc-is-container'] with allowed return codes [0] (shell=False, capture=True)
2019-03-29 11:25:02,547 - util.py[DEBUG]: Reading from /proc/1/environ (quiet=False)
2019-03-29 11:25:02,547 - util.py[DEBUG]: Read 150 bytes from /proc/1/environ
2019-03-29 11:25:02,547 - util.py[DEBUG]: Reading from /proc/self/status (quiet=False)
2019-03-29 11:25:02,547 - util.py[DEBUG]: Read 967 bytes from /proc/self/status
2019-03-29 11:25:02,547 - util.py[DEBUG]: querying dmi data /sys/class/dmi/id/product_name
2019-03-29 11:25:02,547 - util.py[DEBUG]: Reading from /sys/class/dmi/id/product_name (quiet=False)
2019-03-29 11:25:02,547 - util.py[DEBUG]: Read 9 bytes from /sys/class/dmi/id/product_name
2019-03-29 11:25:02,547 - util.py[DEBUG]: dmi data /sys/class/dmi/id/product_name returned HVM domU
2019-03-29 11:25:02,548 - DataSourceCloudSigma.py[DEBUG]: detected hypervisor as HVM domU
2019-03-29 11:25:02,548 - handlers.py[DEBUG]: finish: init-local/search-CloudSigma: SUCCESS: no local data found from DataSourceCloudSigma
2019-03-29 11:25:02,548 - handlers.py[DEBUG]: start: init-local/search-SmartOS: searching for local data from DataSourceSmartOS
2019-03-29 11:25:02,548 - __init__.py[DEBUG]: Seeing if we can get any data from <class 'cloudinit.sources.DataSourceSmartOS.DataSourceSmartOS'>
2019-03-29 11:25:02,548 - util.py[DEBUG]: Running command ['systemd-detect-virt', '--quiet', '--container'] with allowed return codes [0] (shell=False, capture=True)
2019-03-29 11:25:02,550 - util.py[DEBUG]: Running command ['running-in-container'] with allowed return codes [0] (shell=False, capture=True)
2019-03-29 11:25:02,551 - util.py[DEBUG]: Running command ['lxc-is-container'] with allowed return codes [0] (shell=False, capture=True)
2019-03-29 11:25:02,553 - util.py[DEBUG]: Reading from /proc/1/environ (quiet=False)
2019-03-29 11:25:02,553 - util.py[DEBUG]: Read 150 bytes from /proc/1/environ
2019-03-29 11:25:02,553 - util.py[DEBUG]: Reading from /proc/self/status (quiet=False)
2019-03-29 11:25:02,553 - util.py[DEBUG]: Read 967 bytes from /proc/self/status
2019-03-29 11:25:02,553 - util.py[DEBUG]: querying dmi data /sys/class/dmi/id/product_name
2019-03-29 11:25:02,553 - util.py[DEBUG]: Reading from /sys/class/dmi/id/product_name (quiet=False)
2019-03-29 11:25:02,553 - util.py[DEBUG]: Read 9 bytes from /sys/class/dmi/id/product_name
2019-03-29 11:25:02,553 - util.py[DEBUG]: dmi data /sys/class/dmi/id/product_name returned HVM domU
2019-03-29 11:25:02,554 - __init__.py[DEBUG]: Update datasource metadata and network config due to events: New instance first boot
2019-03-29 11:25:02,554 - DataSourceSmartOS.py[DEBUG]: Not running on smartos
2019-03-29 11:25:02,554 - handlers.py[DEBUG]: finish: init-local/search-SmartOS: SUCCESS: no local data found from DataSourceSmartOS
2019-03-29 11:25:02,554 - handlers.py[DEBUG]: start: init-local/search-Ec2Local: searching for local data from DataSourceEc2Local
2019-03-29 11:25:02,554 - __init__.py[DEBUG]: Seeing if we can get any data from <class 'cloudinit.sources.DataSourceEc2.DataSourceEc2Local'>
2019-03-29 11:25:02,554 - __init__.py[DEBUG]: Update datasource metadata and network config due to events: New instance first boot
2019-03-29 11:25:02,554 - util.py[DEBUG]: Reading from /sys/hypervisor/uuid (quiet=False)
2019-03-29 11:25:02,554 - util.py[DEBUG]: Read 37 bytes from /sys/hypervisor/uuid
2019-03-29 11:25:02,554 - util.py[DEBUG]: Running command ['systemd-detect-virt', '--quiet', '--container'] with allowed return codes [0] (shell=False, capture=True)
2019-03-29 11:25:02,556 - util.py[DEBUG]: Running command ['running-in-container'] with allowed return codes [0] (shell=False, capture=True)
2019-03-29 11:25:02,557 - util.py[DEBUG]: Running command ['lxc-is-container'] with allowed return codes [0] (shell=False, capture=True)
2019-03-29 11:25:02,559 - util.py[DEBUG]: Reading from /proc/1/environ (quiet=False)
2019-03-29 11:25:02,559 - util.py[DEBUG]: Read 150 bytes from /proc/1/environ
2019-03-29 11:25:02,559 - util.py[DEBUG]: Reading from /proc/self/status (quiet=False)
2019-03-29 11:25:02,559 - util.py[DEBUG]: Read 967 bytes from /proc/self/status
2019-03-29 11:25:02,559 - util.py[DEBUG]: querying dmi data /sys/class/dmi/id/product_serial
2019-03-29 11:25:02,559 - util.py[DEBUG]: Reading from /sys/class/dmi/id/product_serial (quiet=False)
2019-03-29 11:25:02,559 - util.py[DEBUG]: Read 37 bytes from /sys/class/dmi/id/product_serial
2019-03-29 11:25:02,559 - util.py[DEBUG]: dmi data /sys/class/dmi/id/product_serial returned ec260091-9413-bbdc-08bf-e2a098ca0faa
2019-03-29 11:25:02,560 - DataSourceEc2.py[DEBUG]: strict_mode: warn, cloud_platform=AWS
2019-03-29 11:25:02,560 - util.py[DEBUG]: Reading from /etc/os-release (quiet=False)
2019-03-29 11:25:02,560 - util.py[DEBUG]: Read 298 bytes from /etc/os-release
2019-03-29 11:25:02,560 - util.py[DEBUG]: Reading from /sys/class/net/ens3/name_assign_type (quiet=False)
2019-03-29 11:25:02,560 - util.py[DEBUG]: Read 2 bytes from /sys/class/net/ens3/name_assign_type
2019-03-29 11:25:02,560 - util.py[DEBUG]: Reading from /sys/class/net/ens3/carrier (quiet=False)
2019-03-29 11:25:02,561 - util.py[DEBUG]: Reading from /sys/class/net/ens3/dormant (quiet=False)
2019-03-29 11:25:02,561 - util.py[DEBUG]: Reading from /sys/class/net/ens3/operstate (quiet=False)
2019-03-29 11:25:02,561 - util.py[DEBUG]: Read 5 bytes from /sys/class/net/ens3/operstate
2019-03-29 11:25:02,561 - util.py[DEBUG]: Reading from /sys/class/net/ens3/address (quiet=False)
2019-03-29 11:25:02,561 - util.py[DEBUG]: Read 18 bytes from /sys/class/net/ens3/address
2019-03-29 11:25:02,561 - dhcp.py[DEBUG]: Performing a dhcp discovery on ens3
2019-03-29 11:25:02,561 - util.py[DEBUG]: Copying /sbin/dhclient to /var/tmp/cloud-init/cloud-init-dhcp-hhfwnz0m/dhclient
2019-03-29 11:25:02,578 - util.py[DEBUG]: Running command ['ip', 'link', 'set', 'dev', 'ens3', 'up'] with allowed return codes [0] (shell=False, capture=True)
2019-03-29 11:25:02,595 - util.py[DEBUG]: Running command ['/var/tmp/cloud-init/cloud-init-dhcp-hhfwnz0m/dhclient', '-1', '-v', '-lf', '/var/tmp/cloud-init/cloud-init-dhcp-hhfwnz0m/dhcp.leases', '-pf', '/var/tmp/cloud-init/cloud-init-dhcp-hhfwnz0m/dhclient.pid', 'ens3', '-sf', '/bin/true'] with allowed return codes [0] (shell=False, capture=True)
2019-03-29 11:25:02,686 - util.py[DEBUG]: All files appeared after 0 seconds: ['/var/tmp/cloud-init/cloud-init-dhcp-hhfwnz0m/dhclient.pid', '/var/tmp/cloud-init/cloud-init-dhcp-hhfwnz0m/dhcp.leases']
2019-03-29 11:25:02,686 - util.py[DEBUG]: Reading from /var/tmp/cloud-init/cloud-init-dhcp-hhfwnz0m/dhclient.pid (quiet=False)
2019-03-29 11:25:02,686 - util.py[DEBUG]: Read 5 bytes from /var/tmp/cloud-init/cloud-init-dhcp-hhfwnz0m/dhclient.pid
2019-03-29 11:25:02,686 - util.py[DEBUG]: Reading from /var/tmp/cloud-init/cloud-init-dhcp-hhfwnz0m/dhcp.leases (quiet=False)
2019-03-29 11:25:02,686 - util.py[DEBUG]: Read 511 bytes from /var/tmp/cloud-init/cloud-init-dhcp-hhfwnz0m/dhcp.leases
2019-03-29 11:25:02,686 - dhcp.py[DEBUG]: Received dhcp lease on ens3 for 10.0.0.80/255.255.255.0
2019-03-29 11:25:02,687 - __init__.py[DEBUG]: Attempting setup of ephemeral network on ens3 with 10.0.0.80/24 brd 10.0.0.255
2019-03-29 11:25:02,687 - util.py[DEBUG]: Running command ['ip', '-family', 'inet', 'addr', 'add', '10.0.0.80/24', 'broadcast', '10.0.0.255', 'dev', 'ens3'] with allowed return codes [0] (shell=False, capture=True)
2019-03-29 11:25:02,689 - util.py[DEBUG]: Running command ['ip', '-family', 'inet', 'link', 'set', 'dev', 'ens3', 'up'] with allowed return codes [0] (shell=False, capture=True)
2019-03-29 11:25:02,692 - util.py[DEBUG]: Running command ['ip', 'route', 'show', '0.0.0.0/0'] with allowed return codes [0] (shell=False, capture=True)
2019-03-29 11:25:02,693 - util.py[DEBUG]: Running command ['ip', '-4', 'route', 'add', 'default', 'via', '10.0.0.1', 'dev', 'ens3'] with allowed return codes [0] (shell=False, capture=True)
2019-03-29 11:25:02,698 - util.py[DEBUG]: Resolving URL: http://169.254.169.254 took 0.003 seconds
2019-03-29 11:25:02,698 - util.py[DEBUG]: Resolving URL: http://instance-data.:8773 took 0.000 seconds
2019-03-29 11:25:02,698 - DataSourceEc2.py[DEBUG]: Removed the following from metadata urls: ['http://instance-data.:8773']
2019-03-29 11:25:02,699 - url_helper.py[DEBUG]: [0/1] open 'http://169.254.169.254/2009-04-04/meta-data/instance-id' with {'url': 'http://169.254.169.254/2009-04-04/meta-data/instance-id', 'method': 'GET', 'headers': {'User-Agent': 'Cloud-Init/18.3-9-g2e62cb8a-0ubuntu1~16.04.2'}, 'timeout': 50.0, 'allow_redirects': True} configuration
2019-03-29 11:25:02,704 - url_helper.py[DEBUG]: Read from http://169.254.169.254/2009-04-04/meta-data/instance-id (200, 19b) after 1 attempts
2019-03-29 11:25:02,704 - DataSourceEc2.py[DEBUG]: Using metadata source: 'http://169.254.169.254'
2019-03-29 11:25:02,704 - url_helper.py[DEBUG]: [0/1] open 'http://169.254.169.254/2016-09-02/meta-data/instance-id' with {'url': 'http://169.254.169.254/2016-09-02/meta-data/instance-id', 'method': 'GET', 'headers': {'User-Agent': 'Cloud-Init/18.3-9-g2e62cb8a-0ubuntu1~16.04.2'}, 'allow_redirects': True} configuration
2019-03-29 11:25:02,705 - url_helper.py[DEBUG]: Read from http://169.254.169.254/2016-09-02/meta-data/instance-id (200, 19b) after 1 attempts
2019-03-29 11:25:02,705 - DataSourceEc2.py[DEBUG]: Found preferred metadata version 2016-09-02
2019-03-29 11:25:02,706 - url_helper.py[DEBUG]: [0/6] open 'http://169.254.169.254/2016-09-02/user-data' with {'url': 'http://169.254.169.254/2016-09-02/user-data', 'method': 'GET', 'headers': {'User-Agent': 'Cloud-Init/18.3-9-g2e62cb8a-0ubuntu1~16.04.2'}, 'timeout': 5.0, 'allow_redirects': True} configuration
2019-03-29 11:25:02,707 - url_helper.py[DEBUG]: [0/6] open 'http://169.254.169.254/2016-09-02/meta-data/' with {'url': 'http://169.254.169.254/2016-09-02/meta-data/', 'method': 'GET', 'headers': {'User-Agent': 'Cloud-Init/18.3-9-g2e62cb8a-0ubuntu1~16.04.2'}, 'timeout': 5.0, 'allow_redirects': True} configuration
2019-03-29 11:25:02,709 - url_helper.py[DEBUG]: Read from http://169.254.169.254/2016-09-02/meta-data/ (200, 268b) after 1 attempts
2019-03-29 11:25:02,709 - url_helper.py[DEBUG]: [0/6] open 'http://169.254.169.254/2016-09-02/meta-data/block-device-mapping/' with {'url': 'http://169.254.169.254/2016-09-02/meta-data/block-device-mapping/', 'method': 'GET', 'headers': {'User-Agent': 'Cloud-Init/18.3-9-g2e62cb8a-0ubuntu1~16.04.2'}, 'timeout': 5.0, 'allow_redirects': True} configuration
2019-03-29 11:25:02,710 - url_helper.py[DEBUG]: Read from http://169.254.169.254/2016-09-02/meta-data/block-device-mapping/ (200, 30b) after 1 attempts
2019-03-29 11:25:02,711 - url_helper.py[DEBUG]: [0/6] open 'http://169.254.169.254/2016-09-02/meta-data/block-device-mapping/ami' with {'url': 'http://169.254.169.254/2016-09-02/meta-data/block-device-mapping/ami', 'method': 'GET', 'headers': {'User-Agent': 'Cloud-Init/18.3-9-g2e62cb8a-0ubuntu1~16.04.2'}, 'timeout': 5.0, 'allow_redirects': True} configuration
2019-03-29 11:25:02,712 - url_helper.py[DEBUG]: Read from http://169.254.169.254/2016-09-02/meta-data/block-device-mapping/ami (200, 9b) after 1 attempts
2019-03-29 11:25:02,712 - url_helper.py[DEBUG]: [0/6] open 'http://169.254.169.254/2016-09-02/meta-data/block-device-mapping/ephemeral0' with {'url': 'http://169.254.169.254/2016-09-02/meta-data/block-device-mapping/ephemeral0', 'method': 'GET', 'headers': {'User-Agent': 'Cloud-Init/18.3-9-g2e62cb8a-0ubuntu1~16.04.2'}, 'timeout': 5.0, 'allow_redirects': True} configuration
2019-03-29 11:25:02,714 - url_helper.py[DEBUG]: Read from http://169.254.169.254/2016-09-02/meta-data/block-device-mapping/ephemeral0 (200, 3b) after 1 attempts
2019-03-29 11:25:02,714 - url_helper.py[DEBUG]: [0/6] open 'http://169.254.169.254/2016-09-02/meta-data/block-device-mapping/ephemeral1' with {'url': 'http://169.254.169.254/2016-09-02/meta-data/block-device-mapping/ephemeral1', 'method': 'GET', 'headers': {'User-Agent': 'Cloud-Init/18.3-9-g2e62cb8a-0ubuntu1~16.04.2'}, 'timeout': 5.0, 'allow_redirects': True} configuration
2019-03-29 11:25:02,715 - url_helper.py[DEBUG]: Read from http://169.254.169.254/2016-09-02/meta-data/block-device-mapping/ephemeral1 (200, 3b) after 1 attempts
2019-03-29 11:25:02,715 - url_helper.py[DEBUG]: [0/6] open 'http://169.254.169.254/2016-09-02/meta-data/block-device-mapping/root' with {'url': 'http://169.254.169.254/2016-09-02/meta-data/block-device-mapping/root', 'method': 'GET', 'headers': {'User-Agent': 'Cloud-Init/18.3-9-g2e62cb8a-0ubuntu1~16.04.2'}, 'timeout': 5.0, 'allow_redirects': True} configuration
2019-03-29 11:25:02,717 - url_helper.py[DEBUG]: Read from http://169.254.169.254/2016-09-02/meta-data/block-device-mapping/root (200, 9b) after 1 attempts
2019-03-29 11:25:02,717 - url_helper.py[DEBUG]: [0/6] open 'http://169.254.169.254/2016-09-02/meta-data/iam/' with {'url': 'http://169.254.169.254/2016-09-02/meta-data/iam/', 'method': 'GET', 'headers': {'User-Agent': 'Cloud-Init/18.3-9-g2e62cb8a-0ubuntu1~16.04.2'}, 'timeout': 5.0, 'allow_redirects': True} configuration
2019-03-29 11:25:02,719 - url_helper.py[DEBUG]: Read from http://169.254.169.254/2016-09-02/meta-data/iam/ (200, 26b) after 1 attempts
2019-03-29 11:25:02,719 - url_helper.py[DEBUG]: [0/6] open 'http://169.254.169.254/2016-09-02/meta-data/iam/info' with {'url': 'http://169.254.169.254/2016-09-02/meta-data/iam/info', 'method': 'GET', 'headers': {'User-Agent': 'Cloud-Init/18.3-9-g2e62cb8a-0ubuntu1~16.04.2'}, 'timeout': 5.0, 'allow_redirects': True} configuration
2019-03-29 11:25:02,720 - url_helper.py[DEBUG]: Read from http://169.254.169.254/2016-09-02/meta-data/iam/info (200, 245b) after 1 attempts
2019-03-29 11:25:02,720 - url_helper.py[DEBUG]: [0/6] open 'http://169.254.169.254/2016-09-02/meta-data/metrics/' with {'url': 'http://169.254.169.254/2016-09-02/meta-data/metrics/', 'method': 'GET', 'headers': {'User-Agent': 'Cloud-Init/18.3-9-g2e62cb8a-0ubuntu1~16.04.2'}, 'timeout': 5.0, 'allow_redirects': True} configuration
2019-03-29 11:25:02,722 - url_helper.py[DEBUG]: Read from http://169.254.169.254/2016-09-02/meta-data/metrics/ (200, 7b) after 1 attempts
2019-03-29 11:25:02,722 - url_helper.py[DEBUG]: [0/6] open 'http://169.254.169.254/2016-09-02/meta-data/metrics/vhostmd' with {'url': 'http://169.254.169.254/2016-09-02/meta-data/metrics/vhostmd', 'method': 'GET', 'headers': {'User-Agent': 'Cloud-Init/18.3-9-g2e62cb8a-0ubuntu1~16.04.2'}, 'timeout': 5.0, 'allow_redirects': True} configuration
2019-03-29 11:25:02,723 - url_helper.py[DEBUG]: Read from http://169.254.169.254/2016-09-02/meta-data/metrics/vhostmd (200, 38b) after 1 attempts
2019-03-29 11:25:02,724 - url_helper.py[DEBUG]: [0/6] open 'http://169.254.169.254/2016-09-02/meta-data/network/' with {'url': 'http://169.254.169.254/2016-09-02/meta-data/network/', 'method': 'GET', 'headers': {'User-Agent': 'Cloud-Init/18.3-9-g2e62cb8a-0ubuntu1~16.04.2'}, 'timeout': 5.0, 'allow_redirects': True} configuration
2019-03-29 11:25:02,725 - url_helper.py[DEBUG]: Read from http://169.254.169.254/2016-09-02/meta-data/network/ (200, 11b) after 1 attempts
2019-03-29 11:25:02,725 - url_helper.py[DEBUG]: [0/6] open 'http://169.254.169.254/2016-09-02/meta-data/network/interfaces/' with {'url': 'http://169.254.169.254/2016-09-02/meta-data/network/interfaces/', 'method': 'GET', 'headers': {'User-Agent': 'Cloud-Init/18.3-9-g2e62cb8a-0ubuntu1~16.04.2'}, 'timeout': 5.0, 'allow_redirects': True} configuration
2019-03-29 11:25:02,727 - url_helper.py[DEBUG]: Read from http://169.254.169.254/2016-09-02/meta-data/network/interfaces/ (200, 5b) after 1 attempts
2019-03-29 11:25:02,727 - url_helper.py[DEBUG]: [0/6] open 'http://169.254.169.254/2016-09-02/meta-data/network/interfaces/macs/' with {'url': 'http://169.254.169.254/2016-09-02/meta-data/network/interfaces/macs/', 'method': 'GET', 'headers': {'User-Agent': 'Cloud-Init/18.3-9-g2e62cb8a-0ubuntu1~16.04.2'}, 'timeout': 5.0, 'allow_redirects': True} configuration
2019-03-29 11:25:02,729 - url_helper.py[DEBUG]: Read from http://169.254.169.254/2016-09-02/meta-data/network/interfaces/macs/ (200, 18b) after 1 attempts
2019-03-29 11:25:02,729 - url_helper.py[DEBUG]: [0/6] open 'http://169.254.169.254/2016-09-02/meta-data/network/interfaces/macs/06:71:46:9b:71:b8/' with {'url': 'http://169.254.169.254/2016-09-02/meta-data/network/interfaces/macs/06:71:46:9b:71:b8/', 'method': 'GET', 'headers': {'User-Agent': 'Cloud-Init/18.3-9-g2e62cb8a-0ubuntu1~16.04.2'}, 'timeout': 5.0, 'allow_redirects': True} configuration
2019-03-29 11:25:02,730 - url_helper.py[DEBUG]: Read from http://169.254.169.254/2016-09-02/meta-data/network/interfaces/macs/06:71:46:9b:71:b8/ (200, 230b) after 1 attempts
2019-03-29 11:25:02,731 - url_helper.py[DEBUG]: [0/6] open 'http://169.254.169.254/2016-09-02/meta-data/network/interfaces/macs/06:71:46:9b:71:b8/ipv4-associations/' with {'url': 'http://169.254.169.254/2016-09-02/meta-data/network/interfaces/macs/06:71:46:9b:71:b8/ipv4-associations/', 'method': 'GET', 'headers': {'User-Agent': 'Cloud-Init/18.3-9-g2e62cb8a-0ubuntu1~16.04.2'}, 'timeout': 5.0, 'allow_redirects': True} configuration
2019-03-29 11:25:02,732 - url_helper.py[DEBUG]: Read from http://169.254.169.254/2016-09-02/meta-data/network/interfaces/macs/06:71:46:9b:71:b8/ipv4-associations/ (200, 12b) after 1 attempts
2019-03-29 11:25:02,732 - url_helper.py[DEBUG]: [0/6] open 'http://169.254.169.254/2016-09-02/meta-data/network/interfaces/macs/06:71:46:9b:71:b8/ipv4-associations/34.245.54.26' with {'url': 'http://169.254.169.254/2016-09-02/meta-data/network/interfaces/macs/06:71:46:9b:71:b8/ipv4-associations/34.245.54.26', 'method': 'GET', 'headers': {'User-Agent': 'Cloud-Init/18.3-9-g2e62cb8a-0ubuntu1~16.04.2'}, 'timeout': 5.0, 'allow_redirects': True} configuration
2019-03-29 11:25:02,734 - url_helper.py[DEBUG]: Read from http://169.254.169.254/2016-09-02/meta-data/network/interfaces/macs/06:71:46:9b:71:b8/ipv4-associations/34.245.54.26 (200, 9b) after 1 attempts
2019-03-29 11:25:02,734 - url_helper.py[DEBUG]: [0/6] open 'http://169.254.169.254/2016-09-02/meta-data/network/interfaces/macs/06:71:46:9b:71:b8/mac' with {'url': 'http://169.254.169.254/2016-09-02/meta-data/network/interfaces/macs/06:71:46:9b:71:b8/mac', 'method': 'GET', 'headers': {'User-Agent': 'Cloud-Init/18.3-9-g2e62cb8a-0ubuntu1~16.04.2'}, 'timeout': 5.0, 'allow_redirects': True} configuration
2019-03-29 11:25:02,735 - url_helper.py[DEBUG]: Read from http://169.254.169.254/2016-09-02/meta-data/network/interfaces/macs/06:71:46:9b:71:b8/mac (200, 17b) after 1 attempts
2019-03-29 11:25:02,735 - url_helper.py[DEBUG]: [0/6] open 'http://169.254.169.254/2016-09-02/meta-data/network/interfaces/macs/06:71:46:9b:71:b8/interface-id' with {'url': 'http://169.254.169.254/2016-09-02/meta-data/network/interfaces/macs/06:71:46:9b:71:b8/interface-id', 'method': 'GET', 'headers': {'User-Agent': 'Cloud-Init/18.3-9-g2e62cb8a-0ubuntu1~16.04.2'}, 'timeout': 5.0, 'allow_redirects': True} configuration
2019-03-29 11:25:02,737 - url_helper.py[DEBUG]: Read from http://169.254.169.254/2016-09-02/meta-data/network/interfaces/macs/06:71:46:9b:71:b8/interface-id (200, 21b) after 1 attempts
2019-03-29 11:25:02,737 - url_helper.py[DEBUG]: [0/6] open 'http://169.254.169.254/2016-09-02/meta-data/network/interfaces/macs/06:71:46:9b:71:b8/vpc-id' with {'url': 'http://169.254.169.254/2016-09-02/meta-data/network/interfaces/macs/06:71:46:9b:71:b8/vpc-id', 'method': 'GET', 'headers': {'User-Agent': 'Cloud-Init/18.3-9-g2e62cb8a-0ubuntu1~16.04.2'}, 'timeout': 5.0, 'allow_redirects': True} configuration
2019-03-29 11:25:02,738 - url_helper.py[DEBUG]: Read from http://169.254.169.254/2016-09-02/meta-data/network/interfaces/macs/06:71:46:9b:71:b8/vpc-id (200, 21b) after 1 attempts
2019-03-29 11:25:02,739 - url_helper.py[DEBUG]: [0/6] open 'http://169.254.169.254/2016-09-02/meta-data/network/interfaces/macs/06:71:46:9b:71:b8/subnet-id' with {'url': 'http://169.254.169.254/2016-09-02/meta-data/network/interfaces/macs/06:71:46:9b:71:b8/subnet-id', 'method': 'GET', 'headers': {'User-Agent': 'Cloud-Init/18.3-9-g2e62cb8a-0ubuntu1~16.04.2'}, 'timeout': 5.0, 'allow_redirects': True} configuration
2019-03-29 11:25:02,740 - url_helper.py[DEBUG]: Read from http://169.254.169.254/2016-09-02/meta-data/network/interfaces/macs/06:71:46:9b:71:b8/subnet-id (200, 24b) after 1 attempts
2019-03-29 11:25:02,740 - url_helper.py[DEBUG]: [0/6] open 'http://169.254.169.254/2016-09-02/meta-data/network/interfaces/macs/06:71:46:9b:71:b8/device-number' with {'url': 'http://169.254.169.254/2016-09-02/meta-data/network/interfaces/macs/06:71:46:9b:71:b8/device-number', 'method': 'GET', 'headers': {'User-Agent': 'Cloud-Init/18.3-9-g2e62cb8a-0ubuntu1~16.04.2'}, 'timeout': 5.0, 'allow_redirects': True} configuration
2019-03-29 11:25:02,742 - url_helper.py[DEBUG]: Read from http://169.254.169.254/2016-09-02/meta-data/network/interfaces/macs/06:71:46:9b:71:b8/device-number (200, 1b) after 1 attempts
2019-03-29 11:25:02,742 - url_helper.py[DEBUG]: [0/6] open 'http://169.254.169.254/2016-09-02/meta-data/network/interfaces/macs/06:71:46:9b:71:b8/local-hostname' with {'url': 'http://169.254.169.254/2016-09-02/meta-data/network/interfaces/macs/06:71:46:9b:71:b8/local-hostname', 'method': 'GET', 'headers': {'User-Agent': 'Cloud-Init/18.3-9-g2e62cb8a-0ubuntu1~16.04.2'}, 'timeout': 5.0, 'allow_redirects': True} configuration
2019-03-29 11:25:02,743 - url_helper.py[DEBUG]: Read from http://169.254.169.254/2016-09-02/meta-data/network/interfaces/macs/06:71:46:9b:71:b8/local-hostname (200, 39b) after 1 attempts
2019-03-29 11:25:02,743 - url_helper.py[DEBUG]: [0/6] open 'http://169.254.169.254/2016-09-02/meta-data/network/interfaces/macs/06:71:46:9b:71:b8/public-hostname' with {'url': 'http://169.254.169.254/2016-09-02/meta-data/network/interfaces/macs/06:71:46:9b:71:b8/public-hostname', 'method': 'GET', 'headers': {'User-Agent': 'Cloud-Init/18.3-9-g2e62cb8a-0ubuntu1~16.04.2'}, 'timeout': 5.0, 'allow_redirects': True} configuration
2019-03-29 11:25:02,745 - url_helper.py[DEBUG]: Read from http://169.254.169.254/2016-09-02/meta-data/network/interfaces/macs/06:71:46:9b:71:b8/public-hostname (200, 48b) after 1 attempts
2019-03-29 11:25:02,745 - url_helper.py[DEBUG]: [0/6] open 'http://169.254.169.254/2016-09-02/meta-data/network/interfaces/macs/06:71:46:9b:71:b8/local-ipv4s' with {'url': 'http://169.254.169.254/2016-09-02/meta-data/network/interfaces/macs/06:71:46:9b:71:b8/local-ipv4s', 'method': 'GET', 'headers': {'User-Agent': 'Cloud-Init/18.3-9-g2e62cb8a-0ubuntu1~16.04.2'}, 'timeout': 5.0, 'allow_redirects': True} configuration
2019-03-29 11:25:02,748 - url_helper.py[DEBUG]: Read from http://169.254.169.254/2016-09-02/meta-data/network/interfaces/macs/06:71:46:9b:71:b8/local-ipv4s (200, 9b) after 1 attempts
2019-03-29 11:25:02,748 - url_helper.py[DEBUG]: [0/6] open 'http://169.254.169.254/2016-09-02/meta-data/network/interfaces/macs/06:71:46:9b:71:b8/public-ipv4s' with {'url': 'http://169.254.169.254/2016-09-02/meta-data/network/interfaces/macs/06:71:46:9b:71:b8/public-ipv4s', 'method': 'GET', 'headers': {'User-Agent': 'Cloud-Init/18.3-9-g2e62cb8a-0ubuntu1~16.04.2'}, 'timeout': 5.0, 'allow_redirects': True} configuration
2019-03-29 11:25:02,749 - url_helper.py[DEBUG]: Read from http://169.254.169.254/2016-09-02/meta-data/network/interfaces/macs/06:71:46:9b:71:b8/public-ipv4s (200, 12b) after 1 attempts
2019-03-29 11:25:02,749 - url_helper.py[DEBUG]: [0/6] open 'http://169.254.169.254/2016-09-02/meta-data/network/interfaces/macs/06:71:46:9b:71:b8/vpc-ipv4-cidr-block' with {'url': 'http://169.254.169.254/2016-09-02/meta-data/network/interfaces/macs/06:71:46:9b:71:b8/vpc-ipv4-cidr-block', 'method': 'GET', 'headers': {'User-Agent': 'Cloud-Init/18.3-9-g2e62cb8a-0ubuntu1~16.04.2'}, 'timeout': 5.0, 'allow_redirects': True} configuration
2019-03-29 11:25:02,751 - url_helper.py[DEBUG]: Read from http://169.254.169.254/2016-09-02/meta-data/network/interfaces/macs/06:71:46:9b:71:b8/vpc-ipv4-cidr-block (200, 11b) after 1 attempts
2019-03-29 11:25:02,751 - url_helper.py[DEBUG]: [0/6] open 'http://169.254.169.254/2016-09-02/meta-data/network/interfaces/macs/06:71:46:9b:71:b8/security-groups' with {'url': 'http://169.254.169.254/2016-09-02/meta-data/network/interfaces/macs/06:71:46:9b:71:b8/security-groups', 'method': 'GET', 'headers': {'User-Agent': 'Cloud-Init/18.3-9-g2e62cb8a-0ubuntu1~16.04.2'}, 'timeout': 5.0, 'allow_redirects': True} configuration
2019-03-29 11:25:02,752 - url_helper.py[DEBUG]: Read from http://169.254.169.254/2016-09-02/meta-data/network/interfaces/macs/06:71:46:9b:71:b8/security-groups (200, 328b) after 1 attempts
2019-03-29 11:25:02,752 - url_helper.py[DEBUG]: [0/6] open 'http://169.254.169.254/2016-09-02/meta-data/network/interfaces/macs/06:71:46:9b:71:b8/security-group-ids' with {'url': 'http://169.254.169.254/2016-09-02/meta-data/network/interfaces/macs/06:71:46:9b:71:b8/security-group-ids', 'method': 'GET', 'headers': {'User-Agent': 'Cloud-Init/18.3-9-g2e62cb8a-0ubuntu1~16.04.2'}, 'timeout': 5.0, 'allow_redirects': True} configuration
2019-03-29 11:25:02,754 - url_helper.py[DEBUG]: Read from http://169.254.169.254/2016-09-02/meta-data/network/interfaces/macs/06:71:46:9b:71:b8/security-group-ids (200, 83b) after 1 attempts
2019-03-29 11:25:02,754 - url_helper.py[DEBUG]: [0/6] open 'http://169.254.169.254/2016-09-02/meta-data/network/interfaces/macs/06:71:46:9b:71:b8/owner-id' with {'url': 'http://169.254.169.254/2016-09-02/meta-data/network/interfaces/macs/06:71:46:9b:71:b8/owner-id', 'method': 'GET', 'headers': {'User-Agent': 'Cloud-Init/18.3-9-g2e62cb8a-0ubuntu1~16.04.2'}, 'timeout': 5.0, 'allow_redirects': True} configuration
2019-03-29 11:25:02,756 - url_helper.py[DEBUG]: Read from http://169.254.169.254/2016-09-02/meta-data/network/interfaces/macs/06:71:46:9b:71:b8/owner-id (200, 12b) after 1 attempts
2019-03-29 11:25:02,756 - url_helper.py[DEBUG]: [0/6] open 'http://169.254.169.254/2016-09-02/meta-data/network/interfaces/macs/06:71:46:9b:71:b8/vpc-ipv4-cidr-blocks' with {'url': 'http://169.254.169.254/2016-09-02/meta-data/network/interfaces/macs/06:71:46:9b:71:b8/vpc-ipv4-cidr-blocks', 'method': 'GET', 'headers': {'User-Agent': 'Cloud-Init/18.3-9-g2e62cb8a-0ubuntu1~16.04.2'}, 'timeout': 5.0, 'allow_redirects': True} configuration
2019-03-29 11:25:02,757 - url_helper.py[DEBUG]: Read from http://169.254.169.254/2016-09-02/meta-data/network/interfaces/macs/06:71:46:9b:71:b8/vpc-ipv4-cidr-blocks (200, 11b) after 1 attempts
2019-03-29 11:25:02,757 - url_helper.py[DEBUG]: [0/6] open 'http://169.254.169.254/2016-09-02/meta-data/network/interfaces/macs/06:71:46:9b:71:b8/subnet-ipv4-cidr-block' with {'url': 'http://169.254.169.254/2016-09-02/meta-data/network/interfaces/macs/06:71:46:9b:71:b8/subnet-ipv4-cidr-block', 'method': 'GET', 'headers': {'User-Agent': 'Cloud-Init/18.3-9-g2e62cb8a-0ubuntu1~16.04.2'}, 'timeout': 5.0, 'allow_redirects': True} configuration
2019-03-29 11:25:02,759 - url_helper.py[DEBUG]: Read from http://169.254.169.254/2016-09-02/meta-data/network/interfaces/macs/06:71:46:9b:71:b8/subnet-ipv4-cidr-block (200, 11b) after 1 attempts
2019-03-29 11:25:02,759 - url_helper.py[DEBUG]: [0/6] open 'http://169.254.169.254/2016-09-02/meta-data/placement/' with {'url': 'http://169.254.169.254/2016-09-02/meta-data/placement/', 'method': 'GET', 'headers': {'User-Agent': 'Cloud-Init/18.3-9-g2e62cb8a-0ubuntu1~16.04.2'}, 'timeout': 5.0, 'allow_redirects': True} configuration
2019-03-29 11:25:02,760 - url_helper.py[DEBUG]: Read from http://169.254.169.254/2016-09-02/meta-data/placement/ (200, 17b) after 1 attempts
2019-03-29 11:25:02,761 - url_helper.py[DEBUG]: [0/6] open 'http://169.254.169.254/2016-09-02/meta-data/placement/availability-zone' with {'url': 'http://169.254.169.254/2016-09-02/meta-data/placement/availability-zone', 'method': 'GET', 'headers': {'User-Agent': 'Cloud-Init/18.3-9-g2e62cb8a-0ubuntu1~16.04.2'}, 'timeout': 5.0, 'allow_redirects': True} configuration
2019-03-29 11:25:02,762 - url_helper.py[DEBUG]: Read from http://169.254.169.254/2016-09-02/meta-data/placement/availability-zone (200, 10b) after 1 attempts
2019-03-29 11:25:02,762 - url_helper.py[DEBUG]: [0/6] open 'http://169.254.169.254/2016-09-02/meta-data/public-keys/' with {'url': 'http://169.254.169.254/2016-09-02/meta-data/public-keys/', 'method': 'GET', 'headers': {'User-Agent': 'Cloud-Init/18.3-9-g2e62cb8a-0ubuntu1~16.04.2'}, 'timeout': 5.0, 'allow_redirects': True} configuration
2019-03-29 11:25:02,764 - url_helper.py[DEBUG]: Read from http://169.254.169.254/2016-09-02/meta-data/public-keys/ (200, 68b) after 1 attempts
2019-03-29 11:25:02,764 - url_helper.py[DEBUG]: [0/6] open 'http://169.254.169.254/2016-09-02/meta-data/public-keys/0/openssh-key' with {'url': 'http://169.254.169.254/2016-09-02/meta-data/public-keys/0/openssh-key', 'method': 'GET', 'headers': {'User-Agent': 'Cloud-Init/18.3-9-g2e62cb8a-0ubuntu1~16.04.2'}, 'timeout': 5.0, 'allow_redirects': True} configuration
2019-03-29 11:25:02,765 - url_helper.py[DEBUG]: Read from http://169.254.169.254/2016-09-02/meta-data/public-keys/0/openssh-key (200, 448b) after 1 attempts
2019-03-29 11:25:02,765 - url_helper.py[DEBUG]: [0/6] open 'http://169.254.169.254/2016-09-02/meta-data/services/' with {'url': 'http://169.254.169.254/2016-09-02/meta-data/services/', 'method': 'GET', 'headers': {'User-Agent': 'Cloud-Init/18.3-9-g2e62cb8a-0ubuntu1~16.04.2'}, 'timeout': 5.0, 'allow_redirects': True} configuration
2019-03-29 11:25:02,767 - url_helper.py[DEBUG]: Read from http://169.254.169.254/2016-09-02/meta-data/services/ (200, 16b) after 1 attempts
2019-03-29 11:25:02,767 - url_helper.py[DEBUG]: [0/6] open 'http://169.254.169.254/2016-09-02/meta-data/services/partition' with {'url': 'http://169.254.169.254/2016-09-02/meta-data/services/partition', 'method': 'GET', 'headers': {'User-Agent': 'Cloud-Init/18.3-9-g2e62cb8a-0ubuntu1~16.04.2'}, 'timeout': 5.0, 'allow_redirects': True} configuration
2019-03-29 11:25:02,768 - url_helper.py[DEBUG]: Read from http://169.254.169.254/2016-09-02/meta-data/services/partition (200, 3b) after 1 attempts
2019-03-29 11:25:02,769 - url_helper.py[DEBUG]: [0/6] open 'http://169.254.169.254/2016-09-02/meta-data/services/domain' with {'url': 'http://169.254.169.254/2016-09-02/meta-data/services/domain', 'method': 'GET', 'headers': {'User-Agent': 'Cloud-Init/18.3-9-g2e62cb8a-0ubuntu1~16.04.2'}, 'timeout': 5.0, 'allow_redirects': True} configuration
2019-03-29 11:25:02,770 - url_helper.py[DEBUG]: Read from http://169.254.169.254/2016-09-02/meta-data/services/domain (200, 13b) after 1 attempts
2019-03-29 11:25:02,770 - url_helper.py[DEBUG]: [0/6] open 'http://169.254.169.254/2016-09-02/meta-data/mac' with {'url': 'http://169.254.169.254/2016-09-02/meta-data/mac', 'method': 'GET', 'headers': {'User-Agent': 'Cloud-Init/18.3-9-g2e62cb8a-0ubuntu1~16.04.2'}, 'timeout': 5.0, 'allow_redirects': True} configuration
2019-03-29 11:25:02,771 - url_helper.py[DEBUG]: Read from http://169.254.169.254/2016-09-02/meta-data/mac (200, 17b) after 1 attempts
2019-03-29 11:25:02,772 - url_helper.py[DEBUG]: [0/6] open 'http://169.254.169.254/2016-09-02/meta-data/instance-type' with {'url': 'http://169.254.169.254/2016-09-02/meta-data/instance-type', 'method': 'GET', 'headers': {'User-Agent': 'Cloud-Init/18.3-9-g2e62cb8a-0ubuntu1~16.04.2'}, 'timeout': 5.0, 'allow_redirects': True} configuration
2019-03-29 11:25:02,773 - url_helper.py[DEBUG]: Read from http://169.254.169.254/2016-09-02/meta-data/instance-type (200, 10b) after 1 attempts
2019-03-29 11:25:02,773 - url_helper.py[DEBUG]: [0/6] open 'http://169.254.169.254/2016-09-02/meta-data/local-ipv4' with {'url': 'http://169.254.169.254/2016-09-02/meta-data/local-ipv4', 'method': 'GET', 'headers': {'User-Agent': 'Cloud-Init/18.3-9-g2e62cb8a-0ubuntu1~16.04.2'}, 'timeout': 5.0, 'allow_redirects': True} configuration
2019-03-29 11:25:02,775 - url_helper.py[DEBUG]: Read from http://169.254.169.254/2016-09-02/meta-data/local-ipv4 (200, 9b) after 1 attempts
2019-03-29 11:25:02,775 - url_helper.py[DEBUG]: [0/6] open 'http://169.254.169.254/2016-09-02/meta-data/hostname' with {'url': 'http://169.254.169.254/2016-09-02/meta-data/hostname', 'method': 'GET', 'headers': {'User-Agent': 'Cloud-Init/18.3-9-g2e62cb8a-0ubuntu1~16.04.2'}, 'timeout': 5.0, 'allow_redirects': True} configuration
2019-03-29 11:25:02,776 - url_helper.py[DEBUG]: Read from http://169.254.169.254/2016-09-02/meta-data/hostname (200, 39b) after 1 attempts
2019-03-29 11:25:02,776 - url_helper.py[DEBUG]: [0/6] open 'http://169.254.169.254/2016-09-02/meta-data/local-hostname' with {'url': 'http://169.254.169.254/2016-09-02/meta-data/local-hostname', 'method': 'GET', 'headers': {'User-Agent': 'Cloud-Init/18.3-9-g2e62cb8a-0ubuntu1~16.04.2'}, 'timeout': 5.0, 'allow_redirects': True} configuration
2019-03-29 11:25:02,778 - url_helper.py[DEBUG]: Read from http://169.254.169.254/2016-09-02/meta-data/local-hostname (200, 39b) after 1 attempts
2019-03-29 11:25:02,778 - url_helper.py[DEBUG]: [0/6] open 'http://169.254.169.254/2016-09-02/meta-data/public-hostname' with {'url': 'http://169.254.169.254/2016-09-02/meta-data/public-hostname', 'method': 'GET', 'headers': {'User-Agent': 'Cloud-Init/18.3-9-g2e62cb8a-0ubuntu1~16.04.2'}, 'timeout': 5.0, 'allow_redirects': True} configuration
2019-03-29 11:25:02,779 - url_helper.py[DEBUG]: Read from http://169.254.169.254/2016-09-02/meta-data/public-hostname (200, 48b) after 1 attempts
2019-03-29 11:25:02,779 - url_helper.py[DEBUG]: [0/6] open 'http://169.254.169.254/2016-09-02/meta-data/ami-launch-index' with {'url': 'http://169.254.169.254/2016-09-02/meta-data/ami-launch-index', 'method': 'GET', 'headers': {'User-Agent': 'Cloud-Init/18.3-9-g2e62cb8a-0ubuntu1~16.04.2'}, 'timeout': 5.0, 'allow_redirects': True} configuration
2019-03-29 11:25:02,781 - url_helper.py[DEBUG]: Read from http://169.254.169.254/2016-09-02/meta-data/ami-launch-index (200, 1b) after 1 attempts
2019-03-29 11:25:02,781 - url_helper.py[DEBUG]: [0/6] open 'http://169.254.169.254/2016-09-02/meta-data/public-ipv4' with {'url': 'http://169.254.169.254/2016-09-02/meta-data/public-ipv4', 'method': 'GET', 'headers': {'User-Agent': 'Cloud-Init/18.3-9-g2e62cb8a-0ubuntu1~16.04.2'}, 'timeout': 5.0, 'allow_redirects': True} configuration
2019-03-29 11:25:02,782 - url_helper.py[DEBUG]: Read from http://169.254.169.254/2016-09-02/meta-data/public-ipv4 (200, 12b) after 1 attempts
2019-03-29 11:25:02,782 - url_helper.py[DEBUG]: [0/6] open 'http://169.254.169.254/2016-09-02/meta-data/ami-manifest-path' with {'url': 'http://169.254.169.254/2016-09-02/meta-data/ami-manifest-path', 'method': 'GET', 'headers': {'User-Agent': 'Cloud-Init/18.3-9-g2e62cb8a-0ubuntu1~16.04.2'}, 'timeout': 5.0, 'allow_redirects': True} configuration
2019-03-29 11:25:02,784 - url_helper.py[DEBUG]: Read from http://169.254.169.254/2016-09-02/meta-data/ami-manifest-path (200, 9b) after 1 attempts
2019-03-29 11:25:02,784 - url_helper.py[DEBUG]: [0/6] open 'http://169.254.169.254/2016-09-02/meta-data/security-groups' with {'url': 'http://169.254.169.254/2016-09-02/meta-data/security-groups', 'method': 'GET', 'headers': {'User-Agent': 'Cloud-Init/18.3-9-g2e62cb8a-0ubuntu1~16.04.2'}, 'timeout': 5.0, 'allow_redirects': True} configuration
2019-03-29 11:25:02,786 - url_helper.py[DEBUG]: Read from http://169.254.169.254/2016-09-02/meta-data/security-groups (200, 328b) after 1 attempts
2019-03-29 11:25:02,786 - url_helper.py[DEBUG]: [0/6] open 'http://169.254.169.254/2016-09-02/meta-data/instance-id' with {'url': 'http://169.254.169.254/2016-09-02/meta-data/instance-id', 'method': 'GET', 'headers': {'User-Agent': 'Cloud-Init/18.3-9-g2e62cb8a-0ubuntu1~16.04.2'}, 'timeout': 5.0, 'allow_redirects': True} configuration
2019-03-29 11:25:02,787 - url_helper.py[DEBUG]: Read from http://169.254.169.254/2016-09-02/meta-data/instance-id (200, 19b) after 1 attempts
2019-03-29 11:25:02,787 - url_helper.py[DEBUG]: [0/6] open 'http://169.254.169.254/2016-09-02/meta-data/profile' with {'url': 'http://169.254.169.254/2016-09-02/meta-data/profile', 'method': 'GET', 'headers': {'User-Agent': 'Cloud-Init/18.3-9-g2e62cb8a-0ubuntu1~16.04.2'}, 'timeout': 5.0, 'allow_redirects': True} configuration
2019-03-29 11:25:02,789 - url_helper.py[DEBUG]: Read from http://169.254.169.254/2016-09-02/meta-data/profile (200, 11b) after 1 attempts
2019-03-29 11:25:02,789 - url_helper.py[DEBUG]: [0/6] open 'http://169.254.169.254/2016-09-02/meta-data/ami-id' with {'url': 'http://169.254.169.254/2016-09-02/meta-data/ami-id', 'method': 'GET', 'headers': {'User-Agent': 'Cloud-Init/18.3-9-g2e62cb8a-0ubuntu1~16.04.2'}, 'timeout': 5.0, 'allow_redirects': True} configuration
2019-03-29 11:25:02,790 - url_helper.py[DEBUG]: Read from http://169.254.169.254/2016-09-02/meta-data/ami-id (200, 21b) after 1 attempts
2019-03-29 11:25:02,790 - url_helper.py[DEBUG]: [0/6] open 'http://169.254.169.254/2016-09-02/meta-data/reservation-id' with {'url': 'http://169.254.169.254/2016-09-02/meta-data/reservation-id', 'method': 'GET', 'headers': {'User-Agent': 'Cloud-Init/18.3-9-g2e62cb8a-0ubuntu1~16.04.2'}, 'timeout': 5.0, 'allow_redirects': True} configuration
2019-03-29 11:25:02,792 - url_helper.py[DEBUG]: Read from http://169.254.169.254/2016-09-02/meta-data/reservation-id (200, 19b) after 1 attempts
2019-03-29 11:25:02,792 - url_helper.py[DEBUG]: [0/6] open 'http://169.254.169.254/2016-09-02/meta-data/instance-action' with {'url': 'http://169.254.169.254/2016-09-02/meta-data/instance-action', 'method': 'GET', 'headers': {'User-Agent': 'Cloud-Init/18.3-9-g2e62cb8a-0ubuntu1~16.04.2'}, 'timeout': 5.0, 'allow_redirects': True} configuration
2019-03-29 11:25:02,793 - url_helper.py[DEBUG]: Read from http://169.254.169.254/2016-09-02/meta-data/instance-action (200, 4b) after 1 attempts
2019-03-29 11:25:02,794 - url_helper.py[DEBUG]: [0/6] open 'http://169.254.169.254/2016-09-02/dynamic/instance-identity' with {'url': 'http://169.254.169.254/2016-09-02/dynamic/instance-identity', 'method': 'GET', 'headers': {'User-Agent': 'Cloud-Init/18.3-9-g2e62cb8a-0ubuntu1~16.04.2'}, 'timeout': 5.0, 'allow_redirects': True} configuration
2019-03-29 11:25:02,796 - url_helper.py[DEBUG]: Read from http://169.254.169.254/2016-09-02/dynamic/instance-identity (200, 33b) after 1 attempts
2019-03-29 11:25:02,796 - url_helper.py[DEBUG]: [0/6] open 'http://169.254.169.254/2016-09-02/dynamic/instance-identity/signature' with {'url': 'http://169.254.169.254/2016-09-02/dynamic/instance-identity/signature', 'method': 'GET', 'headers': {'User-Agent': 'Cloud-Init/18.3-9-g2e62cb8a-0ubuntu1~16.04.2'}, 'timeout': 5.0, 'allow_redirects': True} configuration
2019-03-29 11:25:02,798 - url_helper.py[DEBUG]: Read from http://169.254.169.254/2016-09-02/dynamic/instance-identity/signature (200, 174b) after 1 attempts
2019-03-29 11:25:02,798 - url_helper.py[DEBUG]: [0/6] open 'http://169.254.169.254/2016-09-02/dynamic/instance-identity/pkcs7' with {'url': 'http://169.254.169.254/2016-09-02/dynamic/instance-identity/pkcs7', 'method': 'GET', 'headers': {'User-Agent': 'Cloud-Init/18.3-9-g2e62cb8a-0ubuntu1~16.04.2'}, 'timeout': 5.0, 'allow_redirects': True} configuration
2019-03-29 11:25:02,799 - url_helper.py[DEBUG]: Read from http://169.254.169.254/2016-09-02/dynamic/instance-identity/pkcs7 (200, 1114b) after 1 attempts
2019-03-29 11:25:02,799 - url_helper.py[DEBUG]: [0/6] open 'http://169.254.169.254/2016-09-02/dynamic/instance-identity/document' with {'url': 'http://169.254.169.254/2016-09-02/dynamic/instance-identity/document', 'method': 'GET', 'headers': {'User-Agent': 'Cloud-Init/18.3-9-g2e62cb8a-0ubuntu1~16.04.2'}, 'timeout': 5.0, 'allow_redirects': True} configuration
2019-03-29 11:25:02,801 - url_helper.py[DEBUG]: Read from http://169.254.169.254/2016-09-02/dynamic/instance-identity/document (200, 475b) after 1 attempts
2019-03-29 11:25:02,801 - url_helper.py[DEBUG]: [0/6] open 'http://169.254.169.254/2016-09-02/dynamic/instance-identity/rsa2048' with {'url': 'http://169.254.169.254/2016-09-02/dynamic/instance-identity/rsa2048', 'method': 'GET', 'headers': {'User-Agent': 'Cloud-Init/18.3-9-g2e62cb8a-0ubuntu1~16.04.2'}, 'timeout': 5.0, 'allow_redirects': True} configuration
2019-03-29 11:25:02,802 - url_helper.py[DEBUG]: Read from http://169.254.169.254/2016-09-02/dynamic/instance-identity/rsa2048 (200, 1434b) after 1 attempts
2019-03-29 11:25:02,802 - util.py[DEBUG]: Crawl of metadata service took 0.107 seconds
2019-03-29 11:25:02,803 - util.py[DEBUG]: Running command ['ip', '-4', 'route', 'del', 'default', 'dev', 'ens3'] with allowed return codes [0] (shell=False, capture=True)
2019-03-29 11:25:02,804 - util.py[DEBUG]: Running command ['ip', '-family', 'inet', 'link', 'set', 'dev', 'ens3', 'down'] with allowed return codes [0] (shell=False, capture=True)
2019-03-29 11:25:02,840 - util.py[DEBUG]: Running command ['ip', '-family', 'inet', 'addr', 'del', '10.0.0.80/24', 'dev', 'ens3'] with allowed return codes [0] (shell=False, capture=True)
2019-03-29 11:25:02,844 - handlers.py[DEBUG]: finish: init-local/search-Ec2Local: SUCCESS: found local data from DataSourceEc2Local
2019-03-29 11:25:02,844 - stages.py[INFO]: Loaded datasource DataSourceEc2Local - DataSourceEc2Local
2019-03-29 11:25:02,844 - util.py[DEBUG]: Reading from /etc/cloud/cloud.cfg (quiet=False)
2019-03-29 11:25:02,844 - util.py[DEBUG]: Read 3169 bytes from /etc/cloud/cloud.cfg
2019-03-29 11:25:02,844 - util.py[DEBUG]: Attempting to load yaml from string of length 3169 with allowed root types (<class 'dict'>,)
2019-03-29 11:25:02,855 - util.py[DEBUG]: Reading from /etc/cloud/cloud.cfg.d/90_dpkg.cfg (quiet=False)
2019-03-29 11:25:02,855 - util.py[DEBUG]: Read 238 bytes from /etc/cloud/cloud.cfg.d/90_dpkg.cfg
2019-03-29 11:25:02,855 - util.py[DEBUG]: Attempting to load yaml from string of length 238 with allowed root types (<class 'dict'>,)
2019-03-29 11:25:02,856 - util.py[DEBUG]: Reading from /etc/cloud/cloud.cfg.d/05_logging.cfg (quiet=False)
2019-03-29 11:25:02,856 - util.py[DEBUG]: Read 2057 bytes from /etc/cloud/cloud.cfg.d/05_logging.cfg
2019-03-29 11:25:02,857 - util.py[DEBUG]: Attempting to load yaml from string of length 2057 with allowed root types (<class 'dict'>,)
2019-03-29 11:25:02,860 - util.py[DEBUG]: Reading from /run/cloud-init/cloud.cfg (quiet=False)
2019-03-29 11:25:02,860 - util.py[DEBUG]: Read 44 bytes from /run/cloud-init/cloud.cfg
2019-03-29 11:25:02,860 - util.py[DEBUG]: Attempting to load yaml from string of length 44 with allowed root types (<class 'dict'>,)
2019-03-29 11:25:02,860 - util.py[DEBUG]: Attempting to load yaml from string of length 0 with allowed root types (<class 'dict'>,)
2019-03-29 11:25:02,861 - util.py[DEBUG]: loaded blob returned None, returning default.
2019-03-29 11:25:02,861 - util.py[DEBUG]: Attempting to remove /var/lib/cloud/instance
2019-03-29 11:25:02,861 - util.py[DEBUG]: Creating symbolic link from '/var/lib/cloud/instance' => '/var/lib/cloud/instances/i-07999df64e41cdbe0'
2019-03-29 11:25:02,862 - util.py[DEBUG]: Reading from /var/lib/cloud/instances/i-07999df64e41cdbe0/datasource (quiet=False)
2019-03-29 11:25:02,862 - util.py[DEBUG]: Writing to /var/lib/cloud/instances/i-07999df64e41cdbe0/datasource - wb: [644] 39 bytes
2019-03-29 11:25:02,863 - util.py[DEBUG]: Writing to /var/lib/cloud/data/previous-datasource - wb: [644] 39 bytes
2019-03-29 11:25:02,863 - util.py[DEBUG]: Reading from /var/lib/cloud/data/instance-id (quiet=False)
2019-03-29 11:25:02,863 - stages.py[DEBUG]: previous iid found to be NO_PREVIOUS_INSTANCE_ID
2019-03-29 11:25:02,863 - util.py[DEBUG]: Writing to /var/lib/cloud/data/instance-id - wb: [644] 20 bytes
2019-03-29 11:25:02,863 - util.py[DEBUG]: Writing to /run/cloud-init/.instance-id - wb: [644] 20 bytes
2019-03-29 11:25:02,864 - util.py[DEBUG]: Writing to /var/lib/cloud/data/previous-instance-id - wb: [644] 24 bytes
2019-03-29 11:25:02,864 - util.py[DEBUG]: Writing to /var/lib/cloud/instance/obj.pkl - wb: [400] 9780 bytes
2019-03-29 11:25:02,865 - main.py[DEBUG]: [local] init will now be targeting instance id: i-07999df64e41cdbe0. new=True
2019-03-29 11:25:02,865 - util.py[DEBUG]: Reading from /etc/cloud/cloud.cfg (quiet=False)
2019-03-29 11:25:02,865 - util.py[DEBUG]: Read 3169 bytes from /etc/cloud/cloud.cfg
2019-03-29 11:25:02,865 - util.py[DEBUG]: Attempting to load yaml from string of length 3169 with allowed root types (<class 'dict'>,)
2019-03-29 11:25:02,875 - util.py[DEBUG]: Reading from /etc/cloud/cloud.cfg.d/90_dpkg.cfg (quiet=False)
2019-03-29 11:25:02,875 - util.py[DEBUG]: Read 238 bytes from /etc/cloud/cloud.cfg.d/90_dpkg.cfg
2019-03-29 11:25:02,875 - util.py[DEBUG]: Attempting to load yaml from string of length 238 with allowed root types (<class 'dict'>,)
2019-03-29 11:25:02,877 - util.py[DEBUG]: Reading from /etc/cloud/cloud.cfg.d/05_logging.cfg (quiet=False)
2019-03-29 11:25:02,877 - util.py[DEBUG]: Read 2057 bytes from /etc/cloud/cloud.cfg.d/05_logging.cfg
2019-03-29 11:25:02,877 - util.py[DEBUG]: Attempting to load yaml from string of length 2057 with allowed root types (<class 'dict'>,)
2019-03-29 11:25:02,880 - util.py[DEBUG]: Reading from /run/cloud-init/cloud.cfg (quiet=False)
2019-03-29 11:25:02,880 - util.py[DEBUG]: Read 44 bytes from /run/cloud-init/cloud.cfg
2019-03-29 11:25:02,880 - util.py[DEBUG]: Attempting to load yaml from string of length 44 with allowed root types (<class 'dict'>,)
2019-03-29 11:25:02,881 - util.py[DEBUG]: Attempting to load yaml from string of length 0 with allowed root types (<class 'dict'>,)
2019-03-29 11:25:02,881 - util.py[DEBUG]: loaded blob returned None, returning default.
2019-03-29 11:25:02,882 - stages.py[DEBUG]: Using distro class <class 'cloudinit.distros.ubuntu.Distro'>
2019-03-29 11:25:02,882 - cc_set_hostname.py[DEBUG]: Setting the hostname to ip-10-0-0-80.eu-west-1.compute.internal (ip-10-0-0-80)
2019-03-29 11:25:02,882 - util.py[DEBUG]: Reading from /etc/hostname (quiet=False)
2019-03-29 11:25:02,882 - util.py[DEBUG]: Read 7 bytes from /etc/hostname
2019-03-29 11:25:02,882 - util.py[DEBUG]: Writing to /etc/hostname - wb: [644] 13 bytes
2019-03-29 11:25:02,883 - __init__.py[DEBUG]: Non-persistently setting the system hostname to ip-10-0-0-80
2019-03-29 11:25:02,883 - util.py[DEBUG]: Running command ['hostname', 'ip-10-0-0-80'] with allowed return codes [0] (shell=False, capture=True)
2019-03-29 11:25:02,886 - util.py[DEBUG]: Reading from /sys/class/net/ens3/address (quiet=False)
2019-03-29 11:25:02,887 - util.py[DEBUG]: Read 18 bytes from /sys/class/net/ens3/address
2019-03-29 11:25:02,887 - stages.py[DEBUG]: applying net config names for {'config': [{'mac_address': '06:71:46:9b:71:b8', 'type': 'physical', 'subnets': [{'type': 'dhcp4'}], 'name': 'ens3'}], 'version': 1}
2019-03-29 11:25:02,887 - util.py[DEBUG]: Reading from /sys/class/net/ens3/device/device (quiet=False)
2019-03-29 11:25:02,887 - util.py[DEBUG]: Read 7 bytes from /sys/class/net/ens3/device/device
2019-03-29 11:25:02,887 - util.py[DEBUG]: Reading from /sys/class/net/lo/addr_assign_type (quiet=False)
2019-03-29 11:25:02,887 - util.py[DEBUG]: Read 2 bytes from /sys/class/net/lo/addr_assign_type
2019-03-29 11:25:02,887 - util.py[DEBUG]: Reading from /sys/class/net/lo/uevent (quiet=False)
2019-03-29 11:25:02,887 - util.py[DEBUG]: Read 23 bytes from /sys/class/net/lo/uevent
2019-03-29 11:25:02,887 - util.py[DEBUG]: Reading from /sys/class/net/lo/address (quiet=False)
2019-03-29 11:25:02,887 - util.py[DEBUG]: Read 18 bytes from /sys/class/net/lo/address
2019-03-29 11:25:02,888 - util.py[DEBUG]: Reading from /sys/class/net/lo/device/device (quiet=False)
2019-03-29 11:25:02,888 - util.py[DEBUG]: Reading from /sys/class/net/ens3/addr_assign_type (quiet=False)
2019-03-29 11:25:02,888 - util.py[DEBUG]: Read 2 bytes from /sys/class/net/ens3/addr_assign_type
2019-03-29 11:25:02,888 - util.py[DEBUG]: Reading from /sys/class/net/ens3/uevent (quiet=False)
2019-03-29 11:25:02,888 - util.py[DEBUG]: Read 25 bytes from /sys/class/net/ens3/uevent
2019-03-29 11:25:02,888 - util.py[DEBUG]: Reading from /sys/class/net/ens3/address (quiet=False)
2019-03-29 11:25:02,888 - util.py[DEBUG]: Read 18 bytes from /sys/class/net/ens3/address
2019-03-29 11:25:02,888 - util.py[DEBUG]: Reading from /sys/class/net/ens3/device/device (quiet=False)
2019-03-29 11:25:02,888 - util.py[DEBUG]: Read 7 bytes from /sys/class/net/ens3/device/device
2019-03-29 11:25:02,888 - util.py[DEBUG]: Reading from /sys/class/net/lo/operstate (quiet=False)
2019-03-29 11:25:02,888 - util.py[DEBUG]: Read 8 bytes from /sys/class/net/lo/operstate
2019-03-29 11:25:02,888 - util.py[DEBUG]: Reading from /sys/class/net/ens3/operstate (quiet=False)
2019-03-29 11:25:02,888 - util.py[DEBUG]: Read 5 bytes from /sys/class/net/ens3/operstate
2019-03-29 11:25:02,888 - util.py[DEBUG]: Running command ['ip', '-6', 'addr', 'show', 'permanent', 'scope', 'global'] with allowed return codes [0] (shell=False, capture=True)
2019-03-29 11:25:02,891 - util.py[DEBUG]: Running command ['ip', '-4', 'addr', 'show'] with allowed return codes [0] (shell=False, capture=True)
2019-03-29 11:25:02,893 - __init__.py[DEBUG]: no work necessary for renaming of [['06:71:46:9b:71:b8', 'ens3', 'ixgbevf', '0x10ed']]
2019-03-29 11:25:02,893 - stages.py[INFO]: Applying network configuration from ds bringup=False: {'config': [{'mac_address': '06:71:46:9b:71:b8', 'type': 'physical', 'subnets': [{'type': 'dhcp4'}], 'name': 'ens3'}], 'version': 1}
2019-03-29 11:25:02,893 - __init__.py[DEBUG]: Selected renderer 'eni' from priority list: None
2019-03-29 11:25:02,895 - util.py[DEBUG]: Writing to /etc/network/interfaces.d/50-cloud-init.cfg - wb: [644] 367 bytes
2019-03-29 11:25:02,896 - util.py[DEBUG]: Writing to /etc/udev/rules.d/70-persistent-net.rules - wb: [644] 96 bytes
2019-03-29 11:25:02,896 - main.py[DEBUG]: [local] Exiting. datasource DataSourceEc2Local not in local mode.
2019-03-29 11:25:02,897 - util.py[DEBUG]: Reading from /proc/uptime (quiet=False)
2019-03-29 11:25:02,897 - util.py[DEBUG]: Read 12 bytes from /proc/uptime
2019-03-29 11:25:02,897 - util.py[DEBUG]: cloud-init mode 'init' took 0.654 seconds (0.65)
2019-03-29 11:25:02,897 - handlers.py[DEBUG]: finish: init-local: SUCCESS: searching for local datasources
2019-03-29 11:25:03,411 - util.py[DEBUG]: Cloud-init v. 18.3-9-g2e62cb8a-0ubuntu1~16.04.2 running 'init' at Fri, 29 Mar 2019 11:25:03 +0000. Up 8.88 seconds.
2019-03-29 11:25:03,411 - main.py[DEBUG]: No kernel command line url found.
2019-03-29 11:25:03,411 - main.py[DEBUG]: Closing stdin.
2019-03-29 11:25:03,413 - util.py[DEBUG]: Writing to /var/log/cloud-init.log - ab: [644] 0 bytes
2019-03-29 11:25:03,413 - util.py[DEBUG]: Changing the ownership of /var/log/cloud-init.log to 104:4
2019-03-29 11:25:03,413 - util.py[DEBUG]: Running command ['ip', 'addr', 'show'] with allowed return codes [0] (shell=False, capture=True)
2019-03-29 11:25:03,416 - util.py[DEBUG]: Running command ['ip', '-o', 'route', 'list'] with allowed return codes [0] (shell=False, capture=True)
2019-03-29 11:25:03,418 - util.py[DEBUG]: Running command ['ip', '--oneline', '-6', 'route', 'list', 'table', 'all'] with allowed return codes [0, 1] (shell=False, capture=True)
2019-03-29 11:25:03,422 - main.py[DEBUG]: Checking to see if files that we need already exist from a previous run that would allow us to stop early.
2019-03-29 11:25:03,422 - main.py[DEBUG]: Execution continuing, no previous run detected that would allow us to stop early.
2019-03-29 11:25:03,422 - handlers.py[DEBUG]: start: init-network/check-cache: attempting to read from cache [trust]
2019-03-29 11:25:03,422 - util.py[DEBUG]: Reading from /var/lib/cloud/instance/obj.pkl (quiet=False)
2019-03-29 11:25:03,422 - util.py[DEBUG]: Read 9780 bytes from /var/lib/cloud/instance/obj.pkl
2019-03-29 11:25:03,424 - util.py[DEBUG]: Reading from /run/cloud-init/.instance-id (quiet=False)
2019-03-29 11:25:03,424 - util.py[DEBUG]: Read 20 bytes from /run/cloud-init/.instance-id
2019-03-29 11:25:03,424 - stages.py[DEBUG]: restored from cache with run check: DataSourceEc2Local
2019-03-29 11:25:03,425 - handlers.py[DEBUG]: finish: init-network/check-cache: SUCCESS: restored from cache with run check: DataSourceEc2Local
2019-03-29 11:25:03,425 - util.py[DEBUG]: Reading from /etc/cloud/cloud.cfg (quiet=False)
2019-03-29 11:25:03,425 - util.py[DEBUG]: Read 3169 bytes from /etc/cloud/cloud.cfg
2019-03-29 11:25:03,425 - util.py[DEBUG]: Attempting to load yaml from string of length 3169 with allowed root types (<class 'dict'>,)
2019-03-29 11:25:03,435 - util.py[DEBUG]: Reading from /etc/cloud/cloud.cfg.d/90_dpkg.cfg (quiet=False)
2019-03-29 11:25:03,436 - util.py[DEBUG]: Read 238 bytes from /etc/cloud/cloud.cfg.d/90_dpkg.cfg
2019-03-29 11:25:03,436 - util.py[DEBUG]: Attempting to load yaml from string of length 238 with allowed root types (<class 'dict'>,)
2019-03-29 11:25:03,437 - util.py[DEBUG]: Reading from /etc/cloud/cloud.cfg.d/05_logging.cfg (quiet=False)
2019-03-29 11:25:03,437 - util.py[DEBUG]: Read 2057 bytes from /etc/cloud/cloud.cfg.d/05_logging.cfg
2019-03-29 11:25:03,437 - util.py[DEBUG]: Attempting to load yaml from string of length 2057 with allowed root types (<class 'dict'>,)
2019-03-29 11:25:03,440 - util.py[DEBUG]: Reading from /run/cloud-init/cloud.cfg (quiet=False)
2019-03-29 11:25:03,440 - util.py[DEBUG]: Read 44 bytes from /run/cloud-init/cloud.cfg
2019-03-29 11:25:03,440 - util.py[DEBUG]: Attempting to load yaml from string of length 44 with allowed root types (<class 'dict'>,)
2019-03-29 11:25:03,441 - util.py[DEBUG]: Attempting to load yaml from string of length 0 with allowed root types (<class 'dict'>,)
2019-03-29 11:25:03,441 - util.py[DEBUG]: loaded blob returned None, returning default.
2019-03-29 11:25:03,441 - util.py[DEBUG]: Attempting to remove /var/lib/cloud/instance
2019-03-29 11:25:03,442 - util.py[DEBUG]: Creating symbolic link from '/var/lib/cloud/instance' => '/var/lib/cloud/instances/i-07999df64e41cdbe0'
2019-03-29 11:25:03,442 - util.py[DEBUG]: Reading from /var/lib/cloud/instances/i-07999df64e41cdbe0/datasource (quiet=False)
2019-03-29 11:25:03,442 - util.py[DEBUG]: Read 39 bytes from /var/lib/cloud/instances/i-07999df64e41cdbe0/datasource
2019-03-29 11:25:03,442 - util.py[DEBUG]: Writing to /var/lib/cloud/instances/i-07999df64e41cdbe0/datasource - wb: [644] 39 bytes
2019-03-29 11:25:03,443 - util.py[DEBUG]: Writing to /var/lib/cloud/data/previous-datasource - wb: [644] 39 bytes
2019-03-29 11:25:03,443 - util.py[DEBUG]: Reading from /var/lib/cloud/data/instance-id (quiet=False)
2019-03-29 11:25:03,443 - util.py[DEBUG]: Read 20 bytes from /var/lib/cloud/data/instance-id
2019-03-29 11:25:03,443 - stages.py[DEBUG]: previous iid found to be i-07999df64e41cdbe0
2019-03-29 11:25:03,443 - util.py[DEBUG]: Writing to /var/lib/cloud/data/instance-id - wb: [644] 20 bytes
2019-03-29 11:25:03,443 - util.py[DEBUG]: Writing to /run/cloud-init/.instance-id - wb: [644] 20 bytes
2019-03-29 11:25:03,444 - util.py[DEBUG]: Writing to /var/lib/cloud/data/previous-instance-id - wb: [644] 20 bytes
2019-03-29 11:25:03,444 - util.py[DEBUG]: Writing to /var/lib/cloud/instance/obj.pkl - wb: [400] 9859 bytes
2019-03-29 11:25:03,445 - main.py[DEBUG]: [net] init will now be targeting instance id: i-07999df64e41cdbe0. new=False
2019-03-29 11:25:03,445 - util.py[DEBUG]: Reading from /etc/cloud/cloud.cfg (quiet=False)
2019-03-29 11:25:03,445 - util.py[DEBUG]: Read 3169 bytes from /etc/cloud/cloud.cfg
2019-03-29 11:25:03,445 - util.py[DEBUG]: Attempting to load yaml from string of length 3169 with allowed root types (<class 'dict'>,)
2019-03-29 11:25:03,455 - util.py[DEBUG]: Reading from /etc/cloud/cloud.cfg.d/90_dpkg.cfg (quiet=False)
2019-03-29 11:25:03,455 - util.py[DEBUG]: Read 238 bytes from /etc/cloud/cloud.cfg.d/90_dpkg.cfg
2019-03-29 11:25:03,455 - util.py[DEBUG]: Attempting to load yaml from string of length 238 with allowed root types (<class 'dict'>,)
2019-03-29 11:25:03,456 - util.py[DEBUG]: Reading from /etc/cloud/cloud.cfg.d/05_logging.cfg (quiet=False)
2019-03-29 11:25:03,456 - util.py[DEBUG]: Read 2057 bytes from /etc/cloud/cloud.cfg.d/05_logging.cfg
2019-03-29 11:25:03,456 - util.py[DEBUG]: Attempting to load yaml from string of length 2057 with allowed root types (<class 'dict'>,)
2019-03-29 11:25:03,460 - util.py[DEBUG]: Reading from /run/cloud-init/cloud.cfg (quiet=False)
2019-03-29 11:25:03,460 - util.py[DEBUG]: Read 44 bytes from /run/cloud-init/cloud.cfg
2019-03-29 11:25:03,460 - util.py[DEBUG]: Attempting to load yaml from string of length 44 with allowed root types (<class 'dict'>,)
2019-03-29 11:25:03,460 - util.py[DEBUG]: Attempting to load yaml from string of length 0 with allowed root types (<class 'dict'>,)
2019-03-29 11:25:03,460 - util.py[DEBUG]: loaded blob returned None, returning default.
2019-03-29 11:25:03,461 - util.py[DEBUG]: Reading from /sys/class/net/ens3/address (quiet=False)
2019-03-29 11:25:03,461 - util.py[DEBUG]: Read 18 bytes from /sys/class/net/ens3/address
2019-03-29 11:25:03,461 - stages.py[DEBUG]: applying net config names for {'config': [{'subnets': [{'type': 'dhcp4'}], 'type': 'physical', 'name': 'ens3', 'mac_address': '06:71:46:9b:71:b8'}], 'version': 1}
2019-03-29 11:25:03,462 - stages.py[DEBUG]: Using distro class <class 'cloudinit.distros.ubuntu.Distro'>
2019-03-29 11:25:03,462 - util.py[DEBUG]: Reading from /sys/class/net/ens3/device/device (quiet=False)
2019-03-29 11:25:03,462 - util.py[DEBUG]: Read 7 bytes from /sys/class/net/ens3/device/device
2019-03-29 11:25:03,462 - util.py[DEBUG]: Reading from /sys/class/net/lo/addr_assign_type (quiet=False)
2019-03-29 11:25:03,462 - util.py[DEBUG]: Read 2 bytes from /sys/class/net/lo/addr_assign_type
2019-03-29 11:25:03,462 - util.py[DEBUG]: Reading from /sys/class/net/lo/uevent (quiet=False)
2019-03-29 11:25:03,462 - util.py[DEBUG]: Read 23 bytes from /sys/class/net/lo/uevent
2019-03-29 11:25:03,462 - util.py[DEBUG]: Reading from /sys/class/net/lo/address (quiet=False)
2019-03-29 11:25:03,462 - util.py[DEBUG]: Read 18 bytes from /sys/class/net/lo/address
2019-03-29 11:25:03,463 - util.py[DEBUG]: Reading from /sys/class/net/lo/device/device (quiet=False)
2019-03-29 11:25:03,463 - util.py[DEBUG]: Reading from /sys/class/net/ens3/addr_assign_type (quiet=False)
2019-03-29 11:25:03,463 - util.py[DEBUG]: Read 2 bytes from /sys/class/net/ens3/addr_assign_type
2019-03-29 11:25:03,463 - util.py[DEBUG]: Reading from /sys/class/net/ens3/uevent (quiet=False)
2019-03-29 11:25:03,463 - util.py[DEBUG]: Read 25 bytes from /sys/class/net/ens3/uevent
2019-03-29 11:25:03,463 - util.py[DEBUG]: Reading from /sys/class/net/ens3/address (quiet=False)
2019-03-29 11:25:03,463 - util.py[DEBUG]: Read 18 bytes from /sys/class/net/ens3/address
2019-03-29 11:25:03,463 - util.py[DEBUG]: Reading from /sys/class/net/ens3/device/device (quiet=False)
2019-03-29 11:25:03,463 - util.py[DEBUG]: Read 7 bytes from /sys/class/net/ens3/device/device
2019-03-29 11:25:03,463 - util.py[DEBUG]: Reading from /sys/class/net/lo/operstate (quiet=False)
2019-03-29 11:25:03,463 - util.py[DEBUG]: Read 8 bytes from /sys/class/net/lo/operstate
2019-03-29 11:25:03,463 - util.py[DEBUG]: Reading from /sys/class/net/ens3/operstate (quiet=False)
2019-03-29 11:25:03,463 - util.py[DEBUG]: Read 3 bytes from /sys/class/net/ens3/operstate
2019-03-29 11:25:03,463 - util.py[DEBUG]: Running command ['ip', '-6', 'addr', 'show', 'permanent', 'scope', 'global'] with allowed return codes [0] (shell=False, capture=True)
2019-03-29 11:25:03,465 - util.py[DEBUG]: Running command ['ip', '-4', 'addr', 'show'] with allowed return codes [0] (shell=False, capture=True)
2019-03-29 11:25:03,467 - __init__.py[DEBUG]: no work necessary for renaming of [['06:71:46:9b:71:b8', 'ens3', 'ixgbevf', '0x10ed']]
2019-03-29 11:25:03,467 - stages.py[DEBUG]: No network config applied. Neither a new instance nor datasource network update on 'System boot' event
2019-03-29 11:25:03,467 - handlers.py[DEBUG]: start: init-network/setup-datasource: setting up datasource
2019-03-29 11:25:03,467 - handlers.py[DEBUG]: finish: init-network/setup-datasource: SUCCESS: setting up datasource
2019-03-29 11:25:03,467 - util.py[DEBUG]: Writing to /var/lib/cloud/instances/i-07999df64e41cdbe0/user-data.txt - wb: [600] 0 bytes
2019-03-29 11:25:03,470 - util.py[DEBUG]: Writing to /var/lib/cloud/instances/i-07999df64e41cdbe0/user-data.txt.i - wb: [600] 308 bytes
2019-03-29 11:25:03,470 - util.py[DEBUG]: Writing to /var/lib/cloud/instances/i-07999df64e41cdbe0/vendor-data.txt - wb: [600] 0 bytes
2019-03-29 11:25:03,471 - util.py[DEBUG]: Writing to /var/lib/cloud/instances/i-07999df64e41cdbe0/vendor-data.txt.i - wb: [600] 308 bytes
2019-03-29 11:25:03,472 - util.py[DEBUG]: Reading from /var/lib/cloud/data/set-hostname (quiet=False)
2019-03-29 11:25:03,472 - util.py[DEBUG]: Read 84 bytes from /var/lib/cloud/data/set-hostname
2019-03-29 11:25:03,472 - cc_set_hostname.py[DEBUG]: No hostname changes. Skipping set-hostname
2019-03-29 11:25:03,473 - util.py[DEBUG]: Writing to /var/lib/cloud/instances/i-07999df64e41cdbe0/sem/consume_data - wb: [644] 25 bytes
2019-03-29 11:25:03,473 - helpers.py[DEBUG]: Running consume_data using lock (<FileLock using file '/var/lib/cloud/instances/i-07999df64e41cdbe0/sem/consume_data'>)
2019-03-29 11:25:03,473 - handlers.py[DEBUG]: start: init-network/consume-user-data: reading and applying user-data
2019-03-29 11:25:03,473 - launch_index.py[DEBUG]: Discarding 0 multipart messages which do not match launch index 0
2019-03-29 11:25:03,474 - stages.py[DEBUG]: Added default handler for {'text/cloud-config', 'text/cloud-config-jsonp'} from CloudConfigPartHandler: [['text/cloud-config', 'text/cloud-config-jsonp']]
2019-03-29 11:25:03,474 - stages.py[DEBUG]: Added default handler for {'text/x-shellscript'} from ShellScriptPartHandler: [['text/x-shellscript']]
2019-03-29 11:25:03,474 - stages.py[DEBUG]: Added default handler for {'text/cloud-boothook'} from BootHookPartHandler: [['text/cloud-boothook']]
2019-03-29 11:25:03,474 - stages.py[DEBUG]: Added default handler for {'text/upstart-job'} from UpstartJobPartHandler: [['text/upstart-job']]
2019-03-29 11:25:03,474 - __init__.py[DEBUG]: Calling handler BootHookPartHandler: [['text/cloud-boothook']] (__begin__, None, 2) with frequency once-per-instance
2019-03-29 11:25:03,474 - __init__.py[DEBUG]: Calling handler CloudConfigPartHandler: [['text/cloud-config', 'text/cloud-config-jsonp']] (__begin__, None, 3) with frequency once-per-instance
2019-03-29 11:25:03,474 - __init__.py[DEBUG]: Calling handler UpstartJobPartHandler: [['text/upstart-job']] (__begin__, None, 2) with frequency once-per-instance
2019-03-29 11:25:03,474 - __init__.py[DEBUG]: Calling handler ShellScriptPartHandler: [['text/x-shellscript']] (__begin__, None, 2) with frequency once-per-instance
2019-03-29 11:25:03,474 - __init__.py[DEBUG]: {'MIME-Version': '1.0', 'Content-Type': 'text/x-not-multipart', 'Content-Disposition': 'attachment; filename="part-001"'}
2019-03-29 11:25:03,475 - __init__.py[DEBUG]: Empty payload of type text/x-not-multipart
2019-03-29 11:25:03,475 - __init__.py[DEBUG]: Calling handler BootHookPartHandler: [['text/cloud-boothook']] (__end__, None, 2) with frequency once-per-instance
2019-03-29 11:25:03,475 - __init__.py[DEBUG]: Calling handler CloudConfigPartHandler: [['text/cloud-config', 'text/cloud-config-jsonp']] (__end__, None, 3) with frequency once-per-instance
2019-03-29 11:25:03,475 - util.py[DEBUG]: Writing to /var/lib/cloud/instances/i-07999df64e41cdbe0/cloud-config.txt - wb: [600] 0 bytes
2019-03-29 11:25:03,475 - __init__.py[DEBUG]: Calling handler UpstartJobPartHandler: [['text/upstart-job']] (__end__, None, 2) with frequency once-per-instance
2019-03-29 11:25:03,475 - __init__.py[DEBUG]: Calling handler ShellScriptPartHandler: [['text/x-shellscript']] (__end__, None, 2) with frequency once-per-instance
2019-03-29 11:25:03,475 - handlers.py[DEBUG]: finish: init-network/consume-user-data: SUCCESS: reading and applying user-data
2019-03-29 11:25:03,475 - handlers.py[DEBUG]: start: init-network/consume-vendor-data: reading and applying vendor-data
2019-03-29 11:25:03,475 - stages.py[DEBUG]: no vendordata from datasource
2019-03-29 11:25:03,476 - handlers.py[DEBUG]: finish: init-network/consume-vendor-data: SUCCESS: reading and applying vendor-data
2019-03-29 11:25:03,476 - util.py[DEBUG]: Reading from /etc/cloud/cloud.cfg (quiet=False)
2019-03-29 11:25:03,476 - util.py[DEBUG]: Read 3169 bytes from /etc/cloud/cloud.cfg
2019-03-29 11:25:03,476 - util.py[DEBUG]: Attempting to load yaml from string of length 3169 with allowed root types (<class 'dict'>,)
2019-03-29 11:25:03,486 - util.py[DEBUG]: Reading from /etc/cloud/cloud.cfg.d/90_dpkg.cfg (quiet=False)
2019-03-29 11:25:03,486 - util.py[DEBUG]: Read 238 bytes from /etc/cloud/cloud.cfg.d/90_dpkg.cfg
2019-03-29 11:25:03,486 - util.py[DEBUG]: Attempting to load yaml from string of length 238 with allowed root types (<class 'dict'>,)
2019-03-29 11:25:03,487 - util.py[DEBUG]: Reading from /etc/cloud/cloud.cfg.d/05_logging.cfg (quiet=False)
2019-03-29 11:25:03,487 - util.py[DEBUG]: Read 2057 bytes from /etc/cloud/cloud.cfg.d/05_logging.cfg
2019-03-29 11:25:03,487 - util.py[DEBUG]: Attempting to load yaml from string of length 2057 with allowed root types (<class 'dict'>,)
2019-03-29 11:25:03,491 - util.py[DEBUG]: Reading from /run/cloud-init/cloud.cfg (quiet=False)
2019-03-29 11:25:03,491 - util.py[DEBUG]: Read 44 bytes from /run/cloud-init/cloud.cfg
2019-03-29 11:25:03,491 - util.py[DEBUG]: Attempting to load yaml from string of length 44 with allowed root types (<class 'dict'>,)
2019-03-29 11:25:03,491 - util.py[DEBUG]: Attempting to load yaml from string of length 0 with allowed root types (<class 'dict'>,)
2019-03-29 11:25:03,491 - util.py[DEBUG]: loaded blob returned None, returning default.
2019-03-29 11:25:03,492 - util.py[DEBUG]: Reading from /var/lib/cloud/instance/cloud-config.txt (quiet=False)
2019-03-29 11:25:03,492 - util.py[DEBUG]: Read 0 bytes from /var/lib/cloud/instance/cloud-config.txt
2019-03-29 11:25:03,492 - util.py[DEBUG]: Attempting to load yaml from string of length 0 with allowed root types (<class 'dict'>,)
2019-03-29 11:25:03,492 - util.py[DEBUG]: loaded blob returned None, returning default.
2019-03-29 11:25:03,492 - util.py[DEBUG]: Reading from /var/lib/cloud/instance/cloud-config.txt (quiet=False)
2019-03-29 11:25:03,492 - util.py[DEBUG]: Read 0 bytes from /var/lib/cloud/instance/cloud-config.txt
2019-03-29 11:25:03,492 - util.py[DEBUG]: Attempting to load yaml from string of length 0 with allowed root types (<class 'dict'>,)
2019-03-29 11:25:03,493 - util.py[DEBUG]: loaded blob returned None, returning default.
2019-03-29 11:25:03,494 - handlers.py[DEBUG]: start: init-network/activate-datasource: activating datasource
2019-03-29 11:25:03,494 - util.py[DEBUG]: Writing to /var/lib/cloud/instance/obj.pkl - wb: [400] 9187 bytes
2019-03-29 11:25:03,495 - handlers.py[DEBUG]: finish: init-network/activate-datasource: SUCCESS: activating datasource
2019-03-29 11:25:03,495 - main.py[DEBUG]: used datasource 'DataSourceEc2Local' from 'Ec2' was in di_report's list: ['Ec2', 'None']
2019-03-29 11:25:03,599 - stages.py[DEBUG]: Using distro class <class 'cloudinit.distros.ubuntu.Distro'>
2019-03-29 11:25:03,600 - stages.py[DEBUG]: Running module migrator (<module 'cloudinit.config.cc_migrator' from '/usr/lib/python3/dist-packages/cloudinit/config/cc_migrator.py'>) with frequency always
2019-03-29 11:25:03,600 - handlers.py[DEBUG]: start: init-network/config-migrator: running config-migrator with frequency always
2019-03-29 11:25:03,600 - helpers.py[DEBUG]: Running config-migrator using lock (<cloudinit.helpers.DummyLock object at 0x7f71dad0cf60>)
2019-03-29 11:25:03,600 - cc_migrator.py[DEBUG]: Migrated 0 semaphore files to there canonicalized names
2019-03-29 11:25:03,601 - handlers.py[DEBUG]: finish: init-network/config-migrator: SUCCESS: config-migrator ran successfully
2019-03-29 11:25:03,601 - stages.py[DEBUG]: Running module seed_random (<module 'cloudinit.config.cc_seed_random' from '/usr/lib/python3/dist-packages/cloudinit/config/cc_seed_random.py'>) with frequency once-per-instance
2019-03-29 11:25:03,601 - handlers.py[DEBUG]: start: init-network/config-seed_random: running config-seed_random with frequency once-per-instance
2019-03-29 11:25:03,601 - util.py[DEBUG]: Writing to /var/lib/cloud/instances/i-07999df64e41cdbe0/sem/config_seed_random - wb: [644] 25 bytes
2019-03-29 11:25:03,601 - helpers.py[DEBUG]: Running config-seed_random using lock (<FileLock using file '/var/lib/cloud/instances/i-07999df64e41cdbe0/sem/config_seed_random'>)
2019-03-29 11:25:03,602 - cc_seed_random.py[DEBUG]: no command provided
2019-03-29 11:25:03,602 - handlers.py[DEBUG]: finish: init-network/config-seed_random: SUCCESS: config-seed_random ran successfully
2019-03-29 11:25:03,602 - stages.py[DEBUG]: Running module bootcmd (<module 'cloudinit.config.cc_bootcmd' from '/usr/lib/python3/dist-packages/cloudinit/config/cc_bootcmd.py'>) with frequency always
2019-03-29 11:25:03,602 - handlers.py[DEBUG]: start: init-network/config-bootcmd: running config-bootcmd with frequency always
2019-03-29 11:25:03,602 - helpers.py[DEBUG]: Running config-bootcmd using lock (<cloudinit.helpers.DummyLock object at 0x7f71dad02d30>)
2019-03-29 11:25:03,602 - cc_bootcmd.py[DEBUG]: Skipping module named bootcmd, no 'bootcmd' key in configuration
2019-03-29 11:25:03,602 - handlers.py[DEBUG]: finish: init-network/config-bootcmd: SUCCESS: config-bootcmd ran successfully
2019-03-29 11:25:03,602 - stages.py[DEBUG]: Running module write-files (<module 'cloudinit.config.cc_write_files' from '/usr/lib/python3/dist-packages/cloudinit/config/cc_write_files.py'>) with frequency once-per-instance
2019-03-29 11:25:03,602 - handlers.py[DEBUG]: start: init-network/config-write-files: running config-write-files with frequency once-per-instance
2019-03-29 11:25:03,602 - util.py[DEBUG]: Writing to /var/lib/cloud/instances/i-07999df64e41cdbe0/sem/config_write_files - wb: [644] 25 bytes
2019-03-29 11:25:03,603 - helpers.py[DEBUG]: Running config-write-files using lock (<FileLock using file '/var/lib/cloud/instances/i-07999df64e41cdbe0/sem/config_write_files'>)
2019-03-29 11:25:03,603 - cc_write_files.py[DEBUG]: Skipping module named write-files, no/empty 'write_files' key in configuration
2019-03-29 11:25:03,603 - handlers.py[DEBUG]: finish: init-network/config-write-files: SUCCESS: config-write-files ran successfully
2019-03-29 11:25:03,603 - stages.py[DEBUG]: Running module growpart (<module 'cloudinit.config.cc_growpart' from '/usr/lib/python3/dist-packages/cloudinit/config/cc_growpart.py'>) with frequency always
2019-03-29 11:25:03,603 - handlers.py[DEBUG]: start: init-network/config-growpart: running config-growpart with frequency always
2019-03-29 11:25:03,603 - helpers.py[DEBUG]: Running config-growpart using lock (<cloudinit.helpers.DummyLock object at 0x7f71dad02080>)
2019-03-29 11:25:03,603 - cc_growpart.py[DEBUG]: No 'growpart' entry in cfg.  Using default: {'ignore_growroot_disabled': False, 'mode': 'auto', 'devices': ['/']}
2019-03-29 11:25:03,603 - util.py[DEBUG]: Running command ['growpart', '--help'] with allowed return codes [0] (shell=False, capture=True)
2019-03-29 11:25:03,623 - util.py[DEBUG]: Reading from /proc/1324/mountinfo (quiet=False)
2019-03-29 11:25:03,623 - util.py[DEBUG]: Read 2627 bytes from /proc/1324/mountinfo
2019-03-29 11:25:03,623 - util.py[DEBUG]: Running command ['systemd-detect-virt', '--quiet', '--container'] with allowed return codes [0] (shell=False, capture=True)
2019-03-29 11:25:03,625 - util.py[DEBUG]: Running command ['running-in-container'] with allowed return codes [0] (shell=False, capture=True)
2019-03-29 11:25:03,627 - util.py[DEBUG]: Running command ['lxc-is-container'] with allowed return codes [0] (shell=False, capture=True)
2019-03-29 11:25:03,629 - util.py[DEBUG]: Reading from /proc/1/environ (quiet=False)
2019-03-29 11:25:03,629 - util.py[DEBUG]: Read 150 bytes from /proc/1/environ
2019-03-29 11:25:03,629 - util.py[DEBUG]: Reading from /proc/self/status (quiet=False)
2019-03-29 11:25:03,629 - util.py[DEBUG]: Read 971 bytes from /proc/self/status
2019-03-29 11:25:03,632 - util.py[DEBUG]: Reading from /etc/os-release (quiet=False)
2019-03-29 11:25:03,632 - util.py[DEBUG]: Read 298 bytes from /etc/os-release
2019-03-29 11:25:03,632 - util.py[DEBUG]: Reading from /sys/class/block/xvda1/partition (quiet=False)
2019-03-29 11:25:03,632 - util.py[DEBUG]: Read 2 bytes from /sys/class/block/xvda1/partition
2019-03-29 11:25:03,632 - util.py[DEBUG]: Reading from /sys/devices/vbd-768/block/xvda/dev (quiet=False)
2019-03-29 11:25:03,632 - util.py[DEBUG]: Read 6 bytes from /sys/devices/vbd-768/block/xvda/dev
2019-03-29 11:25:03,632 - util.py[DEBUG]: Running command ['growpart', '--dry-run', '/dev/xvda', '1'] with allowed return codes [0] (shell=False, capture=True)
2019-03-29 11:25:03,770 - util.py[DEBUG]: Running command ['growpart', '/dev/xvda', '1'] with allowed return codes [0] (shell=False, capture=True)
2019-03-29 11:25:03,834 - util.py[DEBUG]: resize_devices took 0.211 seconds
2019-03-29 11:25:03,834 - cc_growpart.py[INFO]: '/' resized: changed (/dev/xvda, 1) from 8588869120 to 107373116928
2019-03-29 11:25:03,834 - handlers.py[DEBUG]: finish: init-network/config-growpart: SUCCESS: config-growpart ran successfully
2019-03-29 11:25:03,834 - stages.py[DEBUG]: Running module resizefs (<module 'cloudinit.config.cc_resizefs' from '/usr/lib/python3/dist-packages/cloudinit/config/cc_resizefs.py'>) with frequency always
2019-03-29 11:25:03,835 - handlers.py[DEBUG]: start: init-network/config-resizefs: running config-resizefs with frequency always
2019-03-29 11:25:03,835 - helpers.py[DEBUG]: Running config-resizefs using lock (<cloudinit.helpers.DummyLock object at 0x7f71dad0ef28>)
2019-03-29 11:25:03,835 - schema.py[DEBUG]: Ignoring schema validation. python-jsonschema is not present
2019-03-29 11:25:03,835 - util.py[DEBUG]: Reading from /proc/1324/mountinfo (quiet=False)
2019-03-29 11:25:03,835 - util.py[DEBUG]: Read 2627 bytes from /proc/1324/mountinfo
2019-03-29 11:25:03,835 - cc_resizefs.py[DEBUG]: resize_info: dev=/dev/xvda1 mnt_point=/ path=/
2019-03-29 11:25:03,835 - util.py[DEBUG]: Running command ['systemd-detect-virt', '--quiet', '--container'] with allowed return codes [0] (shell=False, capture=True)
2019-03-29 11:25:03,838 - util.py[DEBUG]: Running command ['running-in-container'] with allowed return codes [0] (shell=False, capture=True)
2019-03-29 11:25:03,839 - util.py[DEBUG]: Running command ['lxc-is-container'] with allowed return codes [0] (shell=False, capture=True)
2019-03-29 11:25:03,841 - util.py[DEBUG]: Reading from /proc/1/environ (quiet=False)
2019-03-29 11:25:03,841 - util.py[DEBUG]: Read 150 bytes from /proc/1/environ
2019-03-29 11:25:03,842 - util.py[DEBUG]: Reading from /proc/self/status (quiet=False)
2019-03-29 11:25:03,842 - util.py[DEBUG]: Read 972 bytes from /proc/self/status
2019-03-29 11:25:03,842 - cc_resizefs.py[DEBUG]: Resizing / (ext4) using resize2fs /dev/xvda1
2019-03-29 11:25:03,842 - util.py[DEBUG]: Running command ('resize2fs', '/dev/xvda1') with allowed return codes [0] (shell=False, capture=True)
2019-03-29 11:25:03,961 - util.py[DEBUG]: Resizing took 0.119 seconds
2019-03-29 11:25:03,961 - cc_resizefs.py[DEBUG]: Resized root filesystem (type=ext4, val=True)
2019-03-29 11:25:03,961 - handlers.py[DEBUG]: finish: init-network/config-resizefs: SUCCESS: config-resizefs ran successfully
2019-03-29 11:25:03,961 - stages.py[DEBUG]: Running module disk_setup (<module 'cloudinit.config.cc_disk_setup' from '/usr/lib/python3/dist-packages/cloudinit/config/cc_disk_setup.py'>) with frequency once-per-instance
2019-03-29 11:25:03,962 - handlers.py[DEBUG]: start: init-network/config-disk_setup: running config-disk_setup with frequency once-per-instance
2019-03-29 11:25:03,962 - util.py[DEBUG]: Writing to /var/lib/cloud/instances/i-07999df64e41cdbe0/sem/config_disk_setup - wb: [644] 25 bytes
2019-03-29 11:25:03,962 - helpers.py[DEBUG]: Running config-disk_setup using lock (<FileLock using file '/var/lib/cloud/instances/i-07999df64e41cdbe0/sem/config_disk_setup'>)
2019-03-29 11:25:03,963 - handlers.py[DEBUG]: finish: init-network/config-disk_setup: SUCCESS: config-disk_setup ran successfully
2019-03-29 11:25:03,963 - stages.py[DEBUG]: Running module mounts (<module 'cloudinit.config.cc_mounts' from '/usr/lib/python3/dist-packages/cloudinit/config/cc_mounts.py'>) with frequency once-per-instance
2019-03-29 11:25:03,963 - handlers.py[DEBUG]: start: init-network/config-mounts: running config-mounts with frequency once-per-instance
2019-03-29 11:25:03,963 - util.py[DEBUG]: Writing to /var/lib/cloud/instances/i-07999df64e41cdbe0/sem/config_mounts - wb: [644] 25 bytes
2019-03-29 11:25:03,963 - helpers.py[DEBUG]: Running config-mounts using lock (<FileLock using file '/var/lib/cloud/instances/i-07999df64e41cdbe0/sem/config_mounts'>)
2019-03-29 11:25:03,963 - cc_mounts.py[DEBUG]: mounts configuration is []
2019-03-29 11:25:03,964 - util.py[DEBUG]: Reading from /etc/fstab (quiet=False)
2019-03-29 11:25:03,964 - util.py[DEBUG]: Read 51 bytes from /etc/fstab
2019-03-29 11:25:03,964 - cc_mounts.py[DEBUG]: Attempting to determine the real name of ephemeral0
2019-03-29 11:25:03,964 - cc_mounts.py[DEBUG]: changed default device ephemeral0 => None
2019-03-29 11:25:03,964 - cc_mounts.py[DEBUG]: Ignoring nonexistent default named mount ephemeral0
2019-03-29 11:25:03,964 - cc_mounts.py[DEBUG]: Attempting to determine the real name of swap
2019-03-29 11:25:03,964 - DataSourceEc2.py[DEBUG]: Unable to convert swap to a device
2019-03-29 11:25:03,964 - cc_mounts.py[DEBUG]: changed default device swap => None
2019-03-29 11:25:03,964 - cc_mounts.py[DEBUG]: Ignoring nonexistent default named mount swap
2019-03-29 11:25:03,964 - cc_mounts.py[DEBUG]: no need to setup swap
2019-03-29 11:25:03,964 - cc_mounts.py[DEBUG]: No modifications to fstab needed
2019-03-29 11:25:03,964 - handlers.py[DEBUG]: finish: init-network/config-mounts: SUCCESS: config-mounts ran successfully
2019-03-29 11:25:03,964 - stages.py[DEBUG]: Running module set_hostname (<module 'cloudinit.config.cc_set_hostname' from '/usr/lib/python3/dist-packages/cloudinit/config/cc_set_hostname.py'>) with frequency once-per-instance
2019-03-29 11:25:03,964 - handlers.py[DEBUG]: start: init-network/config-set_hostname: running config-set_hostname with frequency once-per-instance
2019-03-29 11:25:03,965 - util.py[DEBUG]: Writing to /var/lib/cloud/instances/i-07999df64e41cdbe0/sem/config_set_hostname - wb: [644] 25 bytes
2019-03-29 11:25:03,965 - helpers.py[DEBUG]: Running config-set_hostname using lock (<FileLock using file '/var/lib/cloud/instances/i-07999df64e41cdbe0/sem/config_set_hostname'>)
2019-03-29 11:25:03,965 - util.py[DEBUG]: Reading from /var/lib/cloud/data/set-hostname (quiet=False)
2019-03-29 11:25:03,965 - util.py[DEBUG]: Read 84 bytes from /var/lib/cloud/data/set-hostname
2019-03-29 11:25:03,965 - cc_set_hostname.py[DEBUG]: No hostname changes. Skipping set-hostname
2019-03-29 11:25:03,965 - handlers.py[DEBUG]: finish: init-network/config-set_hostname: SUCCESS: config-set_hostname ran successfully
2019-03-29 11:25:03,965 - stages.py[DEBUG]: Running module update_hostname (<module 'cloudinit.config.cc_update_hostname' from '/usr/lib/python3/dist-packages/cloudinit/config/cc_update_hostname.py'>) with frequency always
2019-03-29 11:25:03,966 - handlers.py[DEBUG]: start: init-network/config-update_hostname: running config-update_hostname with frequency always
2019-03-29 11:25:03,966 - helpers.py[DEBUG]: Running config-update_hostname using lock (<cloudinit.helpers.DummyLock object at 0x7f71dad0eda0>)
2019-03-29 11:25:03,966 - cc_update_hostname.py[DEBUG]: Updating hostname to ip-10-0-0-80.eu-west-1.compute.internal (ip-10-0-0-80)
2019-03-29 11:25:03,966 - util.py[DEBUG]: Reading from /etc/hostname (quiet=False)
2019-03-29 11:25:03,966 - util.py[DEBUG]: Read 13 bytes from /etc/hostname
2019-03-29 11:25:03,966 - __init__.py[DEBUG]: Attempting to update hostname to ip-10-0-0-80 in 1 files
2019-03-29 11:25:03,966 - util.py[DEBUG]: Reading from /var/lib/cloud/data/previous-hostname (quiet=False)
2019-03-29 11:25:03,966 - util.py[DEBUG]: Writing to /var/lib/cloud/data/previous-hostname - wb: [644] 13 bytes
2019-03-29 11:25:03,966 - handlers.py[DEBUG]: finish: init-network/config-update_hostname: SUCCESS: config-update_hostname ran successfully
2019-03-29 11:25:03,967 - stages.py[DEBUG]: Running module update_etc_hosts (<module 'cloudinit.config.cc_update_etc_hosts' from '/usr/lib/python3/dist-packages/cloudinit/config/cc_update_etc_hosts.py'>) with frequency always
2019-03-29 11:25:03,967 - handlers.py[DEBUG]: start: init-network/config-update_etc_hosts: running config-update_etc_hosts with frequency always
2019-03-29 11:25:03,967 - helpers.py[DEBUG]: Running config-update_etc_hosts using lock (<cloudinit.helpers.DummyLock object at 0x7f71dad02240>)
2019-03-29 11:25:03,967 - cc_update_etc_hosts.py[DEBUG]: Configuration option 'manage_etc_hosts' is not set, not managing /etc/hosts in module update_etc_hosts
2019-03-29 11:25:03,967 - handlers.py[DEBUG]: finish: init-network/config-update_etc_hosts: SUCCESS: config-update_etc_hosts ran successfully
2019-03-29 11:25:03,967 - stages.py[DEBUG]: Running module ca-certs (<module 'cloudinit.config.cc_ca_certs' from '/usr/lib/python3/dist-packages/cloudinit/config/cc_ca_certs.py'>) with frequency once-per-instance
2019-03-29 11:25:03,967 - handlers.py[DEBUG]: start: init-network/config-ca-certs: running config-ca-certs with frequency once-per-instance
2019-03-29 11:25:03,967 - util.py[DEBUG]: Writing to /var/lib/cloud/instances/i-07999df64e41cdbe0/sem/config_ca_certs - wb: [644] 25 bytes
2019-03-29 11:25:03,968 - helpers.py[DEBUG]: Running config-ca-certs using lock (<FileLock using file '/var/lib/cloud/instances/i-07999df64e41cdbe0/sem/config_ca_certs'>)
2019-03-29 11:25:03,968 - cc_ca_certs.py[DEBUG]: Skipping module named ca-certs, no 'ca-certs' key in configuration
2019-03-29 11:25:03,968 - handlers.py[DEBUG]: finish: init-network/config-ca-certs: SUCCESS: config-ca-certs ran successfully
2019-03-29 11:25:03,968 - stages.py[DEBUG]: Running module rsyslog (<module 'cloudinit.config.cc_rsyslog' from '/usr/lib/python3/dist-packages/cloudinit/config/cc_rsyslog.py'>) with frequency once-per-instance
2019-03-29 11:25:03,968 - handlers.py[DEBUG]: start: init-network/config-rsyslog: running config-rsyslog with frequency once-per-instance
2019-03-29 11:25:03,968 - util.py[DEBUG]: Writing to /var/lib/cloud/instances/i-07999df64e41cdbe0/sem/config_rsyslog - wb: [644] 25 bytes
2019-03-29 11:25:03,968 - helpers.py[DEBUG]: Running config-rsyslog using lock (<FileLock using file '/var/lib/cloud/instances/i-07999df64e41cdbe0/sem/config_rsyslog'>)
2019-03-29 11:25:03,969 - cc_rsyslog.py[DEBUG]: Skipping module named rsyslog, no 'rsyslog' key in configuration
2019-03-29 11:25:03,969 - handlers.py[DEBUG]: finish: init-network/config-rsyslog: SUCCESS: config-rsyslog ran successfully
2019-03-29 11:25:03,969 - stages.py[DEBUG]: Running module users-groups (<module 'cloudinit.config.cc_users_groups' from '/usr/lib/python3/dist-packages/cloudinit/config/cc_users_groups.py'>) with frequency once-per-instance
2019-03-29 11:25:03,969 - handlers.py[DEBUG]: start: init-network/config-users-groups: running config-users-groups with frequency once-per-instance
2019-03-29 11:25:03,969 - util.py[DEBUG]: Writing to /var/lib/cloud/instances/i-07999df64e41cdbe0/sem/config_users_groups - wb: [644] 25 bytes
2019-03-29 11:25:03,969 - helpers.py[DEBUG]: Running config-users-groups using lock (<FileLock using file '/var/lib/cloud/instances/i-07999df64e41cdbe0/sem/config_users_groups'>)
2019-03-29 11:25:03,970 - util.py[DEBUG]: Reading from /etc/os-release (quiet=True)
2019-03-29 11:25:03,970 - util.py[DEBUG]: Read 298 bytes from /etc/os-release
2019-03-29 11:25:03,970 - util.py[DEBUG]: Reading from /etc/system-image/channel.ini (quiet=True)
2019-03-29 11:25:03,970 - util.py[DEBUG]: Read 0 bytes from /etc/system-image/channel.ini
2019-03-29 11:25:03,970 - __init__.py[DEBUG]: Adding user ubuntu
2019-03-29 11:25:03,970 - util.py[DEBUG]: Running hidden command to protect sensitive input/output logstring: ['useradd', 'ubuntu', '--comment', 'Ubuntu', '--groups', 'adm,audio,cdrom,dialout,dip,floppy,lxd,netdev,plugdev,sudo,video', '--shell', '/bin/bash', '-m']
2019-03-29 11:25:04,074 - util.py[DEBUG]: Running command ['passwd', '-l', 'ubuntu'] with allowed return codes [0] (shell=False, capture=True)
2019-03-29 11:25:04,122 - util.py[DEBUG]: Reading from /etc/sudoers (quiet=False)
2019-03-29 11:25:04,122 - util.py[DEBUG]: Read 755 bytes from /etc/sudoers
2019-03-29 11:25:04,123 - util.py[DEBUG]: Writing to /etc/sudoers.d/90-cloud-init-users - wb: [440] 151 bytes
2019-03-29 11:25:04,124 - handlers.py[DEBUG]: finish: init-network/config-users-groups: SUCCESS: config-users-groups ran successfully
2019-03-29 11:25:04,124 - stages.py[DEBUG]: Running module ssh (<module 'cloudinit.config.cc_ssh' from '/usr/lib/python3/dist-packages/cloudinit/config/cc_ssh.py'>) with frequency once-per-instance
2019-03-29 11:25:04,124 - handlers.py[DEBUG]: start: init-network/config-ssh: running config-ssh with frequency once-per-instance
2019-03-29 11:25:04,124 - util.py[DEBUG]: Writing to /var/lib/cloud/instances/i-07999df64e41cdbe0/sem/config_ssh - wb: [644] 25 bytes
2019-03-29 11:25:04,125 - helpers.py[DEBUG]: Running config-ssh using lock (<FileLock using file '/var/lib/cloud/instances/i-07999df64e41cdbe0/sem/config_ssh'>)
2019-03-29 11:25:04,126 - util.py[DEBUG]: Running command ['ssh-keygen', '-t', 'rsa', '-N', '', '-f', '/etc/ssh/ssh_host_rsa_key'] with allowed return codes [0] (shell=False, capture=True)
2019-03-29 11:25:04,341 - util.py[DEBUG]: Running command ['ssh-keygen', '-t', 'dsa', '-N', '', '-f', '/etc/ssh/ssh_host_dsa_key'] with allowed return codes [0] (shell=False, capture=True)
2019-03-29 11:25:04,457 - util.py[DEBUG]: Running command ['ssh-keygen', '-t', 'ecdsa', '-N', '', '-f', '/etc/ssh/ssh_host_ecdsa_key'] with allowed return codes [0] (shell=False, capture=True)
2019-03-29 11:25:04,460 - util.py[DEBUG]: Running command ['ssh-keygen', '-t', 'ed25519', '-N', '', '-f', '/etc/ssh/ssh_host_ed25519_key'] with allowed return codes [0] (shell=False, capture=True)
2019-03-29 11:25:04,465 - util.py[DEBUG]: Changing the ownership of /home/ubuntu/.ssh to 1000:1000
2019-03-29 11:25:04,465 - util.py[DEBUG]: Reading from /etc/ssh/sshd_config (quiet=False)
2019-03-29 11:25:04,466 - util.py[DEBUG]: Read 2540 bytes from /etc/ssh/sshd_config
2019-03-29 11:25:04,467 - util.py[DEBUG]: Writing to /home/ubuntu/.ssh/authorized_keys - wb: [600] 448 bytes
2019-03-29 11:25:04,467 - util.py[DEBUG]: Changing the ownership of /home/ubuntu/.ssh/authorized_keys to 1000:1000
2019-03-29 11:25:04,467 - util.py[DEBUG]: Changing the ownership of /root/.ssh to 0:0
2019-03-29 11:25:04,468 - util.py[DEBUG]: Reading from /etc/ssh/sshd_config (quiet=False)
2019-03-29 11:25:04,468 - util.py[DEBUG]: Read 2540 bytes from /etc/ssh/sshd_config
2019-03-29 11:25:04,468 - util.py[DEBUG]: Writing to /root/.ssh/authorized_keys - wb: [600] 603 bytes
2019-03-29 11:25:04,469 - util.py[DEBUG]: Changing the ownership of /root/.ssh/authorized_keys to 0:0
2019-03-29 11:25:04,469 - handlers.py[DEBUG]: finish: init-network/config-ssh: SUCCESS: config-ssh ran successfully
2019-03-29 11:25:04,469 - main.py[DEBUG]: Ran 15 modules with 0 failures
2019-03-29 11:25:04,469 - util.py[DEBUG]: Reading from /proc/uptime (quiet=False)
2019-03-29 11:25:04,470 - util.py[DEBUG]: Read 12 bytes from /proc/uptime
2019-03-29 11:25:04,470 - util.py[DEBUG]: cloud-init mode 'init' took 1.085 seconds (1.09)
2019-03-29 11:25:04,470 - handlers.py[DEBUG]: finish: init-network: SUCCESS: searching for network datasources
2019-03-29 11:25:13,779 - util.py[DEBUG]: Cloud-init v. 18.3-9-g2e62cb8a-0ubuntu1~16.04.2 running 'modules:config' at Fri, 29 Mar 2019 11:25:13 +0000. Up 19.22 seconds.
2019-03-29 11:25:13,821 - stages.py[DEBUG]: Using distro class <class 'cloudinit.distros.ubuntu.Distro'>
2019-03-29 11:25:13,822 - stages.py[DEBUG]: Running module emit_upstart (<module 'cloudinit.config.cc_emit_upstart' from '/usr/lib/python3/dist-packages/cloudinit/config/cc_emit_upstart.py'>) with frequency always
2019-03-29 11:25:13,822 - handlers.py[DEBUG]: start: modules-config/config-emit_upstart: running config-emit_upstart with frequency always
2019-03-29 11:25:13,822 - helpers.py[DEBUG]: Running config-emit_upstart using lock (<cloudinit.helpers.DummyLock object at 0x7f7bb83a5d30>)
2019-03-29 11:25:13,822 - cc_emit_upstart.py[DEBUG]: no /sbin/initctl located
2019-03-29 11:25:13,822 - cc_emit_upstart.py[DEBUG]: not upstart system, 'emit_upstart' disabled
2019-03-29 11:25:13,823 - handlers.py[DEBUG]: finish: modules-config/config-emit_upstart: SUCCESS: config-emit_upstart ran successfully
2019-03-29 11:25:13,823 - stages.py[DEBUG]: Running module snap (<module 'cloudinit.config.cc_snap' from '/usr/lib/python3/dist-packages/cloudinit/config/cc_snap.py'>) with frequency once-per-instance
2019-03-29 11:25:13,823 - handlers.py[DEBUG]: start: modules-config/config-snap: running config-snap with frequency once-per-instance
2019-03-29 11:25:13,823 - util.py[DEBUG]: Writing to /var/lib/cloud/instances/i-07999df64e41cdbe0/sem/config_snap - wb: [644] 25 bytes
2019-03-29 11:25:13,823 - helpers.py[DEBUG]: Running config-snap using lock (<FileLock using file '/var/lib/cloud/instances/i-07999df64e41cdbe0/sem/config_snap'>)
2019-03-29 11:25:13,823 - cc_snap.py[DEBUG]: Skipping module named snap, no 'snap' key in configuration
2019-03-29 11:25:13,824 - handlers.py[DEBUG]: finish: modules-config/config-snap: SUCCESS: config-snap ran successfully
2019-03-29 11:25:13,824 - stages.py[DEBUG]: Running module snap_config (<module 'cloudinit.config.cc_snap_config' from '/usr/lib/python3/dist-packages/cloudinit/config/cc_snap_config.py'>) with frequency once-per-instance
2019-03-29 11:25:13,824 - handlers.py[DEBUG]: start: modules-config/config-snap_config: running config-snap_config with frequency once-per-instance
2019-03-29 11:25:13,824 - util.py[DEBUG]: Writing to /var/lib/cloud/instances/i-07999df64e41cdbe0/sem/config_snap_config - wb: [644] 25 bytes
2019-03-29 11:25:13,824 - helpers.py[DEBUG]: Running config-snap_config using lock (<FileLock using file '/var/lib/cloud/instances/i-07999df64e41cdbe0/sem/config_snap_config'>)
2019-03-29 11:25:13,824 - cc_snap_config.py[DEBUG]: No snappy config provided, skipping
2019-03-29 11:25:13,824 - handlers.py[DEBUG]: finish: modules-config/config-snap_config: SUCCESS: config-snap_config ran successfully
2019-03-29 11:25:13,824 - stages.py[DEBUG]: Running module ssh-import-id (<module 'cloudinit.config.cc_ssh_import_id' from '/usr/lib/python3/dist-packages/cloudinit/config/cc_ssh_import_id.py'>) with frequency once-per-instance
2019-03-29 11:25:13,825 - handlers.py[DEBUG]: start: modules-config/config-ssh-import-id: running config-ssh-import-id with frequency once-per-instance
2019-03-29 11:25:13,825 - util.py[DEBUG]: Writing to /var/lib/cloud/instances/i-07999df64e41cdbe0/sem/config_ssh_import_id - wb: [644] 24 bytes
2019-03-29 11:25:13,825 - helpers.py[DEBUG]: Running config-ssh-import-id using lock (<FileLock using file '/var/lib/cloud/instances/i-07999df64e41cdbe0/sem/config_ssh_import_id'>)
2019-03-29 11:25:13,825 - handlers.py[DEBUG]: finish: modules-config/config-ssh-import-id: SUCCESS: config-ssh-import-id ran successfully
2019-03-29 11:25:13,825 - stages.py[DEBUG]: Running module locale (<module 'cloudinit.config.cc_locale' from '/usr/lib/python3/dist-packages/cloudinit/config/cc_locale.py'>) with frequency once-per-instance
2019-03-29 11:25:13,826 - handlers.py[DEBUG]: start: modules-config/config-locale: running config-locale with frequency once-per-instance
2019-03-29 11:25:13,826 - util.py[DEBUG]: Writing to /var/lib/cloud/instances/i-07999df64e41cdbe0/sem/config_locale - wb: [644] 25 bytes
2019-03-29 11:25:13,826 - helpers.py[DEBUG]: Running config-locale using lock (<FileLock using file '/var/lib/cloud/instances/i-07999df64e41cdbe0/sem/config_locale'>)
2019-03-29 11:25:13,826 - util.py[DEBUG]: Reading from /etc/default/locale (quiet=False)
2019-03-29 11:25:13,826 - util.py[DEBUG]: Read 35 bytes from /etc/default/locale
2019-03-29 11:25:13,826 - cc_locale.py[DEBUG]: Setting locale to en_US.UTF-8
2019-03-29 11:25:13,826 - util.py[DEBUG]: Reading from /etc/default/locale (quiet=False)
2019-03-29 11:25:13,827 - util.py[DEBUG]: Read 35 bytes from /etc/default/locale
2019-03-29 11:25:13,827 - debian.py[DEBUG]: Generating locales for en_US.UTF-8
2019-03-29 11:25:13,827 - util.py[DEBUG]: Running command ['locale-gen', 'en_US.UTF-8'] with allowed return codes [0] (shell=False, capture=False)
2019-03-29 11:25:14,556 - debian.py[DEBUG]: Updating /etc/default/locale with locale setting LANG=en_US.UTF-8
2019-03-29 11:25:14,557 - util.py[DEBUG]: Running command ['update-locale', '--locale-file=/etc/default/locale', 'LANG=en_US.UTF-8'] with allowed return codes [0] (shell=False, capture=False)
2019-03-29 11:25:14,786 - handlers.py[DEBUG]: finish: modules-config/config-locale: SUCCESS: config-locale ran successfully
2019-03-29 11:25:14,786 - stages.py[DEBUG]: Running module set-passwords (<module 'cloudinit.config.cc_set_passwords' from '/usr/lib/python3/dist-packages/cloudinit/config/cc_set_passwords.py'>) with frequency once-per-instance
2019-03-29 11:25:14,787 - handlers.py[DEBUG]: start: modules-config/config-set-passwords: running config-set-passwords with frequency once-per-instance
2019-03-29 11:25:14,787 - util.py[DEBUG]: Writing to /var/lib/cloud/instances/i-07999df64e41cdbe0/sem/config_set_passwords - wb: [644] 25 bytes
2019-03-29 11:25:14,787 - helpers.py[DEBUG]: Running config-set-passwords using lock (<FileLock using file '/var/lib/cloud/instances/i-07999df64e41cdbe0/sem/config_set_passwords'>)
2019-03-29 11:25:14,787 - cc_set_passwords.py[DEBUG]: Leaving ssh config 'PasswordAuthentication' unchanged. ssh_pwauth=None
2019-03-29 11:25:14,787 - handlers.py[DEBUG]: finish: modules-config/config-set-passwords: SUCCESS: config-set-passwords ran successfully
2019-03-29 11:25:14,788 - stages.py[DEBUG]: Running module grub-dpkg (<module 'cloudinit.config.cc_grub_dpkg' from '/usr/lib/python3/dist-packages/cloudinit/config/cc_grub_dpkg.py'>) with frequency once-per-instance
2019-03-29 11:25:14,788 - handlers.py[DEBUG]: start: modules-config/config-grub-dpkg: running config-grub-dpkg with frequency once-per-instance
2019-03-29 11:25:14,788 - util.py[DEBUG]: Writing to /var/lib/cloud/instances/i-07999df64e41cdbe0/sem/config_grub_dpkg - wb: [644] 25 bytes
2019-03-29 11:25:14,788 - helpers.py[DEBUG]: Running config-grub-dpkg using lock (<FileLock using file '/var/lib/cloud/instances/i-07999df64e41cdbe0/sem/config_grub_dpkg'>)
2019-03-29 11:25:14,788 - cc_grub_dpkg.py[DEBUG]: Setting grub debconf-set-selections with '/dev/xvda','false'
2019-03-29 11:25:14,788 - util.py[DEBUG]: Running command ['debconf-set-selections'] with allowed return codes [0] (shell=False, capture=True)
2019-03-29 11:25:15,236 - handlers.py[DEBUG]: finish: modules-config/config-grub-dpkg: SUCCESS: config-grub-dpkg ran successfully
2019-03-29 11:25:15,237 - stages.py[DEBUG]: Running module apt-pipelining (<module 'cloudinit.config.cc_apt_pipelining' from '/usr/lib/python3/dist-packages/cloudinit/config/cc_apt_pipelining.py'>) with frequency once-per-instance
2019-03-29 11:25:15,237 - handlers.py[DEBUG]: start: modules-config/config-apt-pipelining: running config-apt-pipelining with frequency once-per-instance
2019-03-29 11:25:15,237 - util.py[DEBUG]: Writing to /var/lib/cloud/instances/i-07999df64e41cdbe0/sem/config_apt_pipelining - wb: [644] 25 bytes
2019-03-29 11:25:15,238 - helpers.py[DEBUG]: Running config-apt-pipelining using lock (<FileLock using file '/var/lib/cloud/instances/i-07999df64e41cdbe0/sem/config_apt_pipelining'>)
2019-03-29 11:25:15,242 - util.py[DEBUG]: Writing to /etc/apt/apt.conf.d/90cloud-init-pipelining - wb: [644] 80 bytes
2019-03-29 11:25:15,243 - cc_apt_pipelining.py[DEBUG]: Wrote /etc/apt/apt.conf.d/90cloud-init-pipelining with apt pipeline depth setting 0
2019-03-29 11:25:15,243 - handlers.py[DEBUG]: finish: modules-config/config-apt-pipelining: SUCCESS: config-apt-pipelining ran successfully
2019-03-29 11:25:15,243 - stages.py[DEBUG]: Running module apt-configure (<module 'cloudinit.config.cc_apt_configure' from '/usr/lib/python3/dist-packages/cloudinit/config/cc_apt_configure.py'>) with frequency once-per-instance
2019-03-29 11:25:15,243 - handlers.py[DEBUG]: start: modules-config/config-apt-configure: running config-apt-configure with frequency once-per-instance
2019-03-29 11:25:15,243 - util.py[DEBUG]: Writing to /var/lib/cloud/instances/i-07999df64e41cdbe0/sem/config_apt_configure - wb: [644] 25 bytes
2019-03-29 11:25:15,244 - helpers.py[DEBUG]: Running config-apt-configure using lock (<FileLock using file '/var/lib/cloud/instances/i-07999df64e41cdbe0/sem/config_apt_configure'>)
2019-03-29 11:25:15,244 - cc_apt_configure.py[DEBUG]: debconf_selections was not set in config
2019-03-29 11:25:15,244 - util.py[DEBUG]: Reading from /etc/os-release (quiet=True)
2019-03-29 11:25:15,244 - util.py[DEBUG]: Read 298 bytes from /etc/os-release
2019-03-29 11:25:15,244 - util.py[DEBUG]: Reading from /etc/system-image/channel.ini (quiet=True)
2019-03-29 11:25:15,245 - util.py[DEBUG]: Read 0 bytes from /etc/system-image/channel.ini
2019-03-29 11:25:15,245 - cc_apt_configure.py[DEBUG]: handling apt config: {}
2019-03-29 11:25:15,245 - util.py[DEBUG]: Running command ['lsb_release', '--all'] with allowed return codes [0] (shell=False, capture=True)
2019-03-29 11:25:15,331 - util.py[DEBUG]: Running command ['dpkg', '--print-architecture'] with allowed return codes [0] (shell=False, capture=True)
2019-03-29 11:25:15,334 - cc_apt_configure.py[DEBUG]: got primary mirror: None
2019-03-29 11:25:15,334 - cc_apt_configure.py[DEBUG]: got security mirror: None
2019-03-29 11:25:15,334 - util.py[DEBUG]: Running command ['dpkg', '--print-architecture'] with allowed return codes [0] (shell=False, capture=True)
2019-03-29 11:25:15,395 - util.py[DEBUG]: Resolving URL: http://eu-west-1.ec2.archive.ubuntu.com/ubuntu/ took 0.059 seconds
2019-03-29 11:25:15,395 - __init__.py[DEBUG]: filtered distro mirror info: {'security': 'http://security.ubuntu.com/ubuntu', 'primary': 'http://eu-west-1.ec2.archive.ubuntu.com/ubuntu/'}
2019-03-29 11:25:15,395 - cc_apt_configure.py[DEBUG]: Apt Mirror info: {'MIRROR': 'http://eu-west-1.ec2.archive.ubuntu.com/ubuntu/', 'security': 'http://security.ubuntu.com/ubuntu', 'SECURITY': 'http://security.ubuntu.com/ubuntu', 'primary': 'http://eu-west-1.ec2.archive.ubuntu.com/ubuntu/', 'PRIMARY': 'http://eu-west-1.ec2.archive.ubuntu.com/ubuntu/'}
2019-03-29 11:25:15,395 - cc_apt_configure.py[INFO]: No custom template provided, fall back to builtin
2019-03-29 11:25:15,396 - util.py[DEBUG]: Reading from /etc/cloud/templates/sources.list.ubuntu.tmpl (quiet=False)
2019-03-29 11:25:15,396 - util.py[DEBUG]: Read 2841 bytes from /etc/cloud/templates/sources.list.ubuntu.tmpl
2019-03-29 11:25:15,403 - util.py[DEBUG]: Writing to /etc/apt/sources.list - wb: [644] 3335 bytes
2019-03-29 11:25:15,403 - util.py[DEBUG]: Running command ['dpkg', '--print-architecture'] with allowed return codes [0] (shell=False, capture=True)
2019-03-29 11:25:15,407 - cc_apt_configure.py[DEBUG]: Renaming apt list /var/lib/apt/lists/archive.ubuntu.com_ubuntu_dists_xenial-updates_main_i18n_Translation-en to /var/lib/apt/lists/eu-west-1.ec2.archive.ubuntu.com_ubuntu_dists_xenial-updates_main_i18n_Translation-en
2019-03-29 11:25:15,407 - cc_apt_configure.py[DEBUG]: Renaming apt list /var/lib/apt/lists/archive.ubuntu.com_ubuntu_dists_xenial-updates_main_binary-amd64_Packages to /var/lib/apt/lists/eu-west-1.ec2.archive.ubuntu.com_ubuntu_dists_xenial-updates_main_binary-amd64_Packages
2019-03-29 11:25:15,407 - cc_apt_configure.py[DEBUG]: Renaming apt list /var/lib/apt/lists/archive.ubuntu.com_ubuntu_dists_xenial-updates_restricted_binary-amd64_Packages to /var/lib/apt/lists/eu-west-1.ec2.archive.ubuntu.com_ubuntu_dists_xenial-updates_restricted_binary-amd64_Packages
2019-03-29 11:25:15,408 - cc_apt_configure.py[DEBUG]: Renaming apt list /var/lib/apt/lists/archive.ubuntu.com_ubuntu_dists_xenial_main_i18n_Translation-en to /var/lib/apt/lists/eu-west-1.ec2.archive.ubuntu.com_ubuntu_dists_xenial_main_i18n_Translation-en
2019-03-29 11:25:15,408 - cc_apt_configure.py[DEBUG]: Renaming apt list /var/lib/apt/lists/archive.ubuntu.com_ubuntu_dists_xenial-updates_restricted_i18n_Translation-en to /var/lib/apt/lists/eu-west-1.ec2.archive.ubuntu.com_ubuntu_dists_xenial-updates_restricted_i18n_Translation-en
2019-03-29 11:25:15,408 - cc_apt_configure.py[DEBUG]: Renaming apt list /var/lib/apt/lists/archive.ubuntu.com_ubuntu_dists_xenial-updates_InRelease to /var/lib/apt/lists/eu-west-1.ec2.archive.ubuntu.com_ubuntu_dists_xenial-updates_InRelease
2019-03-29 11:25:15,408 - cc_apt_configure.py[DEBUG]: Renaming apt list /var/lib/apt/lists/archive.ubuntu.com_ubuntu_dists_xenial_InRelease to /var/lib/apt/lists/eu-west-1.ec2.archive.ubuntu.com_ubuntu_dists_xenial_InRelease
2019-03-29 11:25:15,408 - cc_apt_configure.py[DEBUG]: Renaming apt list /var/lib/apt/lists/archive.ubuntu.com_ubuntu_dists_xenial_restricted_i18n_Translation-en to /var/lib/apt/lists/eu-west-1.ec2.archive.ubuntu.com_ubuntu_dists_xenial_restricted_i18n_Translation-en
2019-03-29 11:25:15,408 - cc_apt_configure.py[DEBUG]: Renaming apt list /var/lib/apt/lists/archive.ubuntu.com_ubuntu_dists_xenial_restricted_binary-amd64_Packages to /var/lib/apt/lists/eu-west-1.ec2.archive.ubuntu.com_ubuntu_dists_xenial_restricted_binary-amd64_Packages
2019-03-29 11:25:15,408 - cc_apt_configure.py[DEBUG]: Renaming apt list /var/lib/apt/lists/archive.ubuntu.com_ubuntu_dists_xenial_main_binary-amd64_Packages to /var/lib/apt/lists/eu-west-1.ec2.archive.ubuntu.com_ubuntu_dists_xenial_main_binary-amd64_Packages
2019-03-29 11:25:15,408 - handlers.py[DEBUG]: finish: modules-config/config-apt-configure: SUCCESS: config-apt-configure ran successfully
2019-03-29 11:25:15,408 - stages.py[DEBUG]: Running module ubuntu-advantage (<module 'cloudinit.config.cc_ubuntu_advantage' from '/usr/lib/python3/dist-packages/cloudinit/config/cc_ubuntu_advantage.py'>) with frequency once-per-instance
2019-03-29 11:25:15,408 - handlers.py[DEBUG]: start: modules-config/config-ubuntu-advantage: running config-ubuntu-advantage with frequency once-per-instance
2019-03-29 11:25:15,408 - util.py[DEBUG]: Writing to /var/lib/cloud/instances/i-07999df64e41cdbe0/sem/config_ubuntu_advantage - wb: [644] 24 bytes
2019-03-29 11:25:15,409 - helpers.py[DEBUG]: Running config-ubuntu-advantage using lock (<FileLock using file '/var/lib/cloud/instances/i-07999df64e41cdbe0/sem/config_ubuntu_advantage'>)
2019-03-29 11:25:15,409 - cc_ubuntu_advantage.py[DEBUG]: Skipping module named ubuntu-advantage, no 'ubuntu-advantage' key in configuration
2019-03-29 11:25:15,409 - handlers.py[DEBUG]: finish: modules-config/config-ubuntu-advantage: SUCCESS: config-ubuntu-advantage ran successfully
2019-03-29 11:25:15,409 - stages.py[DEBUG]: Running module ntp (<module 'cloudinit.config.cc_ntp' from '/usr/lib/python3/dist-packages/cloudinit/config/cc_ntp.py'>) with frequency once-per-instance
2019-03-29 11:25:15,409 - handlers.py[DEBUG]: start: modules-config/config-ntp: running config-ntp with frequency once-per-instance
2019-03-29 11:25:15,409 - util.py[DEBUG]: Writing to /var/lib/cloud/instances/i-07999df64e41cdbe0/sem/config_ntp - wb: [644] 24 bytes
2019-03-29 11:25:15,410 - helpers.py[DEBUG]: Running config-ntp using lock (<FileLock using file '/var/lib/cloud/instances/i-07999df64e41cdbe0/sem/config_ntp'>)
2019-03-29 11:25:15,410 - cc_ntp.py[DEBUG]: Skipping module named ntp, not present or disabled by cfg
2019-03-29 11:25:15,410 - handlers.py[DEBUG]: finish: modules-config/config-ntp: SUCCESS: config-ntp ran successfully
2019-03-29 11:25:15,410 - stages.py[DEBUG]: Running module timezone (<module 'cloudinit.config.cc_timezone' from '/usr/lib/python3/dist-packages/cloudinit/config/cc_timezone.py'>) with frequency once-per-instance
2019-03-29 11:25:15,410 - handlers.py[DEBUG]: start: modules-config/config-timezone: running config-timezone with frequency once-per-instance
2019-03-29 11:25:15,410 - util.py[DEBUG]: Writing to /var/lib/cloud/instances/i-07999df64e41cdbe0/sem/config_timezone - wb: [644] 23 bytes
2019-03-29 11:25:15,411 - helpers.py[DEBUG]: Running config-timezone using lock (<FileLock using file '/var/lib/cloud/instances/i-07999df64e41cdbe0/sem/config_timezone'>)
2019-03-29 11:25:15,411 - cc_timezone.py[DEBUG]: Skipping module named timezone, no 'timezone' specified
2019-03-29 11:25:15,411 - handlers.py[DEBUG]: finish: modules-config/config-timezone: SUCCESS: config-timezone ran successfully
2019-03-29 11:25:15,411 - stages.py[DEBUG]: Running module disable-ec2-metadata (<module 'cloudinit.config.cc_disable_ec2_metadata' from '/usr/lib/python3/dist-packages/cloudinit/config/cc_disable_ec2_metadata.py'>) with frequency always
2019-03-29 11:25:15,411 - handlers.py[DEBUG]: start: modules-config/config-disable-ec2-metadata: running config-disable-ec2-metadata with frequency always
2019-03-29 11:25:15,411 - helpers.py[DEBUG]: Running config-disable-ec2-metadata using lock (<cloudinit.helpers.DummyLock object at 0x7f7bb83ba048>)
2019-03-29 11:25:15,411 - cc_disable_ec2_metadata.py[DEBUG]: Skipping module named disable-ec2-metadata, disabling the ec2 route not enabled
2019-03-29 11:25:15,411 - handlers.py[DEBUG]: finish: modules-config/config-disable-ec2-metadata: SUCCESS: config-disable-ec2-metadata ran successfully
2019-03-29 11:25:15,411 - stages.py[DEBUG]: Running module runcmd (<module 'cloudinit.config.cc_runcmd' from '/usr/lib/python3/dist-packages/cloudinit/config/cc_runcmd.py'>) with frequency once-per-instance
2019-03-29 11:25:15,411 - handlers.py[DEBUG]: start: modules-config/config-runcmd: running config-runcmd with frequency once-per-instance
2019-03-29 11:25:15,411 - util.py[DEBUG]: Writing to /var/lib/cloud/instances/i-07999df64e41cdbe0/sem/config_runcmd - wb: [644] 25 bytes
2019-03-29 11:25:15,412 - helpers.py[DEBUG]: Running config-runcmd using lock (<FileLock using file '/var/lib/cloud/instances/i-07999df64e41cdbe0/sem/config_runcmd'>)
2019-03-29 11:25:15,412 - cc_runcmd.py[DEBUG]: Skipping module named runcmd, no 'runcmd' key in configuration
2019-03-29 11:25:15,412 - handlers.py[DEBUG]: finish: modules-config/config-runcmd: SUCCESS: config-runcmd ran successfully
2019-03-29 11:25:15,412 - stages.py[DEBUG]: Running module byobu (<module 'cloudinit.config.cc_byobu' from '/usr/lib/python3/dist-packages/cloudinit/config/cc_byobu.py'>) with frequency once-per-instance
2019-03-29 11:25:15,412 - handlers.py[DEBUG]: start: modules-config/config-byobu: running config-byobu with frequency once-per-instance
2019-03-29 11:25:15,412 - util.py[DEBUG]: Writing to /var/lib/cloud/instances/i-07999df64e41cdbe0/sem/config_byobu - wb: [644] 25 bytes
2019-03-29 11:25:15,413 - helpers.py[DEBUG]: Running config-byobu using lock (<FileLock using file '/var/lib/cloud/instances/i-07999df64e41cdbe0/sem/config_byobu'>)
2019-03-29 11:25:15,413 - cc_byobu.py[DEBUG]: Skipping module named byobu, no 'byobu' values found
2019-03-29 11:25:15,413 - handlers.py[DEBUG]: finish: modules-config/config-byobu: SUCCESS: config-byobu ran successfully
2019-03-29 11:25:15,413 - main.py[DEBUG]: Ran 15 modules with 0 failures
2019-03-29 11:25:15,413 - util.py[DEBUG]: Reading from /proc/uptime (quiet=False)
2019-03-29 11:25:15,413 - util.py[DEBUG]: Read 13 bytes from /proc/uptime
2019-03-29 11:25:15,414 - util.py[DEBUG]: cloud-init mode 'modules' took 1.680 seconds (1.68)
2019-03-29 11:25:15,414 - handlers.py[DEBUG]: finish: modules-config: SUCCESS: running modules for config
2019-03-29 11:25:15,707 - util.py[DEBUG]: Cloud-init v. 18.3-9-g2e62cb8a-0ubuntu1~16.04.2 running 'modules:final' at Fri, 29 Mar 2019 11:25:15 +0000. Up 21.15 seconds.
2019-03-29 11:25:15,742 - stages.py[DEBUG]: Using distro class <class 'cloudinit.distros.ubuntu.Distro'>
2019-03-29 11:25:15,743 - stages.py[DEBUG]: Running module snappy (<module 'cloudinit.config.cc_snappy' from '/usr/lib/python3/dist-packages/cloudinit/config/cc_snappy.py'>) with frequency once-per-instance
2019-03-29 11:25:15,743 - handlers.py[DEBUG]: start: modules-final/config-snappy: running config-snappy with frequency once-per-instance
2019-03-29 11:25:15,743 - util.py[DEBUG]: Writing to /var/lib/cloud/instances/i-07999df64e41cdbe0/sem/config_snappy - wb: [644] 25 bytes
2019-03-29 11:25:15,744 - helpers.py[DEBUG]: Running config-snappy using lock (<FileLock using file '/var/lib/cloud/instances/i-07999df64e41cdbe0/sem/config_snappy'>)
2019-03-29 11:25:15,744 - util.py[DEBUG]: Reading from /etc/os-release (quiet=True)
2019-03-29 11:25:15,744 - util.py[DEBUG]: Read 298 bytes from /etc/os-release
2019-03-29 11:25:15,744 - util.py[DEBUG]: Reading from /etc/system-image/channel.ini (quiet=True)
2019-03-29 11:25:15,744 - util.py[DEBUG]: Read 0 bytes from /etc/system-image/channel.ini
2019-03-29 11:25:15,744 - cc_snappy.py[DEBUG]: snappy: 'auto' mode, and system not snappy
2019-03-29 11:25:15,745 - handlers.py[DEBUG]: finish: modules-final/config-snappy: SUCCESS: config-snappy ran successfully
2019-03-29 11:25:15,745 - stages.py[DEBUG]: Running module package-update-upgrade-install (<module 'cloudinit.config.cc_package_update_upgrade_install' from '/usr/lib/python3/dist-packages/cloudinit/config/cc_package_update_upgrade_install.py'>) with frequency once-per-instance
2019-03-29 11:25:15,745 - handlers.py[DEBUG]: start: modules-final/config-package-update-upgrade-install: running config-package-update-upgrade-install with frequency once-per-instance
2019-03-29 11:25:15,745 - util.py[DEBUG]: Writing to /var/lib/cloud/instances/i-07999df64e41cdbe0/sem/config_package_update_upgrade_install - wb: [644] 25 bytes
2019-03-29 11:25:15,745 - helpers.py[DEBUG]: Running config-package-update-upgrade-install using lock (<FileLock using file '/var/lib/cloud/instances/i-07999df64e41cdbe0/sem/config_package_update_upgrade_install'>)
2019-03-29 11:25:15,746 - handlers.py[DEBUG]: finish: modules-final/config-package-update-upgrade-install: SUCCESS: config-package-update-upgrade-install ran successfully
2019-03-29 11:25:15,746 - stages.py[DEBUG]: Running module fan (<module 'cloudinit.config.cc_fan' from '/usr/lib/python3/dist-packages/cloudinit/config/cc_fan.py'>) with frequency once-per-instance
2019-03-29 11:25:15,746 - handlers.py[DEBUG]: start: modules-final/config-fan: running config-fan with frequency once-per-instance
2019-03-29 11:25:15,746 - util.py[DEBUG]: Writing to /var/lib/cloud/instances/i-07999df64e41cdbe0/sem/config_fan - wb: [644] 25 bytes
2019-03-29 11:25:15,746 - helpers.py[DEBUG]: Running config-fan using lock (<FileLock using file '/var/lib/cloud/instances/i-07999df64e41cdbe0/sem/config_fan'>)
2019-03-29 11:25:15,746 - cc_fan.py[DEBUG]: fan: no 'fan' config entry. disabling
2019-03-29 11:25:15,746 - handlers.py[DEBUG]: finish: modules-final/config-fan: SUCCESS: config-fan ran successfully
2019-03-29 11:25:15,746 - stages.py[DEBUG]: Running module landscape (<module 'cloudinit.config.cc_landscape' from '/usr/lib/python3/dist-packages/cloudinit/config/cc_landscape.py'>) with frequency once-per-instance
2019-03-29 11:25:15,747 - handlers.py[DEBUG]: start: modules-final/config-landscape: running config-landscape with frequency once-per-instance
2019-03-29 11:25:15,747 - util.py[DEBUG]: Writing to /var/lib/cloud/instances/i-07999df64e41cdbe0/sem/config_landscape - wb: [644] 25 bytes
2019-03-29 11:25:15,747 - helpers.py[DEBUG]: Running config-landscape using lock (<FileLock using file '/var/lib/cloud/instances/i-07999df64e41cdbe0/sem/config_landscape'>)
2019-03-29 11:25:15,747 - handlers.py[DEBUG]: finish: modules-final/config-landscape: SUCCESS: config-landscape ran successfully
2019-03-29 11:25:15,747 - stages.py[DEBUG]: Running module lxd (<module 'cloudinit.config.cc_lxd' from '/usr/lib/python3/dist-packages/cloudinit/config/cc_lxd.py'>) with frequency once-per-instance
2019-03-29 11:25:15,747 - handlers.py[DEBUG]: start: modules-final/config-lxd: running config-lxd with frequency once-per-instance
2019-03-29 11:25:15,748 - util.py[DEBUG]: Writing to /var/lib/cloud/instances/i-07999df64e41cdbe0/sem/config_lxd - wb: [644] 24 bytes
2019-03-29 11:25:15,748 - helpers.py[DEBUG]: Running config-lxd using lock (<FileLock using file '/var/lib/cloud/instances/i-07999df64e41cdbe0/sem/config_lxd'>)
2019-03-29 11:25:15,748 - cc_lxd.py[DEBUG]: Skipping module named lxd, not present or disabled by cfg
2019-03-29 11:25:15,748 - handlers.py[DEBUG]: finish: modules-final/config-lxd: SUCCESS: config-lxd ran successfully
2019-03-29 11:25:15,748 - stages.py[DEBUG]: Running module puppet (<module 'cloudinit.config.cc_puppet' from '/usr/lib/python3/dist-packages/cloudinit/config/cc_puppet.py'>) with frequency once-per-instance
2019-03-29 11:25:15,748 - handlers.py[DEBUG]: start: modules-final/config-puppet: running config-puppet with frequency once-per-instance
2019-03-29 11:25:15,748 - util.py[DEBUG]: Writing to /var/lib/cloud/instances/i-07999df64e41cdbe0/sem/config_puppet - wb: [644] 25 bytes
2019-03-29 11:25:15,749 - helpers.py[DEBUG]: Running config-puppet using lock (<FileLock using file '/var/lib/cloud/instances/i-07999df64e41cdbe0/sem/config_puppet'>)
2019-03-29 11:25:15,749 - cc_puppet.py[DEBUG]: Skipping module named puppet, no 'puppet' configuration found
2019-03-29 11:25:15,749 - handlers.py[DEBUG]: finish: modules-final/config-puppet: SUCCESS: config-puppet ran successfully
2019-03-29 11:25:15,749 - stages.py[DEBUG]: Running module chef (<module 'cloudinit.config.cc_chef' from '/usr/lib/python3/dist-packages/cloudinit/config/cc_chef.py'>) with frequency once-per-instance
2019-03-29 11:25:15,749 - handlers.py[DEBUG]: start: modules-final/config-chef: running config-chef with frequency once-per-instance
2019-03-29 11:25:15,749 - util.py[DEBUG]: Writing to /var/lib/cloud/instances/i-07999df64e41cdbe0/sem/config_chef - wb: [644] 24 bytes
2019-03-29 11:25:15,750 - helpers.py[DEBUG]: Running config-chef using lock (<FileLock using file '/var/lib/cloud/instances/i-07999df64e41cdbe0/sem/config_chef'>)
2019-03-29 11:25:15,750 - cc_chef.py[DEBUG]: Skipping module named chef, no 'chef' key in configuration
2019-03-29 11:25:15,750 - handlers.py[DEBUG]: finish: modules-final/config-chef: SUCCESS: config-chef ran successfully
2019-03-29 11:25:15,750 - stages.py[DEBUG]: Running module mcollective (<module 'cloudinit.config.cc_mcollective' from '/usr/lib/python3/dist-packages/cloudinit/config/cc_mcollective.py'>) with frequency once-per-instance
2019-03-29 11:25:15,750 - handlers.py[DEBUG]: start: modules-final/config-mcollective: running config-mcollective with frequency once-per-instance
2019-03-29 11:25:15,750 - util.py[DEBUG]: Writing to /var/lib/cloud/instances/i-07999df64e41cdbe0/sem/config_mcollective - wb: [644] 25 bytes
2019-03-29 11:25:15,750 - helpers.py[DEBUG]: Running config-mcollective using lock (<FileLock using file '/var/lib/cloud/instances/i-07999df64e41cdbe0/sem/config_mcollective'>)
2019-03-29 11:25:15,751 - cc_mcollective.py[DEBUG]: Skipping module named mcollective, no 'mcollective' key in configuration
2019-03-29 11:25:15,751 - handlers.py[DEBUG]: finish: modules-final/config-mcollective: SUCCESS: config-mcollective ran successfully
2019-03-29 11:25:15,751 - stages.py[DEBUG]: Running module salt-minion (<module 'cloudinit.config.cc_salt_minion' from '/usr/lib/python3/dist-packages/cloudinit/config/cc_salt_minion.py'>) with frequency once-per-instance
2019-03-29 11:25:15,751 - handlers.py[DEBUG]: start: modules-final/config-salt-minion: running config-salt-minion with frequency once-per-instance
2019-03-29 11:25:15,751 - util.py[DEBUG]: Writing to /var/lib/cloud/instances/i-07999df64e41cdbe0/sem/config_salt_minion - wb: [644] 25 bytes
2019-03-29 11:25:15,751 - helpers.py[DEBUG]: Running config-salt-minion using lock (<FileLock using file '/var/lib/cloud/instances/i-07999df64e41cdbe0/sem/config_salt_minion'>)
2019-03-29 11:25:15,751 - cc_salt_minion.py[DEBUG]: Skipping module named salt-minion, no 'salt_minion' key in configuration
2019-03-29 11:25:15,751 - handlers.py[DEBUG]: finish: modules-final/config-salt-minion: SUCCESS: config-salt-minion ran successfully
2019-03-29 11:25:15,752 - stages.py[DEBUG]: Running module rightscale_userdata (<module 'cloudinit.config.cc_rightscale_userdata' from '/usr/lib/python3/dist-packages/cloudinit/config/cc_rightscale_userdata.py'>) with frequency once-per-instance
2019-03-29 11:25:15,752 - handlers.py[DEBUG]: start: modules-final/config-rightscale_userdata: running config-rightscale_userdata with frequency once-per-instance
2019-03-29 11:25:15,752 - util.py[DEBUG]: Writing to /var/lib/cloud/instances/i-07999df64e41cdbe0/sem/config_rightscale_userdata - wb: [644] 25 bytes
2019-03-29 11:25:15,752 - helpers.py[DEBUG]: Running config-rightscale_userdata using lock (<FileLock using file '/var/lib/cloud/instances/i-07999df64e41cdbe0/sem/config_rightscale_userdata'>)
2019-03-29 11:25:15,752 - cc_rightscale_userdata.py[DEBUG]: Failed to get raw userdata in module rightscale_userdata
2019-03-29 11:25:15,752 - handlers.py[DEBUG]: finish: modules-final/config-rightscale_userdata: SUCCESS: config-rightscale_userdata ran successfully
2019-03-29 11:25:15,752 - stages.py[DEBUG]: Running module scripts-vendor (<module 'cloudinit.config.cc_scripts_vendor' from '/usr/lib/python3/dist-packages/cloudinit/config/cc_scripts_vendor.py'>) with frequency once-per-instance
2019-03-29 11:25:15,753 - handlers.py[DEBUG]: start: modules-final/config-scripts-vendor: running config-scripts-vendor with frequency once-per-instance
2019-03-29 11:25:15,753 - util.py[DEBUG]: Writing to /var/lib/cloud/instances/i-07999df64e41cdbe0/sem/config_scripts_vendor - wb: [644] 25 bytes
2019-03-29 11:25:15,753 - helpers.py[DEBUG]: Running config-scripts-vendor using lock (<FileLock using file '/var/lib/cloud/instances/i-07999df64e41cdbe0/sem/config_scripts_vendor'>)
2019-03-29 11:25:15,753 - handlers.py[DEBUG]: finish: modules-final/config-scripts-vendor: SUCCESS: config-scripts-vendor ran successfully
2019-03-29 11:25:15,753 - stages.py[DEBUG]: Running module scripts-per-once (<module 'cloudinit.config.cc_scripts_per_once' from '/usr/lib/python3/dist-packages/cloudinit/config/cc_scripts_per_once.py'>) with frequency once
2019-03-29 11:25:15,753 - handlers.py[DEBUG]: start: modules-final/config-scripts-per-once: running config-scripts-per-once with frequency once
2019-03-29 11:25:15,753 - util.py[DEBUG]: Writing to /var/lib/cloud/sem/config_scripts_per_once.once - wb: [644] 25 bytes
2019-03-29 11:25:15,754 - helpers.py[DEBUG]: Running config-scripts-per-once using lock (<FileLock using file '/var/lib/cloud/sem/config_scripts_per_once.once'>)
2019-03-29 11:25:15,754 - handlers.py[DEBUG]: finish: modules-final/config-scripts-per-once: SUCCESS: config-scripts-per-once ran successfully
2019-03-29 11:25:15,754 - stages.py[DEBUG]: Running module scripts-per-boot (<module 'cloudinit.config.cc_scripts_per_boot' from '/usr/lib/python3/dist-packages/cloudinit/config/cc_scripts_per_boot.py'>) with frequency always
2019-03-29 11:25:15,754 - handlers.py[DEBUG]: start: modules-final/config-scripts-per-boot: running config-scripts-per-boot with frequency always
2019-03-29 11:25:15,754 - helpers.py[DEBUG]: Running config-scripts-per-boot using lock (<cloudinit.helpers.DummyLock object at 0x7f87309cf128>)
2019-03-29 11:25:15,754 - handlers.py[DEBUG]: finish: modules-final/config-scripts-per-boot: SUCCESS: config-scripts-per-boot ran successfully
2019-03-29 11:25:15,754 - stages.py[DEBUG]: Running module scripts-per-instance (<module 'cloudinit.config.cc_scripts_per_instance' from '/usr/lib/python3/dist-packages/cloudinit/config/cc_scripts_per_instance.py'>) with frequency once-per-instance
2019-03-29 11:25:15,754 - handlers.py[DEBUG]: start: modules-final/config-scripts-per-instance: running config-scripts-per-instance with frequency once-per-instance
2019-03-29 11:25:15,755 - util.py[DEBUG]: Writing to /var/lib/cloud/instances/i-07999df64e41cdbe0/sem/config_scripts_per_instance - wb: [644] 25 bytes
2019-03-29 11:25:15,755 - helpers.py[DEBUG]: Running config-scripts-per-instance using lock (<FileLock using file '/var/lib/cloud/instances/i-07999df64e41cdbe0/sem/config_scripts_per_instance'>)
2019-03-29 11:25:15,755 - handlers.py[DEBUG]: finish: modules-final/config-scripts-per-instance: SUCCESS: config-scripts-per-instance ran successfully
2019-03-29 11:25:15,755 - stages.py[DEBUG]: Running module scripts-user (<module 'cloudinit.config.cc_scripts_user' from '/usr/lib/python3/dist-packages/cloudinit/config/cc_scripts_user.py'>) with frequency once-per-instance
2019-03-29 11:25:15,755 - handlers.py[DEBUG]: start: modules-final/config-scripts-user: running config-scripts-user with frequency once-per-instance
2019-03-29 11:25:15,755 - util.py[DEBUG]: Writing to /var/lib/cloud/instances/i-07999df64e41cdbe0/sem/config_scripts_user - wb: [644] 25 bytes
2019-03-29 11:25:15,756 - helpers.py[DEBUG]: Running config-scripts-user using lock (<FileLock using file '/var/lib/cloud/instances/i-07999df64e41cdbe0/sem/config_scripts_user'>)
2019-03-29 11:25:15,756 - handlers.py[DEBUG]: finish: modules-final/config-scripts-user: SUCCESS: config-scripts-user ran successfully
2019-03-29 11:25:15,756 - stages.py[DEBUG]: Running module ssh-authkey-fingerprints (<module 'cloudinit.config.cc_ssh_authkey_fingerprints' from '/usr/lib/python3/dist-packages/cloudinit/config/cc_ssh_authkey_fingerprints.py'>) with frequency once-per-instance
2019-03-29 11:25:15,756 - handlers.py[DEBUG]: start: modules-final/config-ssh-authkey-fingerprints: running config-ssh-authkey-fingerprints with frequency once-per-instance
2019-03-29 11:25:15,756 - util.py[DEBUG]: Writing to /var/lib/cloud/instances/i-07999df64e41cdbe0/sem/config_ssh_authkey_fingerprints - wb: [644] 25 bytes
2019-03-29 11:25:15,756 - helpers.py[DEBUG]: Running config-ssh-authkey-fingerprints using lock (<FileLock using file '/var/lib/cloud/instances/i-07999df64e41cdbe0/sem/config_ssh_authkey_fingerprints'>)
2019-03-29 11:25:15,757 - util.py[DEBUG]: Reading from /etc/ssh/sshd_config (quiet=False)
2019-03-29 11:25:15,757 - util.py[DEBUG]: Read 2540 bytes from /etc/ssh/sshd_config
2019-03-29 11:25:15,757 - util.py[DEBUG]: Reading from /home/ubuntu/.ssh/authorized_keys (quiet=False)
2019-03-29 11:25:15,757 - util.py[DEBUG]: Read 448 bytes from /home/ubuntu/.ssh/authorized_keys
2019-03-29 11:25:15,785 - handlers.py[DEBUG]: finish: modules-final/config-ssh-authkey-fingerprints: SUCCESS: config-ssh-authkey-fingerprints ran successfully
2019-03-29 11:25:15,785 - stages.py[DEBUG]: Running module keys-to-console (<module 'cloudinit.config.cc_keys_to_console' from '/usr/lib/python3/dist-packages/cloudinit/config/cc_keys_to_console.py'>) with frequency once-per-instance
2019-03-29 11:25:15,785 - handlers.py[DEBUG]: start: modules-final/config-keys-to-console: running config-keys-to-console with frequency once-per-instance
2019-03-29 11:25:15,786 - util.py[DEBUG]: Writing to /var/lib/cloud/instances/i-07999df64e41cdbe0/sem/config_keys_to_console - wb: [644] 24 bytes
2019-03-29 11:25:15,786 - helpers.py[DEBUG]: Running config-keys-to-console using lock (<FileLock using file '/var/lib/cloud/instances/i-07999df64e41cdbe0/sem/config_keys_to_console'>)
2019-03-29 11:25:15,786 - util.py[DEBUG]: Running command ['/usr/lib/cloud-init/write-ssh-key-fingerprints', '', 'ssh-dss'] with allowed return codes [0] (shell=False, capture=True)
2019-03-29 11:25:15,814 - handlers.py[DEBUG]: finish: modules-final/config-keys-to-console: SUCCESS: config-keys-to-console ran successfully
2019-03-29 11:25:15,814 - stages.py[DEBUG]: Running module phone-home (<module 'cloudinit.config.cc_phone_home' from '/usr/lib/python3/dist-packages/cloudinit/config/cc_phone_home.py'>) with frequency once-per-instance
2019-03-29 11:25:15,815 - handlers.py[DEBUG]: start: modules-final/config-phone-home: running config-phone-home with frequency once-per-instance
2019-03-29 11:25:15,815 - util.py[DEBUG]: Writing to /var/lib/cloud/instances/i-07999df64e41cdbe0/sem/config_phone_home - wb: [644] 25 bytes
2019-03-29 11:25:15,815 - helpers.py[DEBUG]: Running config-phone-home using lock (<FileLock using file '/var/lib/cloud/instances/i-07999df64e41cdbe0/sem/config_phone_home'>)
2019-03-29 11:25:15,816 - cc_phone_home.py[DEBUG]: Skipping module named phone-home, no 'phone_home' configuration found
2019-03-29 11:25:15,816 - handlers.py[DEBUG]: finish: modules-final/config-phone-home: SUCCESS: config-phone-home ran successfully
2019-03-29 11:25:15,816 - stages.py[DEBUG]: Running module final-message (<module 'cloudinit.config.cc_final_message' from '/usr/lib/python3/dist-packages/cloudinit/config/cc_final_message.py'>) with frequency always
2019-03-29 11:25:15,816 - handlers.py[DEBUG]: start: modules-final/config-final-message: running config-final-message with frequency always
2019-03-29 11:25:15,816 - helpers.py[DEBUG]: Running config-final-message using lock (<cloudinit.helpers.DummyLock object at 0x7f8730238198>)
2019-03-29 11:25:15,816 - util.py[DEBUG]: Reading from /proc/uptime (quiet=False)
2019-03-29 11:25:15,816 - util.py[DEBUG]: Read 13 bytes from /proc/uptime
2019-03-29 11:25:15,819 - util.py[DEBUG]: Cloud-init v. 18.3-9-g2e62cb8a-0ubuntu1~16.04.2 finished at Fri, 29 Mar 2019 11:25:15 +0000. Datasource DataSourceEc2Local.  Up 21.30 seconds
2019-03-29 11:25:15,819 - util.py[DEBUG]: Writing to /var/lib/cloud/instance/boot-finished - wb: [644] 79 bytes
2019-03-29 11:25:15,819 - handlers.py[DEBUG]: finish: modules-final/config-final-message: SUCCESS: config-final-message ran successfully
2019-03-29 11:25:15,819 - stages.py[DEBUG]: Running module power-state-change (<module 'cloudinit.config.cc_power_state_change' from '/usr/lib/python3/dist-packages/cloudinit/config/cc_power_state_change.py'>) with frequency once-per-instance
2019-03-29 11:25:15,820 - handlers.py[DEBUG]: start: modules-final/config-power-state-change: running config-power-state-change with frequency once-per-instance
2019-03-29 11:25:15,820 - util.py[DEBUG]: Writing to /var/lib/cloud/instances/i-07999df64e41cdbe0/sem/config_power_state_change - wb: [644] 25 bytes
2019-03-29 11:25:15,820 - helpers.py[DEBUG]: Running config-power-state-change using lock (<FileLock using file '/var/lib/cloud/instances/i-07999df64e41cdbe0/sem/config_power_state_change'>)
2019-03-29 11:25:15,820 - cc_power_state_change.py[DEBUG]: no power_state provided. doing nothing
2019-03-29 11:25:15,820 - handlers.py[DEBUG]: finish: modules-final/config-power-state-change: SUCCESS: config-power-state-change ran successfully
2019-03-29 11:25:15,820 - main.py[DEBUG]: Ran 20 modules with 0 failures
2019-03-29 11:25:15,821 - util.py[DEBUG]: Creating symbolic link from '/run/cloud-init/result.json' => '../../var/lib/cloud/data/result.json'
2019-03-29 11:25:15,821 - util.py[DEBUG]: Reading from /proc/uptime (quiet=False)
2019-03-29 11:25:15,821 - util.py[DEBUG]: Read 13 bytes from /proc/uptime
2019-03-29 11:25:15,821 - util.py[DEBUG]: cloud-init mode 'modules' took 0.161 seconds (0.16)
2019-03-29 11:25:15,821 - handlers.py[DEBUG]: finish: modules-final: SUCCESS: running modules for final
